Workbook

Sheet GC data
C2: Volume Standards = | D2: 10µl | E2: Phospholipid
D3: µg Int std TG = | E3: =23.67/2 -> 11.835 | AD3: PL µmol per litre fraction | BG3: PL
A4: PL | D4: µg ext std = | E4: =49.04/2 -> 24.52 | AD4: volume (ml) | AE4: 0.15 | AF4: 0.15 | AG4: 0.15 | AH4: 0.15 | AI4: 0.15 | AJ4: 0.15 | AK4: 0.15 | AL4: 0.15 | AM4: 0.15 | AN4: 0.15 | AO4: 0.15 | AP4: 0.15 | AQ4: 0.15 | AR4: 0.15 | AS4: 0.15 | AT4: 0.15 | AU4: 0.15 | AV4: 0.15 | AW4: 0.15 | AX4: 0.15 | AY4: 0.15 | AZ4: 0.15 | BA4: 0.15 | BB4: 0.15 | BC4: 0.15 | BD4: 0.15 | BE4: 0.15 | BG4: fatty acids expressed as mol %
A5: Sample: | B5: OPLA 0.1 | C5: OPLA 0.2 | D5: OPLA 0.3 | E5: OPLA 2.1 | F5: OPLA 2.2 | G5: OPLA 2.3 | H5: OPLA 8.1 | I5: OPLA 8.2 | J5: OPLA 8.3 | K5: OPLA 0.4 | L5: OPLA 0.5 | M5: OPLA 0.6 | N5: OPLA 0.7 | O5: OPLA 0.8 | P5: OPLA 0.9 | Q5: OPLA 2.4 | R5: OPLA 2.5 | S5: OPLA 2.6 | T5: OPLA 2.7 | U5: OPLA 2.8 | V5: OPLA 2.9 | W5: OPLA 8.4 | X5: OPLA 8.5 | Y5: OPLA 8.6 | Z5: OPLA 8.7 | AA5: OPLA 8.8 | AB5: OPLA 8.9 | AD5: Time Point | AE5: =B5 -> OPLA 0.1 | AF5: =C5 -> OPLA 0.2 | AG5: =D5 -> OPLA 0.3 | AH5: =E5 -> OPLA 2.1 | AI5: =F5 -> OPLA 2.2 | AJ5: =G5 -> OPLA 2.3 | AK5: =H5 -> OPLA 8.1 | AL5: =I5 -> OPLA 8.2 | ... BE5: =AB5 -> OPLA 8.9 | BH5: =AE5 -> OPLA 0.1 | BI5: =AF5 -> OPLA 0.2 | BJ5: =AG5 -> OPLA 0.3 | BK5: =AH5 -> OPLA 2.1 | BL5: =AI5 -> OPLA 2.2 | BM5: =AJ5 -> OPLA 2.3 | BN5: =AK5 -> OPLA 8.1 | BO5: =AL5 -> OPLA 8.2 | ... CH5: =BE5 -> OPLA 8.9 | CK5: =BH5 -> OPLA 0.1 | CL5: =BI5 -> OPLA 0.2 | CM5: =BJ5 -> OPLA 0.3 | CN5: =BK5 -> OPLA 2.1 | CO5: =BL5 -> OPLA 2.2 | CP5: =BM5 -> OPLA 2.3 | CQ5: =BN5 -> OPLA 8.1 | CR5: =BO5 -> OPLA 8.2 | ... DK5: =CH5 -> OPLA 8.9
A6: 8:0 | B6: 0 | C6: 0 | D6: 0 | E6: 0 | F6: 0 | G6: 0 | H6: 0 | I6: 0 | J6: 0 | K6: 0 | L6: 0 | M6: 0 | N6: 0 | O6: 0 | P6: 0 | Q6: 0 | R6: 0 | S6: 0 | T6: 0 | U6: 0 | V6: 0 | W6: 0 | X6: 0 | Y6: 0 | Z6: 0 | AA6: 0 | AB6: 0 | AD6: 0.33333333 | AE6: =((B$6/B$18)*$E$3)/144.4*(1/AE$4*1000)/2 -> 0 | AF6: =((C$6/C$18)*$E$3)/144.4*(1/AF$4*1000)/2 -> 0 | AG6: =((D$6/D$18)*$E$3)/144.4*(1/AG$4*1000)/2 -> 0 | AH6: =((E$6/E$18)*$E$3)/144.4*(1/AH$4*1000)/2 -> 0 | AI6: =((F$6/F$18)*$E$3)/144.4*(1/AI$4*1000)/2 -> 0 | AJ6: =((G$6/G$18)*$E$3)/144.4*(1/AJ$4*1000)/2 -> 0 | AK6: =((H$6/H$18)*$E$3)/144.4*(1/AK$4*1000)/2 -> 0 | AL6: =((I$6/I$18)*$E$3)/144.4*(1/AL$4*1000)/2 -> 0 | ... BE6: =((AB$6/AB$18)*$E$3)/144.4*(1/BE$4*1000)/2 -> 0 | BG6: 0.33333333 | BH6: =AE6*100/AE$39 -> 0 | BI6: =AF6*100/AF$39 -> 0 | BJ6: =AG6*100/AG$39 -> 0 | BK6: =AH6*100/AH$39 -> 0 | BL6: =AI6*100/AI$39 -> 0 | BM6: =AJ6*100/AJ$39 -> 0 | BN6: =AK6*100/AK$39 -> 0 | BO6: =AL6*100/AL$39 -> 0 | ... CH6: =BE6*100/BE$39 -> 0 | CJ6: 16:0/18:2 | CK6: =BH23/BH15 -> 0.18547839 | CL6: =BI23/BI15 -> 0.18316424 | CM6: =BJ23/BJ15 -> 0.19250555 | CN6: =BK23/BK15 -> 0.25605587 | CO6: =BL23/BL15 -> 0.263458 | CP6: =BM23/BM15 -> 0.26900362 | CQ6: =BN23/BN15 -> 0.32094513 | CR6: =BO23/BO15 -> 0.32355275 | ... CV6: =BS23/BS15 -> 0.21217744 | CW6: =CD23/CD15 -> 0.38437771 | CX6: =#REF!/#REF! -> #REF! | CY6: =#REF!/#REF! -> #REF! | CZ6: =#REF!/#REF! -> #REF! | DA6: =#REF!/#REF! -> #REF! | DB6: =#REF!/#REF! -> #REF! | DC6: =#REF!/#REF! -> #REF! | DD6: =CA23/CA15 -> 0.29954866 | DE6: =CB23/CB15 -> 0.32378309 | DF6: =CC23/CC15 -> 0.37099744 | DG6: =CD23/CD15 -> 0.38437771 | DH6: =CE23/CE15 -> 0.37911765 | DI6: =CF23/CF15 -> 0.45168182 | DJ6: =CG23/CG15 -> 0.45605123 | DK6: =CH23/CH15 -> 0.45419125
A7: 10:0 | B7: 0 | C7: 0 | D7: 0 | E7: 0 | F7: 0 | G7: 0 | H7: 0 | I7: 0 | J7: 0 | K7: 0 | L7: 0 | M7: 0 | N7: 0 | O7: 0 | P7: 0 | Q7: 0 | R7: 0 | S7: 0 | T7: 0 | U7: 0 | V7: 0 | W7: 0 | X7: 0 | Y7: 0 | Z7: 0 | AA7: 0 | AB7: 0 | AD7: 0.41666667 | AE7: =((B$7/B$18)*$E$3)/172.4*(1/AE$4*1000)/2 -> 0 | AF7: =((C$7/C$18)*$E$3)/172.4*(1/AF$4*1000)/2 -> 0 | AG7: =((D$7/D$18)*$E$3)/172.4*(1/AG$4*1000)/2 -> 0 | AH7: =((E$7/E$18)*$E$3)/172.4*(1/AH$4*1000)/2 -> 0 | AI7: =((F$7/F$18)*$E$3)/172.4*(1/AI$4*1000)/2 -> 0 | AJ7: =((G$7/G$18)*$E$3)/172.4*(1/AJ$4*1000)/2 -> 0 | AK7: =((H$7/H$18)*$E$3)/172.4*(1/AK$4*1000)/2 -> 0 | AL7: =((I$7/I$18)*$E$3)/172.4*(1/AL$4*1000)/2 -> 0 | ... BE7: =((AB$7/AB$18)*$E$3)/172.4*(1/BE$4*1000)/2 -> 0 | BG7: 0.41666667 | BH7: =AE7*100/AE$39 -> 0 | BI7: =AF7*100/AF$39 -> 0 | BJ7: =AG7*100/AG$39 -> 0 | BK7: =AH7*100/AH$39 -> 0 | BL7: =AI7*100/AI$39 -> 0 | BM7: =AJ7*100/AJ$39 -> 0 | BN7: =AK7*100/AK$39 -> 0 | BO7: =AL7*100/AL$39 -> 0 | ... CH7: =BE7*100/BE$39 -> 0 | CJ7: 16:1/16:0 | CK7: =BH17/BH15 -> 0.24618252 | CL7: =BI17/BI15 -> 0.23562915 | CM7: =BJ17/BJ15 -> 0.23779744 | CN7: =BK17/BK15 -> 0 | CO7: =BL17/BL15 -> 0 | CP7: =BM17/BM15 -> 0 | CQ7: =BN17/BN15 -> 0 | CR7: =BO17/BO15 -> 0 | ... CV7: =BS17/BS15 -> 0.2511803 | CW7: =CD17/CD15 -> 0 | CX7: =#REF!/#REF! -> #REF! | CY7: =#REF!/#REF! -> #REF! | CZ7: =#REF!/#REF! -> #REF! | DA7: =#REF!/#REF! -> #REF! | DB7: =#REF!/#REF! -> #REF! | DC7: =#REF!/#REF! -> #REF! | DD7: =CA17/CA15 -> 0 | DE7: =CB17/CB15 -> 0 | DF7: =CC17/CC15 -> 0 | DG7: =CD17/CD15 -> 0 | DH7: =CE17/CE15 -> 0 | DI7: =CF17/CF15 -> 0 | DJ7: =CG17/CG15 -> 0 | DK7: =CH17/CH15 -> 0
A8: 11:0 | B8: 0 | C8: 0 | D8: 0 | E8: 0 | F8: 0 | G8: 0 | H8: 0 | I8: 0 | J8: 0 | K8: 0 | L8: 0 | M8: 0 | N8: 0 | O8: 0 | P8: 0 | Q8: 51.4593 | R8: 0 | S8: 0 | T8: 0 | U8: 0 | V8: 0 | W8: 56.1510 | X8: 0 | Y8: 0 | Z8: 0 | AA8: 0 | AB8: 0 | AD8: 0.45833333 | AE8: =((B$8/B$18)*$E$3)/172.4*(1/AE$4*1000)/2 -> 0 | AF8: =((C$8/C$18)*$E$3)/172.4*(1/AF$4*1000)/2 -> 0 | AG8: =((D$8/D$18)*$E$3)/172.4*(1/AG$4*1000)/2 -> 0 | AH8: =((E$8/E$18)*$E$3)/172.4*(1/AH$4*1000)/2 -> 0 | AI8: =((F$8/F$18)*$E$3)/172.4*(1/AI$4*1000)/2 -> 0 | AJ8: =((G$8/G$18)*$E$3)/172.4*(1/AJ$4*1000)/2 -> 0 | AK8: =((H$8/H$18)*$E$3)/172.4*(1/AK$4*1000)/2 -> 0 | AL8: =((I$8/I$18)*$E$3)/172.4*(1/AL$4*1000)/2 -> 0 | ... BE8: =((AB$8/AB$18)*$E$3)/172.4*(1/BE$4*1000)/2 -> 0 | BG8: 0.45833333 | BH8: =AE8*100/AE$39 -> 0 | BI8: =AF8*100/AF$39 -> 0 | BJ8: =AG8*100/AG$39 -> 0 | BK8: =AH8*100/AH$39 -> 0 | BL8: =AI8*100/AI$39 -> 0 | BM8: =AJ8*100/AJ$39 -> 0 | BN8: =AK8*100/AK$39 -> 0 | BO8: =AL8*100/AL$39 -> 0 | ... CH8: =BE8*100/BE$39 -> 0
A9: 12:0 | B9: 0 | C9: 0 | D9: 0 | E9: 0 | F9: 0 | G9: 0 | H9: 0 | I9: 0 | J9: 0 | K9: 0 | L9: 0 | M9: 0 | N9: 0 | O9: 0 | P9: 0 | Q9: 0 | R9: 0 | S9: 0 | T9: 0 | U9: 0 | V9: 0 | W9: 0 | X9: 0 | Y9: 0 | Z9: 0 | AA9: 0 | AB9: 0 | AD9: 0.5 | AE9: =((B$9/B$18)*$E$3)/200.4*(1/AE$4*1000)/2 -> 0 | AF9: =((C$9/C$18)*$E$3)/200.4*(1/AF$4*1000)/2 -> 0 | AG9: =((D$9/D$18)*$E$3)/200.4*(1/AG$4*1000)/2 -> 0 | AH9: =((E$9/E$18)*$E$3)/200.4*(1/AH$4*1000)/2 -> 0 | AI9: =((F$9/F$18)*$E$3)/200.4*(1/AI$4*1000)/2 -> 0 | AJ9: =((G$9/G$18)*$E$3)/200.4*(1/AJ$4*1000)/2 -> 0 | AK9: =((H$9/H$18)*$E$3)/200.4*(1/AK$4*1000)/2 -> 0 | AL9: =((I$9/I$18)*$E$3)/200.4*(1/AL$4*1000)/2 -> 0 | ... BE9: =((AB$9/AB$18)*$E$3)/200.4*(1/BE$4*1000)/2 -> 0 | BG9: 0.5 | BH9: =AE9*100/AE$39 -> 0 | BI9: =AF9*100/AF$39 -> 0 | BJ9: =AG9*100/AG$39 -> 0 | BK9: =AH9*100/AH$39 -> 0 | BL9: =AI9*100/AI$39 -> 0 | BM9: =AJ9*100/AJ$39 -> 0 | BN9: =AK9*100/AK$39 -> 0 | BO9: =AL9*100/AL$39 -> 0 | ... CH9: =BE9*100/BE$39 -> 0
A10: 13:0/BHT | B10: 0 | C10: 0 | D10: 0 | E10: 0 | F10: 0 | G10: 0 | H10: 0 | I10: 0 | J10: 0 | K10: 0 | L10: 0 | M10: 0 | N10: 0 | O10: 0 | P10: 0 | Q10: 0 | R10: 0 | S10: 0 | T10: 0 | U10: 0 | V10: 0 | W10: 0 | X10: 0 | Y10: 0 | Z10: 0 | AA10: 0 | AB10: 0 | BG10: 0.54166667
A11: 14:0 | B11: 384.3908 | C11: 0 | D11: 0 | E11: 0 | F11: 0 | G11: 0 | H11: 0 | I11: 0 | J11: 0 | K11: 0 | L11: 0 | M11: 0 | N11: 0 | O11: 0 | P11: 0 | Q11: 0 | R11: 0 | S11: 0 | T11: 0 | U11: 0 | V11: 0 | W11: 0 | X11: 0 | Y11: 0 | Z11: 0 | AA11: 0 | AB11: 0 | AD11: C14:0, µmol/l | AE11: =((B$11/B$18)*$E$3)/228.4*(1/AE$4*1000)/2 -> 13.468053 | AF11: =((C$11/C$18)*$E$3)/228.4*(1/AF$4*1000)/2 -> 0 | AG11: =((D$11/D$18)*$E$3)/228.4*(1/AG$4*1000)/2 -> 0 | AH11: =((E$11/E$18)*$E$3)/228.4*(1/AH$4*1000)/2 -> 0 | AI11: =((F$11/F$18)*$E$3)/228.4*(1/AI$4*1000)/2 -> 0 | AJ11: =((G$11/G$18)*$E$3)/228.4*(1/AJ$4*1000)/2 -> 0 | AK11: =((H$11/H$18)*$E$3)/228.4*(1/AK$4*1000)/2 -> 0 | AL11: =((I$11/I$18)*$E$3)/228.4*(1/AL$4*1000)/2 -> 0 | ... BE11: =((AB$11/AB$18)*$E$3)/228.4*(1/BE$4*1000)/2 -> 0 | BG11: 0.58333333 | BH11: =AE11*100/AE$39 -> 1.1722855 | BI11: =AF11*100/AF$39 -> 0 | BJ11: =AG11*100/AG$39 -> 0 | BK11: =AH11*100/AH$39 -> 0 | BL11: =AI11*100/AI$39 -> 0 | BM11: =AJ11*100/AJ$39 -> 0 | BN11: =AK11*100/AK$39 -> 0 | BO11: =AL11*100/AL$39 -> 0 | ... CH11: =BE11*100/BE$39 -> 0
A12: 14:1 | B12: 0 | C12: 0 | D12: 0 | E12: 0 | F12: 0 | G12: 0 | H12: 0 | I12: 0 | J12: 0 | K12: 0 | L12: 0 | M12: 0 | N12: 0 | O12: 0 | P12: 0 | Q12: 0 | R12: 0 | S12: 0 | T12: 0 | U12: 0 | V12: 0 | W12: 0 | X12: 0 | Y12: 0 | Z12: 0 | AA12: 0 | AB12: 0 | AD12: 0.58402778 | AE12: =((B$12/B$18)*$E$3)/226.4*(1/AE$4*1000)/2 -> 0 | AF12: =((C$12/C$18)*$E$3)/226.4*(1/AF$4*1000)/2 -> 0 | AG12: =((D$12/D$18)*$E$3)/226.4*(1/AG$4*1000)/2 -> 0 | AH12: =((E$12/E$18)*$E$3)/226.4*(1/AH$4*1000)/2 -> 0 | AI12: =((F$12/F$18)*$E$3)/226.4*(1/AI$4*1000)/2 -> 0 | AJ12: =((G$12/G$18)*$E$3)/226.4*(1/AJ$4*1000)/2 -> 0 | AK12: =((H$12/H$18)*$E$3)/226.4*(1/AK$4*1000)/2 -> 0 | AL12: =((I$12/I$18)*$E$3)/226.4*(1/AL$4*1000)/2 -> 0 | ... BE12: =((AB$12/AB$18)*$E$3)/226.4*(1/BE$4*1000)/2 -> 0 | BG12: 0.58402778 | BH12: =AE12*100/AE$39 -> 0 | BI12: =AF12*100/AF$39 -> 0 | BJ12: =AG12*100/AG$39 -> 0 | BK12: =AH12*100/AH$39 -> 0 | BL12: =AI12*100/AI$39 -> 0 | BM12: =AJ12*100/AJ$39 -> 0 | BN12: =AK12*100/AK$39 -> 0 | BO12: =AL12*100/AL$39 -> 0 | ... CH12: =BE12*100/BE$39 -> 0
A13: 15:0 | B13: 0 | C13: 0 | D13: 0 | E13: 0 | F13: 0 | G13: 0 | H13: 0 | I13: 0 | J13: 0 | K13: 0 | L13: 0 | M13: 0 | N13: 0 | O13: 0 | P13: 0 | Q13: 0 | R13: 0 | S13: 0 | T13: 0 | U13: 0 | V13: 0 | W13: 0 | X13: 0 | Y13: 0 | Z13: 0 | AA13: 0 | AB13: 0 | BG13: 0.625
A14: 15:1 | B14: 0 | C14: 0 | D14: 0 | E14: 0 | F14: 0 | G14: 0 | H14: 0 | I14: 0 | J14: 0 | K14: 0 | L14: 0 | M14: 0 | N14: 0 | O14: 0 | P14: 0 | Q14: 0 | R14: 0 | S14: 0 | T14: 0 | U14: 0 | V14: 0 | W14: 0 | X14: 0 | Y14: 0 | Z14: 0 | AA14: 0 | AB14: 0 | AD14: 0.62569444 | AE14: =((B$14/B$18)*$E$3)/240.4*(1/AE$4*1000)/2 -> 0 | AF14: =((C$14/C$18)*$E$3)/240.4*(1/AF$4*1000)/2 -> 0 | AG14: =((D$14/D$18)*$E$3)/240.4*(1/AG$4*1000)/2 -> 0 | AH14: =((E$14/E$18)*$E$3)/240.4*(1/AH$4*1000)/2 -> 0 | AI14: =((F$14/F$18)*$E$3)/240.4*(1/AI$4*1000)/2 -> 0 | AJ14: =((G$14/G$18)*$E$3)/240.4*(1/AJ$4*1000)/2 -> 0 | AK14: =((H$14/H$18)*$E$3)/240.4*(1/AK$4*1000)/2 -> 0 | AL14: =((I$14/I$18)*$E$3)/240.4*(1/AL$4*1000)/2 -> 0 | ... BE14: =((AB$14/AB$18)*$E$3)/240.4*(1/BE$4*1000)/2 -> 0 | BG14: 0.62569444 | BH14: =AE14*100/AE$39 -> 0 | BI14: =AF14*100/AF$39 -> 0 | BJ14: =AG14*100/AG$39 -> 0 | BK14: =AH14*100/AH$39 -> 0 | BL14: =AI14*100/AI$39 -> 0 | BM14: =AJ14*100/AJ$39 -> 0 | BN14: =AK14*100/AK$39 -> 0 | BO14: =AL14*100/AL$39 -> 0 | ... CH14: =BE14*100/BE$39 -> 0
A15: 16:0 | B15: 10774.94 | C15: 8248.0078 | D15: 8578.8848 | E15: 2260.2397 | F15: 2205.6399 | G15: 2589.71 | H15: 2545.2405 | I15: 2874.2593 | J15: 3152.8933 | K15: 2481.0176 | L15: 2632.1523 | M15: 3244.2693 | N15: 2614.3457 | O15: 2967.5361 | P15: 3285.2493 | Q15: 1686.7598 | R15: 2421.2913 | S15: 1874.7617 | T15: 1742.9335 | U15: 2659.3481 | V15: 1513.9360 | W15: 2141.3574 | X15: 2263.9778 | Y15: 2353.9097 | Z15: 1633.1239 | AA15: 1831.1730 | AB15: 2179.7114 | AD15: C16:0, µmol/l | AE15: =((B$15/B$18)*$E$3)/256.4*(1/AE$4*1000)/2 -> 336.29838 | AF15: =((C$15/C$18)*$E$3)/256.4*(1/AF$4*1000)/2 -> 296.57882 | AG15: =((D$15/D$18)*$E$3)/256.4*(1/AG$4*1000)/2 -> 298.05169 | AH15: =((E$15/E$18)*$E$3)/256.4*(1/AH$4*1000)/2 -> 341.75917 | AI15: =((F$15/F$18)*$E$3)/256.4*(1/AI$4*1000)/2 -> 353.8218 | AJ15: =((G$15/G$18)*$E$3)/256.4*(1/AJ$4*1000)/2 -> 362.86509 | AK15: =((H$15/H$18)*$E$3)/256.4*(1/AK$4*1000)/2 -> 350.47948 | AL15: =((I$15/I$18)*$E$3)/256.4*(1/AL$4*1000)/2 -> 406.00847 | ... BE15: =((AB$15/AB$18)*$E$3)/256.4*(1/BE$4*1000)/2 -> 415.64394 | BG15: 0.66666667 | BH15: =AE15*100/AE$39 -> 29.272064 | BI15: =AF15*100/AF$39 -> 28.575081 | BJ15: =AG15*100/AG$39 -> 29.09707 | BK15: =AH15*100/AH$39 -> 31.02591 | BL15: =AI15*100/AI$39 -> 31.188031 | BM15: =AJ15*100/AJ$39 -> 30.893427 | BN15: =AK15*100/AK$39 -> 32.881131 | BO15: =AL15*100/AL$39 -> 33.800365 | ... CH15: =BE15*100/BE$39 -> 23.270799
A16: 16:s | B16: 0 | C16: 0 | D16: 0 | E16: 0 | F16: 0 | G16: 0 | H16: 0 | I16: 0 | J16: 0 | K16: 0 | L16: 0 | M16: 0 | N16: 0 | O16: 0 | P16: 0 | Q16: 0 | R16: 0 | S16: 0 | T16: 0 | U16: 0 | V16: 0 | W16: 0 | X16: 0 | Y16: 0 | Z16: 0 | AA16: 0 | AB16: 0 | BG16: 16:s
A17: 16:1 | B17: 2631.9109 | C17: 1928.3114 | D17: 2024.1239 | E17: 0 | F17: 0 | G17: 0 | H17: 0 | I17: 0 | J17: 0 | K17: 531.7194 | L17: 771.1248 | M17: 808.5401 | N17: 680.2258 | O17: 815.9235 | P17: 907.3795 | Q17: 0 | R17: 0 | S17: 0 | T17: 0 | U17: 0 | V17: 0 | W17: 0 | X17: 0 | Y17: 0 | Z17: 0 | AA17: 0 | AB17: 0 | AD17: C16:1, µmol/l | AE17: =((B$17/B$18)*$E$3)/254.4*(1/AE$4*1000)/2 -> 82.790784 | AF17: =((C$17/C$18)*$E$3)/254.4*(1/AF$4*1000)/2 -> 69.882615 | AG17: =((D$17/D$18)*$E$3)/254.4*(1/AG$4*1000)/2 -> 70.875927 | AH17: =((E$17/E$18)*$E$3)/254.4*(1/AH$4*1000)/2 -> 0 | AI17: =((F$17/F$18)*$E$3)/254.4*(1/AI$4*1000)/2 -> 0 | AJ17: =((G$17/G$18)*$E$3)/254.4*(1/AJ$4*1000)/2 -> 0 | AK17: =((H$17/H$18)*$E$3)/254.4*(1/AK$4*1000)/2 -> 0 | AL17: =((I$17/I$18)*$E$3)/254.4*(1/AL$4*1000)/2 -> 0 | ... BE17: =((AB$17/AB$18)*$E$3)/254.4*(1/BE$4*1000)/2 -> 0 | BG17: 0.66736111 | BH17: =AE17*100/AE$39 -> 7.2062707 | BI17: =AF17*100/AF$39 -> 6.733122 | BJ17: =AG17*100/AG$39 -> 6.9192087 | BK17: =AH17*100/AH$39 -> 0 | BL17: =AI17*100/AI$39 -> 0 | BM17: =AJ17*100/AJ$39 -> 0 | BN17: =AK17*100/AK$39 -> 0 | BO17: =AL17*100/AL$39 -> 0 | ... CH17: =BE17*100/BE$39 -> 0
A18: 17:0 | B18: 4929.6841 | C18: 4278.957 | D18: 4428.6182 | E18: 1017.5677 | F18: 959.1334 | G18: 1098.0824 | H18: 1117.3654 | I18: 1089.2306 | J18: 1201.8397 | K18: 1394.1823 | L18: 1466.0789 | M18: 1511.7922 | N18: 1350.5195 | O18: 1633.4559 | P18: 1979.2821 | Q18: 902.6000 | R18: 1014.0144 | S18: 816.1480 | T18: 844.6030 | U18: 972.3913 | V18: 686.2928 | W18: 918.1285 | X18: 848.2192 | Y18: 850.7307 | Z18: 778.5511 | AA18: 756.8929 | AB18: 806.8755 | AD18: 0.70833333 | AE18: =((B$18/B$18)*$E$3)/270.4*(1/AE$4*1000)/2 -> 145.89497 | AF18: =((C$18/C$18)*$E$3)/270.4*(1/AF$4*1000)/2 -> 145.89497 | AG18: =((D$18/D$18)*$E$3)/270.4*(1/AG$4*1000)/2 -> 145.89497 | AH18: =((E$18/E$18)*$E$3)/270.4*(1/AH$4*1000)/2 -> 145.89497 | AI18: =((F$18/F$18)*$E$3)/270.4*(1/AI$4*1000)/2 -> 145.89497 | AJ18: =((G$18/G$18)*$E$3)/270.4*(1/AJ$4*1000)/2 -> 145.89497 | AK18: =((H$18/H$18)*$E$3)/270.4*(1/AK$4*1000)/2 -> 145.89497 | AL18: =((I$18/I$18)*$E$3)/270.4*(1/AL$4*1000)/2 -> 145.89497 | ... BE18: =((AB$18/AB$18)*$E$3)/270.4*(1/BE$4*1000)/2 -> 145.89497 | BG18: 0.70833333 | BH18: =AE18*100/AE$39 -> 12.698982 | BI18: =AF18*100/AF$39 -> 14.056839 | BJ18: =AG18*100/AG$39 -> 14.242886 | BK18: =AH18*100/AH$39 -> 13.244778 | BL18: =AI18*100/AI$39 -> 12.860081 | BM18: =AJ18*100/AJ$39 -> 12.421133 | BN18: =AK18*100/AK$39 -> 13.687511 | BO18: =AL18*100/AL$39 -> 12.145814 | ... CH18: =BE18*100/BE$39 -> 8.1682714
A19: 17:1 | B19: 0 | C19: 0 | D19: 0 | E19: 0 | F19: 0 | G19: 0 | H19: 0 | I19: 0 | J19: 0 | K19: 0 | L19: 0 | M19: 0 | N19: 0 | O19: 0 | P19: 0 | Q19: 0 | R19: 0 | S19: 0 | T19: 0 | U19: 0 | V19: 0 | W19: 0 | X19: 0 | Y19: 0 | Z19: 0 | AA19: 0 | AB19: 0 | BG19: 0.70902778
A20: 18:0 | B20: 4270.9326 | C20: 3302.5574 | D20: 3352.4707 | E20: 819.5538 | F20: 793.6481 | G20: 972.2786 | H20: 687.818 | I20: 820.9355 | J20: 890.227 | K20: 1639.7777 | L20: 1865.5430 | M20: 1987.4915 | N20: 1453.3207 | O20: 1726.7960 | P20: 1801.1036 | Q20: 1085.9100 | R20: 1614.0463 | S20: 1231.2241 | T20: 1062.7557 | U20: 1617.8096 | V20: 943.4133 | W20: 1264.4932 | X20: 1368.4099 | Y20: 1406.7595 | Z20: 1051.4696 | AA20: 1204.7531 | AB20: 1414.3530 | AD20: C18:0, µmol/l | AE20: =((B$20/B$18)*$E$3)/284.4*(1/AE$4*1000)/2 -> 120.17691 | AF20: =((C$20/C$18)*$E$3)/284.4*(1/AF$4*1000)/2 -> 107.06065 | AG20: =((D$20/D$18)*$E$3)/284.4*(1/AG$4*1000)/2 -> 105.00601 | AH20: =((E$20/E$18)*$E$3)/284.4*(1/AH$4*1000)/2 -> 111.72017 | AI20: =((F$20/F$18)*$E$3)/284.4*(1/AI$4*1000)/2 -> 114.78004 | AJ20: =((G$20/G$18)*$E$3)/284.4*(1/AJ$4*1000)/2 -> 122.82116 | AK20: =((H$20/H$18)*$E$3)/284.4*(1/AK$4*1000)/2 -> 85.387782 | AL20: =((I$20/I$18)*$E$3)/284.4*(1/AL$4*1000)/2 -> 104.54581 | ... BE20: =((AB$20/AB$18)*$E$3)/284.4*(1/BE$4*1000)/2 -> 243.14688 | BG20: 0.75 | BH20: =AE20*100/AE$39 -> 10.460432 | BI20: =AF20*100/AF$39 -> 10.315189 | BJ20: =AG20*100/AG$39 -> 10.251132 | BK20: =AH20*100/AH$39 -> 10.142288 | BL20: =AI20*100/AI$39 -> 10.117419 | BM20: =AJ20*100/AJ$39 -> 10.456687 | BN20: =AK20*100/AK$39 -> 8.0108739 | BO20: =AL20*100/AL$39 -> 8.7034795 | ... CH20: =BE20*100/BE$39 -> 13.613147
A21: 18:1 | B21: 7747.7603 | C21: 6266.9258 | D21: 6936.6035 | E21: 2175.6414 | F21: 2120.5891 | G21: 2529.6848 | H21: 2093.9771 | I21: 2211.6316 | J21: 2435.8921 | K21: 3017.7837 | L21: 3534.2795 | M21: 3723.7583 | N21: 3075.7947 | O21: 3585.2874 | P21: 3778.4275 | Q21: 1888.2450 | R21: 2837.7732 | S21: 1743.5997 | T21: 2473.7439 | U21: 3688.9995 | V21: 2223.3274 | W21: 2059.6707 | X21: 2204.1555 | Y21: 2241.0981 | Z21: 2178.6602 | AA21: 2490.6438 | AB21: 2912.4414 | AD21: C18:1, µmol/l | AE21: =((B$21/B$18)*$E$3)/282.4*(1/AE$4*1000)/2 -> 219.55301 | AF21: =((C$21/C$18)*$E$3)/282.4*(1/AF$4*1000)/2 -> 204.59685 | AG21: =((D$21/D$18)*$E$3)/282.4*(1/AG$4*1000)/2 -> 218.80687 | AH21: =((E$21/E$18)*$E$3)/282.4*(1/AH$4*1000)/2 -> 298.68012 | AI21: =((F$21/F$18)*$E$3)/282.4*(1/AI$4*1000)/2 -> 308.85869 | AJ21: =((G$21/G$18)*$E$3)/282.4*(1/AJ$4*1000)/2 -> 321.82057 | AK21: =((H$21/H$18)*$E$3)/282.4*(1/AK$4*1000)/2 -> 261.7936 | AL21: =((I$21/I$18)*$E$3)/282.4*(1/AL$4*1000)/2 -> 283.64509 | ... BE21: =((AB$21/AB$18)*$E$3)/282.4*(1/BE$4*1000)/2 -> 504.23499 | BG21: 0.75069444 | BH21: =AE21*100/AE$39 -> 19.110321 | BI21: =AF21*100/AF$39 -> 19.712708 | BJ21: =AG21*100/AG$39 -> 21.360854 | BK21: =AH21*100/AH$39 -> 27.115066 | BL21: =AI21*100/AI$39 -> 27.224706 | BM21: =AJ21*100/AJ$39 -> 27.398999 | BN21: =AK21*100/AK$39 -> 24.560838 | BO21: =AL21*100/AL$39 -> 23.613565 | ... CH21: =BE21*100/BE$39 -> 28.230776
A22: 18:1v | B22: 1975.1058 | C22: 1962.8992 | D22: 1488.6315 | E22: 0 | F22: 0 | G22: 0 | H22: 0 | I22: 0 | J22: 0 | K22: 777.0742 | L22: 826.9421 | M22: 934.2792 | N22: 696.0117 | O22: 810.5674 | P22: 844.0536 | Q22: 0 | R22: 0 | S22: 212.6890 | T22: 0 | U22: 0 | V22: 0 | W22: 0 | X22: 0 | Y22: 0 | Z22: 0 | AA22: 0 | AB22: 0 | AD22: 18.01v | AE22: =((B$22/B$18)*$E$3)/282.4*(1/AE$4*1000)/2 -> 55.969779 | AF22: =((C$22/C$18)*$E$3)/282.4*(1/AF$4*1000)/2 -> 64.082935 | AG22: =((D$22/D$18)*$E$3)/282.4*(1/AG$4*1000)/2 -> 46.957101 | AH22: =((E$22/E$18)*$E$3)/282.4*(1/AH$4*1000)/2 -> 0 | AI22: =((F$22/F$18)*$E$3)/282.4*(1/AI$4*1000)/2 -> 0 | AJ22: =((G$22/G$18)*$E$3)/282.4*(1/AJ$4*1000)/2 -> 0 | AK22: =((H$22/H$18)*$E$3)/282.4*(1/AK$4*1000)/2 -> 0 | AL22: =((I$22/I$18)*$E$3)/282.4*(1/AL$4*1000)/2 -> 0 | ... BE22: =((AB$22/AB$18)*$E$3)/282.4*(1/BE$4*1000)/2 -> 0 | BG22: 18.01v | BH22: =AE22*100/AE$39 -> 4.8717183 | BI22: =AF22*100/AF$39 -> 6.1743285 | BJ22: =AG22*100/AG$39 -> 4.5841514 | BK22: =AH22*100/AH$39 -> 0 | BL22: =AI22*100/AI$39 -> 0 | BM22: =AJ22*100/AJ$39 -> 0 | BN22: =AK22*100/AK$39 -> 0 | BO22: =AL22*100/AL$39 -> 0 | ... CH22: =BE22*100/BE$39 -> 0
A23: 18:2 | B23: 2185.5874 | C23: 1652.151 | D23: 1806.0679 | E23: 632.9206 | F23: 635.486 | G23: 761.8496 | H23: 893.3458 | I23: 1017.0236 | J23: 1098.9515 | K23: 610.0238 | L23: 677.6957 | M23: 752.7939 | N23: 613.2578 | O23: 747.2306 | P23: 775.6059 | Q23: 548.0217 | R23: 858.4958 | S23: 621.3105 | T23: 574.7326 | U23: 871.1693 | V23: 536.0702 | W23: 868.8005 | X23: 951.6787 | Y23: 975.9415 | Z23: 806.6994 | AA23: 913.2780 | AB23: 1082.6741 | AD23: C18:2, µmol/l | AE23: =((B$23/B$18)*$E$3)/280.4*(1/AE$4*1000)/2 -> 62.376081 | AF23: =((C$23/C$18)*$E$3)/280.4*(1/AF$4*1000)/2 -> 54.322633 | AG23: =((D$23/D$18)*$E$3)/280.4*(1/AG$4*1000)/2 -> 57.376603 | AH23: =((E$23/E$18)*$E$3)/280.4*(1/AH$4*1000)/2 -> 87.509442 | AI23: =((F$23/F$18)*$E$3)/280.4*(1/AI$4*1000)/2 -> 93.217182 | AJ23: =((G$23/G$18)*$E$3)/280.4*(1/AJ$4*1000)/2 -> 97.612023 | AK23: =((H$23/H$18)*$E$3)/280.4*(1/AK$4*1000)/2 -> 112.48468 | AL23: =((I$23/I$18)*$E$3)/280.4*(1/AL$4*1000)/2 -> 131.36516 | ... BE23: =((AB$23/AB$18)*$E$3)/280.4*(1/BE$4*1000)/2 -> 188.78184 | BG23: 0.75138889 | BH23: =AE23*100/AE$39 -> 5.4293353 | BI23: =AF23*100/AF$39 -> 5.2339329 | BJ23: =AG23*100/AG$39 -> 5.6013474 | BK23: =AH23*100/AH$39 -> 7.9443665 | BL23: =AI23*100/AI$39 -> 8.2167362 | BM23: =AJ23*100/AJ$39 -> 8.3104437 | BN23: =AK23*100/AK$39 -> 10.553039 | BO23: =AL23*100/AL$39 -> 10.936201 | ... CH23: =BE23*100/BE$39 -> 10.569393
A24: 18:3g | B24: 0 | C24: 0 | D24: 0 | E24: 0 | F24: 0 | G24: 0 | H24: 0 | I24: 0 | J24: 0 | K24: 0 | L24: 0 | M24: 0 | N24: 0 | O24: 0 | P24: 0 | Q24: 0 | R24: 0 | S24: 0 | T24: 0 | U24: 0 | V24: 0 | W24: 0 | X24: 0 | Y24: 0 | Z24: 0 | AA24: 0 | AB24: 0 | AD24: C18:3, µmol/l | AE24: =((B$24/B$18)*$E$3)/278.4*(1/AE$4*1000)/2 -> 0 | AF24: =((C$24/C$18)*$E$3)/278.4*(1/AF$4*1000)/2 -> 0 | AG24: =((D$24/D$18)*$E$3)/278.4*(1/AG$4*1000)/2 -> 0 | AH24: =((E$24/E$18)*$E$3)/278.4*(1/AH$4*1000)/2 -> 0 | AI24: =((F$24/F$18)*$E$3)/278.4*(1/AI$4*1000)/2 -> 0 | AJ24: =((G$24/G$18)*$E$3)/278.4*(1/AJ$4*1000)/2 -> 0 | AK24: =((H$24/H$18)*$E$3)/278.4*(1/AK$4*1000)/2 -> 0 | AL24: =((I$24/I$18)*$E$3)/278.4*(1/AL$4*1000)/2 -> 0 | ... BE24: =((AB$24/AB$18)*$E$3)/278.4*(1/BE$4*1000)/2 -> 0 | BG24: 18:3 g | BH24: =AE24*100/AE$39 -> 0 | BI24: =AF24*100/AF$39 -> 0 | BJ24: =AG24*100/AG$39 -> 0 | BK24: =AH24*100/AH$39 -> 0 | BL24: =AI24*100/AI$39 -> 0 | BM24: =AJ24*100/AJ$39 -> 0 | BN24: =AK24*100/AK$39 -> 0 | BO24: =AL24*100/AL$39 -> 0 | ... CH24: =BE24*100/BE$39 -> 0
A25: 18:3a | B25: 0 | C25: 0 | D25: 0 | E25: 0 | F25: 0 | G25: 0 | H25: 0 | I25: 0 | J25: 0 | K25: 0 | L25: 0 | M25: 0 | N25: 0 | O25: 0 | P25: 0 | Q25: 0 | R25: 0 | S25: 0 | T25: 0 | U25: 0 | V25: 0 | W25: 0 | X25: 0 | Y25: 0 | Z25: 0 | AA25: 0 | AB25: 0 | AD25: C18:3, µmol/l | AE25: =((B$25/B$18)*$E$3)/278.4*(1/AE$4*1000)/2 -> 0 | AF25: =((C$25/C$18)*$E$3)/278.4*(1/AF$4*1000)/2 -> 0 | AG25: =((D$25/D$18)*$E$3)/278.4*(1/AG$4*1000)/2 -> 0 | AH25: =((E$25/E$18)*$E$3)/278.4*(1/AH$4*1000)/2 -> 0 | AI25: =((F$25/F$18)*$E$3)/278.4*(1/AI$4*1000)/2 -> 0 | AJ25: =((G$25/G$18)*$E$3)/278.4*(1/AJ$4*1000)/2 -> 0 | AK25: =((H$25/H$18)*$E$3)/278.4*(1/AK$4*1000)/2 -> 0 | AL25: =((I$25/I$18)*$E$3)/278.4*(1/AL$4*1000)/2 -> 0 | ... BE25: =((AB$25/AB$18)*$E$3)/278.4*(1/BE$4*1000)/2 -> 0 | BG25: 18:3 a | BH25: =AE25*100/AE$39 -> 0 | BI25: =AF25*100/AF$39 -> 0 | BJ25: =AG25*100/AG$39 -> 0 | BK25: =AH25*100/AH$39 -> 0 | BL25: =AI25*100/AI$39 -> 0 | BM25: =AJ25*100/AJ$39 -> 0 | BN25: =AK25*100/AK$39 -> 0 | BO25: =AL25*100/AL$39 -> 0 | ... CH25: =BE25*100/BE$39 -> 0
A26: 20:0 | B26: 0 | C26: 0 | D26: 0 | E26: 0 | F26: 0 | G26: 0 | H26: 0 | I26: 0 | J26: 0 | K26: 0 | L26: 0 | M26: 0 | N26: 0 | O26: 0 | P26: 0 | Q26: 0 | R26: 0 | S26: 0 | T26: 0 | U26: 0 | V26: 0 | W26: 0 | X26: 0 | Y26: 0 | Z26: 0 | AA26: 0 | AB26: 0 | AD26: C20:0, µmol/l | AE26: =((B$26/B$18)*$E$3)/312.5*(1/AE$4*1000)/2 -> 0 | AF26: =((C$26/C$18)*$E$3)/312.5*(1/AF$4*1000)/2 -> 0 | AG26: =((D$26/D$18)*$E$3)/312.5*(1/AG$4*1000)/2 -> 0 | AH26: =((E$26/E$18)*$E$3)/312.5*(1/AH$4*1000)/2 -> 0 | AI26: =((F$26/F$18)*$E$3)/312.5*(1/AI$4*1000)/2 -> 0 | AJ26: =((G$26/G$18)*$E$3)/312.5*(1/AJ$4*1000)/2 -> 0 | AK26: =((H$26/H$18)*$E$3)/312.5*(1/AK$4*1000)/2 -> 0 | AL26: =((I$26/I$18)*$E$3)/312.5*(1/AL$4*1000)/2 -> 0 | ... BE26: =((AB$26/AB$18)*$E$3)/312.5*(1/BE$4*1000)/2 -> 0 | BG26: 0.83333333 | BH26: =AE26*100/AE$39 -> 0 | BI26: =AF26*100/AF$39 -> 0 | BJ26: =AG26*100/AG$39 -> 0 | BK26: =AH26*100/AH$39 -> 0 | BL26: =AI26*100/AI$39 -> 0 | BM26: =AJ26*100/AJ$39 -> 0 | BN26: =AK26*100/AK$39 -> 0 | BO26: =AL26*100/AL$39 -> 0 | ... CH26: =BE26*100/BE$39 -> 0
A27: 20:1 | B27: 0 | C27: 0 | D27: 0 | E27: 0 | F27: 0 | G27: 0 | H27: 0 | I27: 0 | J27: 0 | K27: 0 | L27: 0 | M27: 0 | N27: 0 | O27: 0 | P27: 0 | Q27: 0 | R27: 0 | S27: 0 | T27: 0 | U27: 0 | V27: 0 | W27: 0 | X27: 0 | Y27: 0 | Z27: 0 | AA27: 0 | AB27: 0 | AD27: C20:1, µmol/l | AE27: =((B$27/B$18)*$E$3)/310.5*(1/AE$4*1000)/2 -> 0 | AF27: =((C$27/C$18)*$E$3)/310.5*(1/AF$4*1000)/2 -> 0 | AG27: =((D$27/D$18)*$E$3)/310.5*(1/AG$4*1000)/2 -> 0 | AH27: =((E$27/E$18)*$E$3)/310.5*(1/AH$4*1000)/2 -> 0 | AI27: =((F$27/F$18)*$E$3)/310.5*(1/AI$4*1000)/2 -> 0 | AJ27: =((G$27/G$18)*$E$3)/310.5*(1/AJ$4*1000)/2 -> 0 | AK27: =((H$27/H$18)*$E$3)/310.5*(1/AK$4*1000)/2 -> 0 | AL27: =((I$27/I$18)*$E$3)/310.5*(1/AL$4*1000)/2 -> 0 | ... BE27: =((AB$27/AB$18)*$E$3)/310.5*(1/BE$4*1000)/2 -> 0 | BG27: 0.83402778 | BH27: =AE27*100/AE$39 -> 0 | BI27: =AF27*100/AF$39 -> 0 | BJ27: =AG27*100/AG$39 -> 0 | BK27: =AH27*100/AH$39 -> 0 | BL27: =AI27*100/AI$39 -> 0 | BM27: =AJ27*100/AJ$39 -> 0 | BN27: =AK27*100/AK$39 -> 0 | BO27: =AL27*100/AL$39 -> 0 | ... CH27: =BE27*100/BE$39 -> 0
A28: 20:2 | B28: 891.4016 | C28: 695.1997 | D28: 696.7592 | E28: 0 | F28: 0 | G28: 0 | H28: 0 | I28: 0 | J28: 0 | K28: 401.0026 | L28: 573.5045 | M28: 563.4609 | N28: 0 | O28: 0 | P28: 0 | Q28: 0 | R28: 0 | S28: 0 | T28: 0 | U28: 0 | V28: 0 | W28: 0 | X28: 0 | Y28: 0 | Z28: 0 | AA28: 0 | AB28: 0 | AD28: C20:2, µmol/l | AE28: =((B$28/B$18)*$E$3)/308.5*(1/AE$4*1000)/2 -> 23.123105 | AF28: =((C$28/C$18)*$E$3)/308.5*(1/AF$4*1000)/2 -> 20.776074 | AG28: =((D$28/D$18)*$E$3)/308.5*(1/AG$4*1000)/2 -> 20.118996 | AH28: =((E$28/E$18)*$E$3)/308.5*(1/AH$4*1000)/2 -> 0 | AI28: =((F$28/F$18)*$E$3)/308.5*(1/AI$4*1000)/2 -> 0 | AJ28: =((G$28/G$18)*$E$3)/308.5*(1/AJ$4*1000)/2 -> 0 | AK28: =((H$28/H$18)*$E$3)/308.5*(1/AK$4*1000)/2 -> 0 | AL28: =((I$28/I$18)*$E$3)/308.5*(1/AL$4*1000)/2 -> 0 | ... BE28: =((AB$28/AB$18)*$E$3)/308.5*(1/BE$4*1000)/2 -> 0 | BG28: 0.83472222 | BH28: =AE28*100/AE$39 -> 2.01268 | BI28: =AF28*100/AF$39 -> 2.0017546 | BJ28: =AG28*100/AG$39 -> 1.9641018 | BK28: =AH28*100/AH$39 -> 0 | BL28: =AI28*100/AI$39 -> 0 | BM28: =AJ28*100/AJ$39 -> 0 | BN28: =AK28*100/AK$39 -> 0 | BO28: =AL28*100/AL$39 -> 0 | ... CH28: =BE28*100/BE$39 -> 0
A29: 20:3/21:0 | B29: 393.856 | C29: 0 | D29: 364.0018 | E29: 0 | F29: 0 | G29: 0 | H29: 0 | I29: 0 | J29: 0 | K29: 1295.8324 | L29: 1413.6090 | M29: 1513.8264 | N29: 1633.0735 | O29: 1935.0648 | P29: 1986.2035 | Q29: 1062.2531 | R29: 1592.3246 | S29: 1219.0015 | T29: 1289.5027 | U29: 1952.6520 | V29: 1115.2782 | W29: 1384.4242 | X29: 1473.2788 | Y29: 1482.3458 | Z29: 1332.6227 | AA29: 1526.1002 | AB29: 1807.4520 | AD29: C20:3, µmol/l | AE29: =((B$29/B$18)*$E$3)/306.4*(1/AE$4*1000)/2 -> 10.286713 | AF29: =((C$29/C$18)*$E$3)/306.4*(1/AF$4*1000)/2 -> 0 | AG29: =((D$29/D$18)*$E$3)/306.4*(1/AG$4*1000)/2 -> 10.582628 | AH29: =((E$29/E$18)*$E$3)/306.4*(1/AH$4*1000)/2 -> 0 | AI29: =((F$29/F$18)*$E$3)/306.4*(1/AI$4*1000)/2 -> 0 | AJ29: =((G$29/G$18)*$E$3)/306.4*(1/AJ$4*1000)/2 -> 0 | AK29: =((H$29/H$18)*$E$3)/306.4*(1/AK$4*1000)/2 -> 0 | AL29: =((I$29/I$18)*$E$3)/306.4*(1/AL$4*1000)/2 -> 0 | ... BE29: =((AB$29/AB$18)*$E$3)/306.4*(1/BE$4*1000)/2 -> 288.41543 | BG29: 20:3/21:0 | BH29: =AE29*100/AE$39 -> 0.89537548 | BI29: =AF29*100/AF$39 -> 0 | BJ29: =AG29*100/AG$39 -> 1.0331211 | BK29: =AH29*100/AH$39 -> 0 | BL29: =AI29*100/AI$39 -> 0 | BM29: =AJ29*100/AJ$39 -> 0 | BN29: =AK29*100/AK$39 -> 0 | BO29: =AL29*100/AL$39 -> 0 | ... CH29: =BE29*100/BE$39 -> 16.147613
A30: 20:3 | B30: 0 | C30: 0 | D30: 0 | E30: 0 | F30: 0 | G30: 0 | H30: 0 | I30: 0 | J30: 0 | K30: 0 | L30: 0 | M30: 0 | N30: 0 | O30: 0 | P30: 0 | Q30: 0 | R30: 0 | S30: 0 | T30: 0 | U30: 0 | V30: 0 | W30: 0 | X30: 0 | Y30: 0 | Z30: 0 | AA30: 0 | AB30: 0 | AD30: C20:3, µmol/l | AE30: =((B$30/B$18)*$E$3)/306.4*(1/AE$4*1000)/2 -> 0 | AF30: =((C$30/C$18)*$E$3)/306.4*(1/AF$4*1000)/2 -> 0 | AG30: =((D$30/D$18)*$E$3)/306.4*(1/AG$4*1000)/2 -> 0 | AH30: =((E$30/E$18)*$E$3)/306.4*(1/AH$4*1000)/2 -> 0 | AI30: =((F$30/F$18)*$E$3)/306.4*(1/AI$4*1000)/2 -> 0 | AJ30: =((G$30/G$18)*$E$3)/306.4*(1/AJ$4*1000)/2 -> 0 | AK30: =((H$30/H$18)*$E$3)/306.4*(1/AK$4*1000)/2 -> 0 | AL30: =((I$30/I$18)*$E$3)/306.4*(1/AL$4*1000)/2 -> 0 | ... BE30: =((AB$30/AB$18)*$E$3)/306.4*(1/BE$4*1000)/2 -> 0 | BG30: 0.83541667 | BH30: =AE30*100/AE$39 -> 0 | BI30: =AF30*100/AF$39 -> 0 | BJ30: =AG30*100/AG$39 -> 0 | BK30: =AH30*100/AH$39 -> 0 | BL30: =AI30*100/AI$39 -> 0 | BM30: =AJ30*100/AJ$39 -> 0 | BN30: =AK30*100/AK$39 -> 0 | BO30: =AL30*100/AL$39 -> 0 | ... CH30: =BE30*100/BE$39 -> 0
A31: 20:4 | B31: 2198.7859 | C31: 1757.1146 | D31: 1731.3046 | E31: 910.5119 | F31: 872.6002 | G31: 1046.8848 | H31: 947.1623 | I31: 1090.3805 | J31: 1148.8748 | K31: 0 | L31: 0 | M31: 0 | N31: 0 | O31: 0 | P31: 0 | Q31: 0 | R31: 0 | S31: 0 | T31: 0 | U31: 0 | V31: 0 | W31: 0 | X31: 0 | Y31: 0 | Z31: 0 | AA31: 0 | AB31: 0 | AD31: C20:4, µmol/l | AE31: =((B$31/B$18)*$E$3)/304.4*(1/AE$4*1000)/2 -> 57.805107 | AF31: =((C$31/C$18)*$E$3)/304.4*(1/AF$4*1000)/2 -> 53.218732 | AG31: =((D$31/D$18)*$E$3)/304.4*(1/AG$4*1000)/2 -> 50.664948 | AH31: =((E$31/E$18)*$E$3)/304.4*(1/AH$4*1000)/2 -> 115.9644 | AI31: =((F$31/F$18)*$E$3)/304.4*(1/AI$4*1000)/2 -> 117.90675 | AJ31: =((G$31/G$18)*$E$3)/304.4*(1/AJ$4*1000)/2 -> 123.55671 | AK31: =((H$31/H$18)*$E$3)/304.4*(1/AK$4*1000)/2 -> 109.85796 | AL31: =((I$31/I$18)*$E$3)/304.4*(1/AL$4*1000)/2 -> 129.73603 | ... BE31: =((AB$31/AB$18)*$E$3)/304.4*(1/BE$4*1000)/2 -> 0 | BG31: 0.83611111 | BH31: =AE31*100/AE$39 -> 5.0314689 | BI31: =AF31*100/AF$39 -> 5.1275731 | BJ31: =AG31*100/AG$39 -> 4.9461272 | BK31: =AH31*100/AH$39 -> 10.527592 | BL31: =AI31*100/AI$39 -> 10.393026 | BM31: =AJ31*100/AJ$39 -> 10.519309 | BN31: =AK31*100/AK$39 -> 10.306607 | BO31: =AL31*100/AL$39 -> 10.800575 | ... CH31: =BE31*100/BE$39 -> 0
A32: 20:5 | B32: 0 | C32: 0 | D32: 0 | E32: 0 | F32: 0 | G32: 0 | H32: 0 | I32: 0 | J32: 0 | K32: 0 | L32: 0 | M32: 0 | N32: 0 | O32: 0 | P32: 0 | Q32: 0 | R32: 0 | S32: 0 | T32: 0 | U32: 0 | V32: 0 | W32: 0 | X32: 0 | Y32: 0 | Z32: 0 | AA32: 0 | AB32: 0 | AD32: C20:5, µmol/l | AE32: =((B$32/B$18)*$E$3)/302.5*(1/AE$4*1000)/2 -> 0 | AF32: =((C$32/C$18)*$E$3)/302.5*(1/AF$4*1000)/2 -> 0 | AG32: =((D$32/D$18)*$E$3)/302.5*(1/AG$4*1000)/2 -> 0 | AH32: =((E$32/E$18)*$E$3)/302.5*(1/AH$4*1000)/2 -> 0 | AI32: =((F$32/F$18)*$E$3)/302.5*(1/AI$4*1000)/2 -> 0 | AJ32: =((G$32/G$18)*$E$3)/302.5*(1/AJ$4*1000)/2 -> 0 | AK32: =((H$32/H$18)*$E$3)/302.5*(1/AK$4*1000)/2 -> 0 | AL32: =((I$32/I$18)*$E$3)/302.5*(1/AL$4*1000)/2 -> 0 | ... BE32: =((AB$32/AB$18)*$E$3)/302.5*(1/BE$4*1000)/2 -> 0 | BG32: 0.83680556 | BH32: =AE32*100/AE$39 -> 0 | BI32: =AF32*100/AF$39 -> 0 | BJ32: =AG32*100/AG$39 -> 0 | BK32: =AH32*100/AH$39 -> 0 | BL32: =AI32*100/AI$39 -> 0 | BM32: =AJ32*100/AJ$39 -> 0 | BN32: =AK32*100/AK$39 -> 0 | BO32: =AL32*100/AL$39 -> 0 | ... CH32: =BE32*100/BE$39 -> 0
A33: 22:0 | B33: 0 | C33: 0 | D33: 0 | E33: 0 | F33: 0 | G33: 0 | H33: 0 | I33: 0 | J33: 0 | K33: 0 | L33: 0 | M33: 0 | N33: 0 | O33: 0 | P33: 0 | Q33: 0 | R33: 0 | S33: 0 | T33: 0 | U33: 0 | V33: 0 | W33: 0 | X33: 0 | Y33: 0 | Z33: 0 | AA33: 0 | AB33: 0 | AD33: 0.91666667 | AE33: =((B$33/B$18)*$E$3)/340.5*(1/AE$4*1000)/2 -> 0 | AF33: =((C$33/C$18)*$E$3)/340.5*(1/AF$4*1000)/2 -> 0 | AG33: =((D$33/D$18)*$E$3)/340.5*(1/AG$4*1000)/2 -> 0 | AH33: =((E$33/E$18)*$E$3)/340.5*(1/AH$4*1000)/2 -> 0 | AI33: =((F$33/F$18)*$E$3)/340.5*(1/AI$4*1000)/2 -> 0 | AJ33: =((G$33/G$18)*$E$3)/340.5*(1/AJ$4*1000)/2 -> 0 | AK33: =((H$33/H$18)*$E$3)/340.5*(1/AK$4*1000)/2 -> 0 | AL33: =((I$33/I$18)*$E$3)/340.5*(1/AL$4*1000)/2 -> 0 | ... BE33: =((AB$33/AB$18)*$E$3)/340.5*(1/BE$4*1000)/2 -> 0 | BG33: 0.91666667 | BH33: =AE33*100/AE$39 -> 0 | BI33: =AF33*100/AF$39 -> 0 | BJ33: =AG33*100/AG$39 -> 0 | BK33: =AH33*100/AH$39 -> 0 | BL33: =AI33*100/AI$39 -> 0 | BM33: =AJ33*100/AJ$39 -> 0 | BN33: =AK33*100/AK$39 -> 0 | BO33: =AL33*100/AL$39 -> 0 | ... CH33: =BE33*100/BE$39 -> 0
A34: 22:1 | B34: 893.7165 | C34: 788.6093 | D34: 0 | E34: 0 | F34: 0 | G34: 0 | H34: 0 | I34: 0 | J34: 0 | K34: 0 | L34: 0 | M34: 0 | N34: 0 | O34: 0 | P34: 0 | Q34: 0 | R34: 0 | S34: 0 | T34: 0 | U34: 0 | V34: 0 | W34: 0 | X34: 0 | Y34: 0 | Z34: 0 | AA34: 0 | AB34: 0 | AD34: 0.91736111 | AE34: =((B$34/B$18)*$E$3)/338.5*(1/AE$4*1000)/2 -> 21.128517 | AF34: =((C$34/C$18)*$E$3)/338.5*(1/AF$4*1000)/2 -> 21.478913 | AG34: =((D$34/D$18)*$E$3)/338.5*(1/AG$4*1000)/2 -> 0 | AH34: =((E$34/E$18)*$E$3)/338.5*(1/AH$4*1000)/2 -> 0 | AI34: =((F$34/F$18)*$E$3)/338.5*(1/AI$4*1000)/2 -> 0 | AJ34: =((G$34/G$18)*$E$3)/338.5*(1/AJ$4*1000)/2 -> 0 | AK34: =((H$34/H$18)*$E$3)/338.5*(1/AK$4*1000)/2 -> 0 | AL34: =((I$34/I$18)*$E$3)/338.5*(1/AL$4*1000)/2 -> 0 | ... BE34: =((AB$34/AB$18)*$E$3)/338.5*(1/BE$4*1000)/2 -> 0 | BG34: 0.91736111 | BH34: =AE34*100/AE$39 -> 1.8390672 | BI34: =AF34*100/AF$39 -> 2.0694724 | BJ34: =AG34*100/AG$39 -> 0 | BK34: =AH34*100/AH$39 -> 0 | BL34: =AI34*100/AI$39 -> 0 | BM34: =AJ34*100/AJ$39 -> 0 | BN34: =AK34*100/AK$39 -> 0 | BO34: =AL34*100/AL$39 -> 0 | ... CH34: =BE34*100/BE$39 -> 0
A35: 22:2 | B35: 0 | C35: 0 | D35: 0 | E35: 0 | F35: 0 | G35: 0 | H35: 0 | I35: 0 | J35: 0 | K35: 0 | L35: 0 | M35: 0 | N35: 0 | O35: 0 | P35: 0 | Q35: 0 | R35: 0 | S35: 0 | T35: 0 | U35: 0 | V35: 0 | W35: 0 | X35: 0 | Y35: 0 | Z35: 0 | AA35: 0 | AB35: 0 | AD35: 0.91805556 | AE35: =((B$35/B$18)*$E$3)/336.5*(1/AE$4*1000)/2 -> 0 | AF35: =((C$35/C$18)*$E$3)/336.5*(1/AF$4*1000)/2 -> 0 | AG35: =((D$35/D$18)*$E$3)/336.5*(1/AG$4*1000)/2 -> 0 | AH35: =((E$35/E$18)*$E$3)/336.5*(1/AH$4*1000)/2 -> 0 | AI35: =((F$35/F$18)*$E$3)/336.5*(1/AI$4*1000)/2 -> 0 | AJ35: =((G$35/G$18)*$E$3)/336.5*(1/AJ$4*1000)/2 -> 0 | AK35: =((H$35/H$18)*$E$3)/336.5*(1/AK$4*1000)/2 -> 0 | AL35: =((I$35/I$18)*$E$3)/336.5*(1/AL$4*1000)/2 -> 0 | ... BE35: =((AB$35/AB$18)*$E$3)/336.5*(1/BE$4*1000)/2 -> 0 | BG35: 0.91805556 | BH35: =AE35*100/AE$39 -> 0 | BI35: =AF35*100/AF$39 -> 0 | BJ35: =AG35*100/AG$39 -> 0 | BK35: =AH35*100/AH$39 -> 0 | BL35: =AI35*100/AI$39 -> 0 | BM35: =AJ35*100/AJ$39 -> 0 | BN35: =AK35*100/AK$39 -> 0 | BO35: =AL35*100/AL$39 -> 0 | ... CH35: =BE35*100/BE$39 -> 0
A36: 23:0 | B36: 0 | C36: 0 | D36: 0 | E36: 0 | F36: 0 | G36: 0 | H36: 0 | I36: 0 | J36: 0 | K36: 10261.2256 | L36: 10260.7217 | M36: 10159.4756 | N36: 10509.8389 | O36: 11290.1045 | P36: 13713.3789 | Q36: 5312.4434 | R36: 5326.1016 | S36: 5546.8428 | T36: 5800.1807 | U36: 5607.1665 | V36: 5676.0249 | W36: 5420.1479 | X36: 5346.8921 | Y36: 5324.8633 | Z36: 5430.2427 | AA36: 5671.0806 | AB36: 5737.5151 | BG36: 0.95833333
A37: 22:5 | B37: 0 | C37: 0 | D37: 0 | E37: 0 | F37: 0 | G37: 0 | H37: 0 | I37: 0 | J37: 0 | K37: 0 | L37: 0 | M37: 0 | N37: 0 | O37: 0 | P37: 0 | Q37: 0 | R37: 0 | S37: 0 | T37: 0 | U37: 0 | V37: 0 | W37: 0 | X37: 0 | Y37: 0 | Z37: 0 | AA37: 0 | AB37: 0 | AD37: C22:5, µmol/l | AE37: =((B$37/B$18)*$E$3)/330.5*(1/AE$4*1000)/2 -> 0 | AF37: =((C$37/C$18)*$E$3)/330.5*(1/AF$4*1000)/2 -> 0 | AG37: =((D$37/D$18)*$E$3)/330.5*(1/AG$4*1000)/2 -> 0 | AH37: =((E$37/E$18)*$E$3)/330.5*(1/AH$4*1000)/2 -> 0 | AI37: =((F$37/F$18)*$E$3)/330.5*(1/AI$4*1000)/2 -> 0 | AJ37: =((G$37/G$18)*$E$3)/330.5*(1/AJ$4*1000)/2 -> 0 | AK37: =((H$37/H$18)*$E$3)/330.5*(1/AK$4*1000)/2 -> 0 | AL37: =((I$37/I$18)*$E$3)/330.5*(1/AL$4*1000)/2 -> 0 | ... BE37: =((AB$37/AB$18)*$E$3)/330.5*(1/BE$4*1000)/2 -> 0 | BG37: 0.92013889 | BH37: =AE37*100/AE$39 -> 0 | BI37: =AF37*100/AF$39 -> 0 | BJ37: =AG37*100/AG$39 -> 0 | BK37: =AH37*100/AH$39 -> 0 | BL37: =AI37*100/AI$39 -> 0 | BM37: =AJ37*100/AJ$39 -> 0 | BN37: =AK37*100/AK$39 -> 0 | BO37: =AL37*100/AL$39 -> 0 | ... CH37: =BE37*100/BE$39 -> 0
A38: 22:6 | B38: 0 | C38: 0 | D38: 0 | E38: 0 | F38: 0 | G38: 0 | H38: 0 | I38: 0 | J38: 0 | K38: 0 | L38: 0 | M38: 0 | N38: 0 | O38: 0 | P38: 0 | Q38: 0 | R38: 0 | S38: 0 | T38: 0 | U38: 0 | V38: 0 | W38: 0 | X38: 0 | Y38: 0 | Z38: 0 | AA38: 0 | AB38: 0 | AD38: C22:6, µmol/l | AE38: =((B$38/B$18)*$E$3)/328.5*(1/AE$4*1000)/2 -> 0 | AF38: =((C$38/C$18)*$E$3)/328.5*(1/AF$4*1000)/2 -> 0 | AG38: =((D$38/D$18)*$E$3)/328.5*(1/AG$4*1000)/2 -> 0 | AH38: =((E$38/E$18)*$E$3)/328.5*(1/AH$4*1000)/2 -> 0 | AI38: =((F$38/F$18)*$E$3)/328.5*(1/AI$4*1000)/2 -> 0 | AJ38: =((G$38/G$18)*$E$3)/328.5*(1/AJ$4*1000)/2 -> 0 | AK38: =((H$38/H$18)*$E$3)/328.5*(1/AK$4*1000)/2 -> 0 | AL38: =((I$38/I$18)*$E$3)/328.5*(1/AL$4*1000)/2 -> 0 | ... BE38: =((AB$38/AB$18)*$E$3)/328.5*(1/BE$4*1000)/2 -> 0 | BG38: 0.92083333 | BH38: =AE38*100/AE$39 -> 0 | BI38: =AF38*100/AF$39 -> 0 | BJ38: =AG38*100/AG$39 -> 0 | BK38: =AH38*100/AH$39 -> 0 | BL38: =AI38*100/AI$39 -> 0 | BM38: =AJ38*100/AJ$39 -> 0 | BN38: =AK38*100/AK$39 -> 0 | BO38: =AL38*100/AL$39 -> 0 | ... CH38: =BE38*100/BE$39 -> 0
AD39: total GC | AE39: =SUM(AE6:AE35,AE37:AE38) -> 1148.8714 | AF39: =SUM(AF6:AF35,AF37:AF38) -> 1037.8932 | AG39: =SUM(AG6:AG35,AG37:AG38) -> 1024.3357 | AH39: =SUM(AH6:AH35,AH37:AH38) -> 1101.5283 | AI39: =SUM(AI6:AI35,AI37:AI38) -> 1134.4794 | AJ39: =SUM(AJ6:AJ35,AJ37:AJ38) -> 1174.5705 | AK39: =SUM(AK6:AK35,AK37:AK38) -> 1065.8985 | AL39: =SUM(AL6:AL35,AL37:AL38) -> 1201.1955 | ... BE39: =SUM(BE6:BE35,BE37:BE38) -> 1786.1181
A40: recovery | B40: =((B18/B36)*($E$4/$E$3))*100 -> #DIV/0! | C40: =((C18/C36)*($E$4/$E$3))*100 -> #DIV/0! | D40: =((D18/D36)*($E$4/$E$3))*100 -> #DIV/0! | E40: =((E18/E36)*($E$4/$E$3))*100 -> #DIV/0! | F40: =((F18/F36)*($E$4/$E$3))*100 -> #DIV/0! | G40: =((G18/G36)*($E$4/$E$3))*100 -> #DIV/0! | H40: =((H18/H36)*($E$4/$E$3))*100 -> #DIV/0! | I40: =((I18/I36)*($E$4/$E$3))*100 -> #DIV/0! | ... AB40: =((AB18/AB36)*($E$4/$E$3))*100 -> 29.136333 | BH40: =SUM(BH6:BH38) -> 100 | BI40: =SUM(BI6:BI38) -> 100 | BJ40: =SUM(BJ6:BJ38) -> 100 | BK40: =SUM(BK6:BK38) -> 100 | BL40: =SUM(BL6:BL38) -> 100 | BM40: =SUM(BM6:BM38) -> 100 | BN40: =SUM(BN6:BN38) -> 100 | BO40: =SUM(BO6:BO38) -> 100 | ... CH40: =SUM(CH6:CH38) -> 100
AE42: 1148.8714 | AF42: 1037.8932 | AG42: 1024.3357 | AH42: 1101.5283 | AI42: 1134.4794 | AJ42: 1174.5705 | AK42: 1065.8985 | AL42: 1201.1955 | AM42: 1187.9506 | AN42: 1240.24 | AO42: 1334.9674 | AP42: 1418.4385 | AQ42: 1280.845 | AR42: 1242.3432 | AS42: 1109.1777 | AT42: 1142.5514 | AU42: 1446.3266 | AV42: 1342.8449 | AW42: 1339.4102 | AX42: 1712.0289 | AY42: 1447.6788 | AZ42: 1350.4446 | BA42: 1524.8405 | BB42: 1554.7384 | BC42: 1413.0583 | BD42: 1627.9729 | BE42: 1786.1181

Sheet TTRs 
A1: TG | B1: 0.66666667
A2: Sample | B2: Time | C2: 270 | D2: 271 | E2: TTR | F2: TTR - background | H2: %16:0 | J2: TG concentration (umol/l) | L2: 16:0 concentration (umol/l) | N2: U13C-16:0 concentration (umol/l)
B4: Background | E4: =D4/C4 -> #DIV/0! | F4: =E4-$E$4 -> #DIV/0! | H4: ='GC data'!BH15 -> 29.272064 | L4: =(H4/100)*J4 -> 0 | N4: =L4*F4 -> #DIV/0!
B6: 1 | E6: =D6/C6 -> #DIV/0! | F6: =E6-$E$4 -> #DIV/0! | H6: ='GC data'!BI$15 -> 28.575081 | L6: =(H6/100)*J6 -> 0 | N6: =L6*F6 -> #DIV/0!
B7: 2 | E7: =D7/C7 -> #DIV/0! | F7: =E7-$E$4 -> #DIV/0! | H7: ='GC data'!BJ$15 -> 29.09707 | L7: =(H7/100)*J7 -> 0 | N7: =L7*F7 -> #DIV/0!
B8: 3 | E8: =D8/C8 -> #DIV/0! | F8: =E8-$E$4 -> #DIV/0! | H8: ='GC data'!BK$15 -> 31.02591 | L8: =(H8/100)*J8 -> 0 | N8: =L8*F8 -> #DIV/0!
B9: 4 | E9: =D9/C9 -> #DIV/0! | F9: =E9-$E$4 -> #DIV/0! | H9: ='GC data'!BL$15 -> 31.188031 | L9: =(H9/100)*J9 -> 0 | N9: =L9*F9 -> #DIV/0!
B10: 5 | E10: =D10/C10 -> #DIV/0! | F10: =E10-$E$4 -> #DIV/0! | H10: ='GC data'!BM$15 -> 30.893427 | L10: =(H10/100)*J10 -> 0 | N10: =L10*F10 -> #DIV/0!
B11: 6 | E11: =D11/C11 -> #DIV/0! | F11: =E11-$E$4 -> #DIV/0! | H11: ='GC data'!BN$15 -> 32.881131 | L11: =(H11/100)*J11 -> 0 | N11: =L11*F11 -> #DIV/0!
B12: 7 | E12: =D12/C12 -> #DIV/0! | F12: =E12-$E$4 -> #DIV/0! | H12: ='GC data'!BO$15 -> 33.800365
B13: 8 | E13: =D13/C13 -> #DIV/0! | F13: =E13-$E$4 -> #DIV/0! | H13: ='GC data'!BP$15 -> 33.97765
B14: 9 | E14: =D14/C14 -> #DIV/0! | F14: =E14-$E$4 -> #DIV/0! | H14: ='GC data'!BO$15 -> 33.800365 | L14: =(H14/100)*J14 -> 0 | N14: =L14*F14 -> #DIV/0!
B15: 10 | E15: =D15/C15 -> #DIV/0! | F15: =E15-$E$4 -> #DIV/0! | H15: ='GC data'!BP$15 -> 33.97765 | L15: =(H15/100)*J15 -> 0 | N15: =L15*F15 -> #DIV/0!
B16: 11 | E16: =D16/C16 -> #DIV/0! | F16: =E16-$E$4 -> #DIV/0! | H16: ='GC data'!BQ$15 -> 22.076669 | L16: =(H16/100)*J16 -> 0 | N16: =L16*F16 -> #DIV/0!
B17: 12 | E17: =D17/C17 -> #DIV/0! | F17: =E17-$E$4 -> #DIV/0! | H17: ='GC data'!BR$15 -> 20.692454 | L17: =(H17/100)*J17 -> 0 | N17: =L17*F17 -> #DIV/0!
B18: 13 | E18: =D18/C18 -> #DIV/0! | F18: =E18-$E$4 -> #DIV/0! | H18: ='GC data'!BS$15 -> 23.277872 | L18: =(H18/100)*J18 -> 0 | N18: =L18*F18 -> #DIV/0!
B19: 14 | E19: =D19/C19 -> #DIV/0! | F19: =E19-$E$4 -> #DIV/0! | H19: ='GC data'!CD$15 -> 26.932003 | L19: =(H19/100)*J19 -> 0 | N19: =L19*F19 -> #DIV/0!
B20: 15 | E20: =D20/C20 -> #DIV/0! | F20: =E20-$E$4 -> #DIV/0! | H20: ='GC data'!#REF! -> #REF! | L20: =(H20/100)*J20 -> #REF! | N20: =L20*F20 -> #REF!
B21: 16 | E21: =D21/C21 -> #DIV/0! | F21: =E21-$E$4 -> #DIV/0! | H21: ='GC data'!#REF! -> #REF! | L21: =(H21/100)*J21 -> #REF! | N21: =L21*F21 -> #REF!
B22: 17 | E22: =D22/C22 -> #DIV/0! | F22: =E22-$E$4 -> #DIV/0! | H22: ='GC data'!#REF! -> #REF! | L22: =(H22/100)*J22 -> #REF! | N22: =L22*F22 -> #REF!
B23: 18 | E23: =D23/C23 -> #DIV/0! | F23: =E23-$E$4 -> #DIV/0! | H23: ='GC data'!#REF! -> #REF! | L23: =(H23/100)*J23 -> #REF! | N23: =L23*F23 -> #REF!
A27: 0.66736111
A28: Sample | B28: Time | C28: 268 | D28: 269 | E28: TTR | F28: TTR - background | H28: %16:01 | J28: TG concentration (umol/l) | L28: 16:01 concentration (umol/l) | N28: U13C-16:1 concentration (umol/l)
B30: Background | E30: =((D30/1000)+1)*0.0112372*17/16 -> 0.011939525 | F30: =E30-$E$30 -> 0 | H30: ='GC data'!#REF! -> #REF! | J30: =J4 -> 0 | L30: =(H30/100)*J30 -> #REF! | N30: =L30*F30 -> #REF!
E31: =((D31/1000)+1)*0.0112372*17/16 -> 0.011939525 | F31: =E31-$E$30 -> 0 | H31: ='GC data'!BH$17 -> 7.2062707 | J31: =J5 -> 0 | L31: =(H31/100)*J31 -> 0 | N31: =L31*F31 -> 0
B32: 1 | E32: =((D32/1000)+1)*0.0112372*17/16 -> 0.011939525 | F32: =E32-$E$30 -> 0 | H32: ='GC data'!BI$17 -> 6.733122 | J32: =J6 -> 0 | L32: =(H32/100)*J32 -> 0 | N32: =L32*F32 -> 0
B33: 2 | E33: =((D33/1000)+1)*0.0112372*17/16 -> 0.011939525 | F33: =E33-$E$30 -> 0 | H33: ='GC data'!BJ$17 -> 6.9192087 | J33: =J7 -> 0 | L33: =(H33/100)*J33 -> 0 | N33: =L33*F33 -> 0
B34: 3 | E34: =((D34/1000)+1)*0.0112372*17/16 -> 0.011939525 | F34: =E34-$E$30 -> 0 | H34: ='GC data'!BK$17 -> 0 | J34: =J8 -> 0 | L34: =(H34/100)*J34 -> 0 | N34: =L34*F34 -> 0
B35: 4 | E35: =((D35/1000)+1)*0.0112372*17/16 -> 0.011939525 | F35: =E35-$E$30 -> 0 | H35: ='GC data'!BL$17 -> 0 | J35: =J9 -> 0 | L35: =(H35/100)*J35 -> 0 | N35: =L35*F35 -> 0
B36: 5 | E36: =((D36/1000)+1)*0.0112372*17/16 -> 0.011939525 | F36: =E36-$E$30 -> 0 | H36: ='GC data'!BM$17 -> 0 | J36: =J10 -> 0 | L36: =(H36/100)*J36 -> 0 | N36: =L36*F36 -> 0
B37: 6 | E37: =((D37/1000)+1)*0.0112372*17/16 -> 0.011939525 | F37: =E37-$E$30 -> 0 | H37: ='GC data'!BN$17 -> 0 | J37: =J11 -> 0 | L37: =(H37/100)*J37 -> 0 | N37: =L37*F37 -> 0
B38: 7
B39: 8
B40: 9 | E40: =((D40/1000)+1)*0.0112372*17/16 -> 0.011939525 | F40: =E40-$E$40 -> 0 | H40: ='GC data'!BO$17 -> 0 | J40: =J14 -> 0 | L40: =(H40/100)*J40 -> 0 | N40: =L40*F40 -> 0
B41: 10 | E41: =((D41/1000)+1)*0.0112372*17/16 -> 0.011939525 | F41: =E41-$E$40 -> 0 | H41: ='GC data'!BP$17 -> 0 | J41: =J15 -> 0 | L41: =(H41/100)*J41 -> 0 | N41: =L41*F41 -> 0
B42: 11 | E42: =((D42/1000)+1)*0.0112372*17/16 -> 0.011939525 | F42: =E42-$E$40 -> 0 | H42: ='GC data'!BQ$17 -> 4.7685586 | J42: =J16 -> 0 | L42: =(H42/100)*J42 -> 0 | N42: =L42*F42 -> 0
B43: 12 | E43: =((D43/1000)+1)*0.0112372*17/16 -> 0.011939525 | F43: =E43-$E$40 -> 0 | H43: ='GC data'!BR$17 -> 6.1097941 | J43: =J17 -> 0 | L43: =(H43/100)*J43 -> 0 | N43: =L43*F43 -> 0
B44: 13 | E44: =((D44/1000)+1)*0.0112372*17/16 -> 0.011939525 | F44: =E44-$E$40 -> 0 | H44: ='GC data'!BS$17 -> 5.8469429 | J44: =J18 -> 0 | L44: =(H44/100)*J44 -> 0 | N44: =L44*F44 -> 0
B45: 14 | E45: =((D45/1000)+1)*0.0112372*17/16 -> 0.011939525 | F45: =E45-$E$40 -> 0 | H45: ='GC data'!CD$17 -> 0 | J45: =J19 -> 0 | L45: =(H45/100)*J45 -> 0 | N45: =L45*F45 -> 0
B46: 15 | E46: =((D46/1000)+1)*0.0112372*17/16 -> 0.011939525 | F46: =E46-$E$40 -> 0 | H46: ='GC data'!#REF! -> #REF! | J46: =J20 -> 0 | L46: =(H46/100)*J46 -> #REF! | N46: =L46*F46 -> #REF!
...
