Workbook

Sheet GC data
C2: Volume Standards = | D2: 150µl | E2: TAG
D3: µg Int std TG = | E3: =50.12/2 -> 25.06 | AD3: TG µmol per litre fraction | BH3: TG
A4: TAG | D4: µg ext std = | E4: =49.04/2 -> 24.52 | AD4: volume (ml) | AE4: 0.15 | AF4: 0.15 | AG4: 0.15 | AH4: 0.15 | AI4: 0.15 | AJ4: 0.15 | AK4: 0.15 | AL4: 0.15 | AM4: 0.15 | AN4: 0.15 | AO4: 0.15 | AP4: 0.15 | AQ4: 0.15 | AR4: 0.15 | AS4: 0.15 | AT4: 0.15 | AU4: 0.15 | AV4: 0.15 | AW4: 0.15 | AX4: 0.15 | AY4: 0.15 | AZ4: 0.15 | BA4: 0.15 | BB4: 0.15 | BC4: 0.15 | BD4: 0.15 | BE4: 0.15 | BH4: fatty acids expressed as mol %
A5: Sample: | B5: OPLA 0.1 | C5: OPLA 0.2 | D5: OPLA 0.3 | E5: OPLA 2.1 | F5: OPLA 2.2 | G5: OPLA 2.3 | H5: OPLA 8.1 | I5: OPLA 8.2 | J5: OPLA 8.3 | K5: OPLA 0.4 | L5: OPLA 0.5 | M5: OPLA 0.6 | N5: OPLA 0.7 | O5: OPLA 0.8 | P5: OPLA 0.9 | Q5: OPLA 2.4 | R5: OPLA 2.5 | S5: OPLA 2.6 | T5: OPLA 2.7 | U5: OPLA 2.8 | V5: OPLA 2.9 | W5: OPLA 8.4 | X5: OPLA 8.5 | Y5: OPLA 8.6 | Z5: OPLA 8.7 | AA5: OPLA 8.8 | AB5: OPLA 8.9 | AD5: Time Point | AE5: =B5 -> OPLA 0.1 | AF5: =C5 -> OPLA 0.2 | AG5: =D5 -> OPLA 0.3 | AH5: =E5 -> OPLA 2.1 | AI5: =F5 -> OPLA 2.2 | AJ5: =G5 -> OPLA 2.3 | AK5: =H5 -> OPLA 8.1 | AL5: =I5 -> OPLA 8.2 | ... BE5: =AB5 -> OPLA 8.9 | BI5: =AE5 -> OPLA 0.1 | BJ5: =AF5 -> OPLA 0.2 | BK5: =AG5 -> OPLA 0.3 | BL5: =AH5 -> OPLA 2.1 | BM5: =AI5 -> OPLA 2.2 | BN5: =AJ5 -> OPLA 2.3 | BO5: =AK5 -> OPLA 8.1 | BP5: =AL5 -> OPLA 8.2 | ... CI5: =BE5 -> OPLA 8.9 | CQ5: =BI5 -> OPLA 0.1 | CR5: =BJ5 -> OPLA 0.2 | CS5: =BK5 -> OPLA 0.3 | CT5: =BL5 -> OPLA 2.1 | CU5: =BM5 -> OPLA 2.2 | CV5: =BN5 -> OPLA 2.3 | CW5: =BO5 -> OPLA 8.1 | CX5: =BP5 -> OPLA 8.2 | ... DF5: =BX5 -> OPLA 2.4 | DG5: =#REF! -> #REF! | DH5: =#REF! -> #REF! | DI5: =#REF! -> #REF! | DJ5: =#REF! -> #REF!
A6: 8:0 | B6: 0 | C6: 0 | D6: 0 | E6: 0 | F6: 0 | G6: 0 | H6: 0 | I6: 0 | J6: 0 | K6: 0 | L6: 0 | M6: 0 | N6: 0 | O6: 0 | P6: 0 | Q6: 0 | R6: 0 | S6: 0 | T6: 0 | U6: 0 | V6: 0 | W6: 0 | X6: 0 | Y6: 0 | Z6: 0 | AA6: 0 | AB6: 0 | AD6: 0.33333333 | AE6: =((B$6/B$13)*$E$3)/144.4*(1/AE$4*1000)/3 -> 0 | AF6: =((C$6/C$13)*$E$3)/144.4*(1/AF$4*1000)/3 -> 0 | AG6: =((D$6/D$13)*$E$3)/144.4*(1/AG$4*1000)/3 -> 0 | AH6: =((E$6/E$13)*$E$3)/144.4*(1/AH$4*1000)/3 -> 0 | AI6: =((F$6/F$13)*$E$3)/144.4*(1/AI$4*1000)/3 -> 0 | AJ6: =((G$6/G$13)*$E$3)/144.4*(1/AJ$4*1000)/3 -> 0 | AK6: =((H$6/H$13)*$E$3)/144.4*(1/AK$4*1000)/3 -> 0 | AL6: =((I$6/I$13)*$E$3)/144.4*(1/AL$4*1000)/3 -> 0 | ... BE6: =((AB$6/AB$13)*$E$3)/144.4*(1/BE$4*1000)/3 -> 0 | BH6: 0.33333333 | BI6: =AE6*100/AE$39 -> 0 | BJ6: =AF6*100/AF$39 -> 0 | BK6: =AG6*100/AG$39 -> 0 | BL6: =AH6*100/AH$39 -> 0 | BM6: =AI6*100/AI$39 -> 0 | BN6: =AJ6*100/AJ$39 -> 0 | BO6: =AK6*100/AK$39 -> 0 | BP6: =AL6*100/AL$39 -> 0 | ... CI6: =BE6*100/BE$39 -> 0 | CP6: 18:2/16:0 | CQ6: =BI23/BI15 -> 0.17727022 | CR6: =BJ23/BJ15 -> 0.11213846 | CS6: =BK23/BK15 -> 0.11768583 | CT6: =BL23/BL15 -> 0.42717239 | CU6: =BM23/BM15 -> 0.43524639 | CV6: =BN23/BN15 -> 0.43314799 | CW6: =BO23/BO15 -> 0.43766327 | CX6: =BP23/BP15 -> 0.44525434 | ... DF6: =BX23/BX15 -> 0.26658858 | DG6: =#REF!/#REF! -> #REF! | DH6: =#REF!/#REF! -> #REF! | DI6: =#REF!/#REF! -> #REF! | DJ6: =#REF!/#REF! -> #REF!
A7: 10:0 | B7: 0 | C7: 0 | D7: 0 | E7: 0 | F7: 0 | G7: 0 | H7: 0 | I7: 0 | J7: 0 | K7: 0 | L7: 0 | M7: 0 | N7: 0 | O7: 0 | P7: 0 | Q7: 0 | R7: 0 | S7: 0 | T7: 0 | U7: 0 | V7: 0 | W7: 0 | X7: 0 | Y7: 0 | Z7: 0 | AA7: 0 | AB7: 0 | AD7: 0.41666667 | AE7: =((B$7/B$13)*$E$3)/172.4*(1/AE$4*1000)/3 -> 0 | AF7: =((C$7/C$13)*$E$3)/172.4*(1/AF$4*1000)/3 -> 0 | AG7: =((D$7/D$13)*$E$3)/172.4*(1/AG$4*1000)/3 -> 0 | AH7: =((E$7/E$13)*$E$3)/172.4*(1/AH$4*1000)/3 -> 0 | AI7: =((F$7/F$13)*$E$3)/172.4*(1/AI$4*1000)/3 -> 0 | AJ7: =((G$7/G$13)*$E$3)/172.4*(1/AJ$4*1000)/3 -> 0 | AK7: =((H$7/H$13)*$E$3)/172.4*(1/AK$4*1000)/3 -> 0 | AL7: =((I$7/I$13)*$E$3)/172.4*(1/AL$4*1000)/3 -> 0 | ... BE7: =((AB$7/AB$13)*$E$3)/172.4*(1/BE$4*1000)/3 -> 0 | BH7: 0.41666667 | BI7: =AE7*100/AE$39 -> 0 | BJ7: =AF7*100/AF$39 -> 0 | BK7: =AG7*100/AG$39 -> 0 | BL7: =AH7*100/AH$39 -> 0 | BM7: =AI7*100/AI$39 -> 0 | BN7: =AJ7*100/AJ$39 -> 0 | BO7: =AK7*100/AK$39 -> 0 | BP7: =AL7*100/AL$39 -> 0 | ... CI7: =BE7*100/BE$39 -> 0 | CP7: 16:1/16:0 | CQ7: =BI17/BI15 -> 0.57526656 | CR7: =BJ17/BJ15 -> 0.62481692 | CS7: =BK17/BK15 -> 0.57281124 | CT7: =BL17/BL15 -> 0.32174371 | CU7: =BM17/BM15 -> 0.31769027 | CV7: =BN17/BN15 -> 0.29704266 | CW7: =BO17/BO15 -> 0.1479098 | CX7: =BP17/BP15 -> 0.14579583 | ... DF7: =BX17/BX15 -> 0 | DG7: =#REF!/#REF! -> #REF! | DH7: =#REF!/#REF! -> #REF! | DI7: =#REF!/#REF! -> #REF! | DJ7: =#REF!/#REF! -> #REF!
A8: 11:0 | B8: 0 | C8: 0 | D8: 0 | E8: 0 | F8: 0 | G8: 0 | H8: 0 | I8: 0 | J8: 0 | K8: 0 | L8: 0 | M8: 0 | N8: 0 | O8: 0 | P8: 0 | Q8: 0 | R8: 0 | S8: 0 | T8: 0 | U8: 0 | V8: 0 | W8: 0 | X8: 0 | Y8: 0 | Z8: 0 | AA8: 0 | AB8: 0 | AD8: 0.45833333 | AE8: =((B$8/B$13)*$E$3)/172.4*(1/AE$4*1000)/3 -> 0 | AF8: =((C$8/C$13)*$E$3)/172.4*(1/AF$4*1000)/3 -> 0 | AG8: =((D$8/D$13)*$E$3)/172.4*(1/AG$4*1000)/3 -> 0 | AH8: =((E$8/E$13)*$E$3)/172.4*(1/AH$4*1000)/3 -> 0 | AI8: =((F$8/F$13)*$E$3)/172.4*(1/AI$4*1000)/3 -> 0 | AJ8: =((G$8/G$13)*$E$3)/172.4*(1/AJ$4*1000)/3 -> 0 | AK8: =((H$8/H$13)*$E$3)/172.4*(1/AK$4*1000)/3 -> 0 | AL8: =((I$8/I$13)*$E$3)/172.4*(1/AL$4*1000)/3 -> 0 | ... BE8: =((AB$8/AB$13)*$E$3)/172.4*(1/BE$4*1000)/3 -> 0 | BH8: 0.45833333 | BI8: =AE8*100/AE$39 -> 0 | BJ8: =AF8*100/AF$39 -> 0 | BK8: =AG8*100/AG$39 -> 0 | BL8: =AH8*100/AH$39 -> 0 | BM8: =AI8*100/AI$39 -> 0 | BN8: =AJ8*100/AJ$39 -> 0 | BO8: =AK8*100/AK$39 -> 0 | BP8: =AL8*100/AL$39 -> 0 | ... CI8: =BE8*100/BE$39 -> 0
A9: 12:0 | B9: 0 | C9: 0 | D9: 0 | E9: 48.8715 | F9: 35.9122 | G9: 41.4279 | H9: 0 | I9: 0 | J9: 0 | K9: 0 | L9: 0 | M9: 0 | N9: 0 | O9: 0 | P9: 0 | Q9: 0 | R9: 0 | S9: 0 | T9: 0 | U9: 0 | V9: 0 | W9: 0 | X9: 0 | Y9: 0 | Z9: 0 | AA9: 0 | AB9: 0 | AD9: 0.5 | AE9: =((B$9/B$13)*$E$3)/200.4*(1/AE$4*1000)/3 -> 0 | AF9: =((C$9/C$13)*$E$3)/200.4*(1/AF$4*1000)/3 -> 0 | AG9: =((D$9/D$13)*$E$3)/200.4*(1/AG$4*1000)/3 -> 0 | AH9: =((E$9/E$13)*$E$3)/200.4*(1/AH$4*1000)/3 -> 4.4827428 | AI9: =((F$9/F$13)*$E$3)/200.4*(1/AI$4*1000)/3 -> 3.0308047 | AJ9: =((G$9/G$13)*$E$3)/200.4*(1/AJ$4*1000)/3 -> 3.5473126 | AK9: =((H$9/H$13)*$E$3)/200.4*(1/AK$4*1000)/3 -> 0 | AL9: =((I$9/I$13)*$E$3)/200.4*(1/AL$4*1000)/3 -> 0 | ... BE9: =((AB$9/AB$13)*$E$3)/200.4*(1/BE$4*1000)/3 -> 0 | BH9: 0.5 | BI9: =AE9*100/AE$39 -> 0 | BJ9: =AF9*100/AF$39 -> 0 | BK9: =AG9*100/AG$39 -> 0 | BL9: =AH9*100/AH$39 -> 0.57254419 | BM9: =AI9*100/AI$39 -> 0.34928426 | BN9: =AJ9*100/AJ$39 -> 0.42107949 | BO9: =AK9*100/AK$39 -> 0 | BP9: =AL9*100/AL$39 -> 0 | ... CI9: =BE9*100/BE$39 -> 0
A10: 13:0/BHT | B10: 338.4563 | C10: 2610.1418 | D10: 2404.0522 | E10: 645.9671 | F10: 708.8383 | G10: 745.2022 | H10: 766.181 | I10: 792.9659 | J10: 763.8168 | K10: 0 | L10: 0 | M10: 0 | N10: 0 | O10: 0 | P10: 0 | Q10: 0 | R10: 0 | S10: 0 | T10: 0 | U10: 0 | V10: 0 | W10: 0 | X10: 0 | Y10: 0 | Z10: 0 | AA10: 0 | AB10: 0 | BH10: 0.54166667
A11: 14:0 | B11: 135.3845 | C11: 365.559 | D11: 309.8371 | E11: 240.8981 | F11: 280.7737 | G11: 289.577 | H11: 535.7114 | I11: 636.6661 | J11: 596.6958 | K11: 0 | L11: 0 | M11: 0 | N11: 0 | O11: 0 | P11: 0 | Q11: 0 | R11: 90.5912 | S11: 51.3615 | T11: 0 | U11: 123.9022 | V11: 57.8532 | W11: 241.1073 | X11: 235.2502 | Y11: 253.1650 | Z11: 210.0910 | AA11: 265.4598 | AB11: 294.0255 | AD11: C14:0, µmol/l | AE11: =((B$11/B$13)*$E$3)/228.4*(1/AE$4*1000)/3 -> 4.1124125 | AF11: =((C$11/C$13)*$E$3)/228.4*(1/AF$4*1000)/3 -> 7.1519817 | AG11: =((D$11/D$13)*$E$3)/228.4*(1/AG$4*1000)/3 -> 6.1005762 | AH11: =((E$11/E$13)*$E$3)/228.4*(1/AH$4*1000)/3 -> 19.38756 | AI11: =((F$11/F$13)*$E$3)/228.4*(1/AI$4*1000)/3 -> 20.790933 | AJ11: =((G$11/G$13)*$E$3)/228.4*(1/AJ$4*1000)/3 -> 21.755658 | AK11: =((H$11/H$13)*$E$3)/228.4*(1/AK$4*1000)/3 -> 39.647537 | AL11: =((I$11/I$13)*$E$3)/228.4*(1/AL$4*1000)/3 -> 45.393467 | ... BE11: =((AB$11/AB$13)*$E$3)/228.4*(1/BE$4*1000)/3 -> 48.00864 | BH11: 0.58333333 | BI11: =AE11*100/AE$39 -> 2.467292 | BJ11: =AF11*100/AF$39 -> 4.9932233 | BK11: =AG11*100/AG$39 -> 4.0884288 | BL11: =AH11*100/AH$39 -> 2.4762149 | BM11: =AI11*100/AI$39 -> 2.3960454 | BN11: =AJ11*100/AJ$39 -> 2.5824793 | BO11: =AK11*100/AK$39 -> 1.3179815 | BP11: =AL11*100/AL$39 -> 1.3072657 | ... CI11: =BE11*100/BE$39 -> 1.1233799
A12: 14:1 | B12: 0 | C12: 255.4364 | D12: 257.423 | E12: 0 | F12: 0 | G12: 0 | H12: 0 | I12: 0 | J12: 0 | K12: 0 | L12: 0 | M12: 0 | N12: 0 | O12: 0 | P12: 0 | Q12: 0 | R12: 0 | S12: 0 | T12: 0 | U12: 0 | V12: 0 | W12: 0 | X12: 0 | Y12: 0 | Z12: 0 | AA12: 0 | AB12: 0 | AD12: 0.58402778 | AE12: =((B$12/B$13)*$E$3)/226.4*(1/AE$4*1000)/3 -> 0 | AF12: =((C$12/C$13)*$E$3)/226.4*(1/AF$4*1000)/3 -> 5.0416347 | AG12: =((D$12/D$13)*$E$3)/226.4*(1/AG$4*1000)/3 -> 5.1133375 | AH12: =((E$12/E$13)*$E$3)/226.4*(1/AH$4*1000)/3 -> 0 | AI12: =((F$12/F$13)*$E$3)/226.4*(1/AI$4*1000)/3 -> 0 | AJ12: =((G$12/G$13)*$E$3)/226.4*(1/AJ$4*1000)/3 -> 0 | AK12: =((H$12/H$13)*$E$3)/226.4*(1/AK$4*1000)/3 -> 0 | AL12: =((I$12/I$13)*$E$3)/226.4*(1/AL$4*1000)/3 -> 0 | ... BE12: =((AB$12/AB$13)*$E$3)/226.4*(1/BE$4*1000)/3 -> 0 | BH12: 0.58402778 | BI12: =AE12*100/AE$39 -> 0 | BJ12: =AF12*100/AF$39 -> 3.5198647 | BK12: =AG12*100/AG$39 -> 3.4268102 | BL12: =AH12*100/AH$39 -> 0 | BM12: =AI12*100/AI$39 -> 0 | BN12: =AJ12*100/AJ$39 -> 0 | BO12: =AK12*100/AK$39 -> 0 | BP12: =AL12*100/AL$39 -> 0 | ... CI12: =BE12*100/BE$39 -> 0
A13: 15:0 | B13: 8026.8423 | C13: 12462.453 | D13: 12383.261 | E13: 3029.5818 | F13: 3292.7207 | G13: 3245.3706 | H13: 3294.4819 | I13: 3419.7222 | J13: 3082.3313 | K13: 10101.9902 | L13: 9342.5781 | M13: 8509.6357 | N13: 6293.4707 | O13: 10715.7041 | P13: 10812.4258 | Q13: 789.3038 | R13: 1313.3916 | S13: 974.9233 | T13: 1020.4738 | U13: 1453.2332 | V13: 1120.6677 | W13: 1514.3253 | X13: 1487.8322 | Y13: 1352.6354 | Z13: 1454.1211 | AA13: 1637.8214 | AB13: 1493.2690 | BH13: 0.625 | BS13: =AO13*100/AO$39 -> 0 | BT13: =AP13*100/AP$39 -> 0 | BU13: =AQ13*100/AQ$39 -> 0 | BV13: =AR13*100/AR$39 -> 0 | BW13: =AS13*100/AS$39 -> 0 | BX13: =AT13*100/AT$39 -> 0 | BY13: =AU13*100/AU$39 -> 0 | BZ13: =AV13*100/AV$39 -> 0 | ... CI13: =BE13*100/BE$39 -> 0
A14: 15:1 | B14: 0 | C14: 0 | D14: 0 | E14: 0 | F14: 0 | G14: 0 | H14: 0 | I14: 0 | J14: 0 | K14: 0 | L14: 0 | M14: 0 | N14: 0 | O14: 0 | P14: 0 | Q14: 0 | R14: 0 | S14: 0 | T14: 0 | U14: 0 | V14: 0 | W14: 0 | X14: 0 | Y14: 0 | Z14: 0 | AA14: 0 | AB14: 0 | AD14: 0.62569444 | AE14: =((B$14/B$13)*$E$3)/240.4*(1/AE$4*1000)/3 -> 0 | AF14: =((C$14/C$13)*$E$3)/240.4*(1/AF$4*1000)/3 -> 0 | AG14: =((D$14/D$13)*$E$3)/240.4*(1/AG$4*1000)/3 -> 0 | AH14: =((E$14/E$13)*$E$3)/240.4*(1/AH$4*1000)/3 -> 0 | AI14: =((F$14/F$13)*$E$3)/240.4*(1/AI$4*1000)/3 -> 0 | AJ14: =((G$14/G$13)*$E$3)/240.4*(1/AJ$4*1000)/3 -> 0 | AK14: =((H$14/H$13)*$E$3)/240.4*(1/AK$4*1000)/3 -> 0 | AL14: =((I$14/I$13)*$E$3)/240.4*(1/AL$4*1000)/3 -> 0 | ... BE14: =((AB$14/AB$13)*$E$3)/240.4*(1/BE$4*1000)/3 -> 0 | BH14: 0.62569444 | BI14: =AE14*100/AE$39 -> 0 | BJ14: =AF14*100/AF$39 -> 0 | BK14: =AG14*100/AG$39 -> 0 | BL14: =AH14*100/AH$39 -> 0 | BM14: =AI14*100/AI$39 -> 0 | BN14: =AJ14*100/AJ$39 -> 0 | BO14: =AK14*100/AK$39 -> 0 | BP14: =AL14*100/AL$39 -> 0 | ... CI14: =BE14*100/BE$39 -> 0
A15: 16:0 | B15: 1446.9866 | C15: 2042.4734 | D15: 2212.0957 | E15: 2207.6548 | F15: 2694.2439 | G15: 2679.6091 | H15: 12020.965 | I15: 14305.819 | J15: 13435.509 | K15: 953.4045 | L15: 1168.8877 | M15: 1124.2815 | N15: 0 | O15: 718.0640 | P15: 617.5596 | Q15: 500.7346 | R15: 1057.2197 | S15: 811.9260 | T15: 842.6141 | U15: 1272.9814 | V15: 1079.9814 | W15: 5550.6992 | X15: 5958.5884 | Y15: 5966.4907 | Z15: 5346.3662 | AA15: 6788.5142 | AB15: 6352.6074 | AD15: C16:0, µmol/l | AE15: =((B$15/B$13)*$E$3)/256.4*(1/AE$4*1000)/3 -> 39.153475 | AF15: =((C$15/C$13)*$E$3)/256.4*(1/AF$4*1000)/3 -> 35.596181 | AG15: =((D$15/D$13)*$E$3)/256.4*(1/AG$4*1000)/3 -> 38.798901 | AH15: =((E$15/E$13)*$E$3)/256.4*(1/AH$4*1000)/3 -> 158.27015 | AI15: =((F$15/F$13)*$E$3)/256.4*(1/AI$4*1000)/3 -> 177.71846 | AJ15: =((G$15/G$13)*$E$3)/256.4*(1/AJ$4*1000)/3 -> 179.33195 | AK15: =((H$15/H$13)*$E$3)/256.4*(1/AK$4*1000)/3 -> 792.50632 | AL15: =((I$15/I$13)*$E$3)/256.4*(1/AL$4*1000)/3 -> 908.59939 | ... BE15: =((AB$15/AB$13)*$E$3)/256.4*(1/BE$4*1000)/3 -> 923.9841 | BH15: 0.66666667 | BI15: =AE15*100/AE$39 -> 23.490604 | BJ15: =AF15*100/AF$39 -> 24.851808 | BK15: =AG15*100/AG$39 -> 26.001896 | BL15: =AH15*100/AH$39 -> 20.214556 | BM15: =AI15*100/AI$39 -> 20.481116 | BN15: =AJ15*100/AJ$39 -> 21.287385 | BO15: =AK15*100/AK$39 -> 26.344857 | BP15: =AL15*100/AL$39 -> 26.166338 | ... CI15: =BE15*100/BE$39 -> 21.6208
A16: 16:sap | B16: 0 | C16: 0 | D16: 0 | E16: 547.9069 | F16: 702.7561 | G16: 575.5818 | H16: 1128.6031 | I16: 1171.4453 | J16: 1073.7979 | K16: 0 | L16: 0 | M16: 0 | N16: 0 | O16: 0 | P16: 0 | Q16: 0 | R16: 184.7241 | S16: 139.9272 | T16: 198.6890 | U16: 244.4139 | V16: 157.2466 | W16: 421.5763 | X16: 585.1436 | Y16: 514.6823 | Z16: 496.9091 | AA16: 787.1721 | AB16: 619.8956 | BH16: 16:s
A17: 16:1 | B17: 825.91 | C17: 1266.2174 | D17: 1257.2294 | E17: 704.7585 | F17: 849.2585 | G17: 789.7495 | H17: 1764.1494 | I17: 2069.4595 | J17: 1841.5922 | K17: 0 | L17: 239.5800 | M17: 547.3601 | N17: 0 | O17: 0 | P17: 0 | Q17: 0 | R17: 258.7943 | S17: 215.3560 | T17: 343.9264 | U17: 381.4141 | V17: 226.2306 | W17: 684.0268 | X17: 978.7969 | Y17: 825.8823 | Z17: 766.8342 | AA17: 944.5797 | AB17: 898.5949 | AD17: C16:1, µmol/l | AE17: =((B$17/B$13)*$E$3)/254.4*(1/AE$4*1000)/3 -> 22.523685 | AF17: =((C$17/C$13)*$E$3)/254.4*(1/AF$4*1000)/3 -> 22.241096 | AG17: =((D$17/D$13)*$E$3)/254.4*(1/AG$4*1000)/3 -> 22.224447 | AH17: =((E$17/E$13)*$E$3)/254.4*(1/AH$4*1000)/3 -> 50.922426 | AI17: =((F$17/F$13)*$E$3)/254.4*(1/AI$4*1000)/3 -> 56.459425 | AJ17: =((G$17/G$13)*$E$3)/254.4*(1/AJ$4*1000)/3 -> 53.269241 | AK17: =((H$17/H$13)*$E$3)/254.4*(1/AK$4*1000)/3 -> 117.21945 | AL17: =((I$17/I$13)*$E$3)/254.4*(1/AL$4*1000)/3 -> 132.47 | ... BE17: =((AB$17/AB$13)*$E$3)/254.4*(1/BE$4*1000)/3 -> 131.72777 | BH17: 0.66736111 | BI17: =AE17*100/AE$39 -> 13.513359 | BJ17: =AF17*100/AF$39 -> 15.52783 | BK17: =AG17*100/AG$39 -> 14.894178 | BL17: =AH17*100/AH$39 -> 6.5039063 | BM17: =AI17*100/AI$39 -> 6.5066511 | BN17: =AJ17*100/AJ$39 -> 6.3232615 | BO17: =AK17*100/AK$39 -> 3.8966625 | BP17: =AL17*100/AL$39 -> 3.814943 | ... CI17: =BE17*100/BE$39 -> 3.0823689
A18: 17:0 | B18: 0 | C18: 0 | D18: 0 | E18: 0 | F18: 0 | G18: 0 | H18: 0 | I18: 0 | J18: 0 | K18: 0 | L18: 0 | M18: 0 | N18: 0 | O18: 0 | P18: 0 | Q18: 0 | R18: 0 | S18: 0 | T18: 0 | U18: 0 | V18: 0 | W18: 0 | X18: 0 | Y18: 0 | Z18: 0 | AA18: 0 | AB18: 0 | AD18: 0.70833333 | AE18: =((B$18/B$13)*$E$3)/270.4*(1/AE$4*1000)/3 -> 0 | AF18: =((C$18/C$13)*$E$3)/270.4*(1/AF$4*1000)/3 -> 0 | AG18: =((D$18/D$13)*$E$3)/270.4*(1/AG$4*1000)/3 -> 0 | AH18: =((E$18/E$13)*$E$3)/270.4*(1/AH$4*1000)/3 -> 0 | AI18: =((F$18/F$13)*$E$3)/270.4*(1/AI$4*1000)/3 -> 0 | AJ18: =((G$18/G$13)*$E$3)/270.4*(1/AJ$4*1000)/3 -> 0 | AK18: =((H$18/H$13)*$E$3)/270.4*(1/AK$4*1000)/3 -> 0 | AL18: =((I$18/I$13)*$E$3)/270.4*(1/AL$4*1000)/3 -> 0 | ... BE18: =((AB$18/AB$13)*$E$3)/270.4*(1/BE$4*1000)/3 -> 0 | BH18: 0.70833333 | BI18: =AE18*100/AE$39 -> 0 | BJ18: =AF18*100/AF$39 -> 0 | BK18: =AG18*100/AG$39 -> 0 | BL18: =AH18*100/AH$39 -> 0 | BM18: =AI18*100/AI$39 -> 0 | BN18: =AJ18*100/AJ$39 -> 0 | BO18: =AK18*100/AK$39 -> 0 | BP18: =AL18*100/AL$39 -> 0 | ... CI18: =BE18*100/BE$39 -> 0
A19: 17:1 | B19: 0 | C19: 0 | D19: 0 | E19: 0 | F19: 0 | G19: 0 | H19: 0 | I19: 0 | J19: 0 | K19: 0 | L19: 0 | M19: 0 | N19: 0 | O19: 0 | P19: 0 | Q19: 0 | R19: 0 | S19: 0 | T19: 0 | U19: 0 | V19: 0 | W19: 0 | X19: 0 | Y19: 0 | Z19: 0 | AA19: 0 | AB19: 0 | BH19: 0.70902778
A20: 18:0 | B20: 571.2721 | C20: 498.234 | D20: 559.0979 | E20: 238.8276 | F20: 357.481 | G20: 397.3002 | H20: 638.1041 | I20: 796.3262 | J20: 773.7837 | K20: 0 | L20: 456.7068 | M20: 437.0486 | N20: 0 | O20: 0 | P20: 0 | Q20: 0 | R20: 0 | S20: 0 | T20: 0 | U20: 0 | V20: 0 | W20: 730.6750 | X20: 831.6392 | Y20: 793.7132 | Z20: 635.6973 | AA20: 844.5223 | AB20: 787.2761 | AD20: C18:0, µmol/l | AE20: =((B$20/B$13)*$E$3)/284.4*(1/AE$4*1000)/3 -> 13.935971 | AF20: =((C$20/C$13)*$E$3)/284.4*(1/AF$4*1000)/3 -> 7.8283239 | AG20: =((D$20/D$13)*$E$3)/284.4*(1/AG$4*1000)/3 -> 8.8408049 | AH20: =((E$20/E$13)*$E$3)/284.4*(1/AH$4*1000)/3 -> 15.436214 | AI20: =((F$20/F$13)*$E$3)/284.4*(1/AI$4*1000)/3 -> 21.258716 | AJ20: =((G$20/G$13)*$E$3)/284.4*(1/AJ$4*1000)/3 -> 23.971403 | AK20: =((H$20/H$13)*$E$3)/284.4*(1/AK$4*1000)/3 -> 37.926553 | AL20: =((I$20/I$13)*$E$3)/284.4*(1/AL$4*1000)/3 -> 45.597301 | ... BE20: =((AB$20/AB$13)*$E$3)/284.4*(1/BE$4*1000)/3 -> 103.23524 | BH20: 0.75 | BI20: =AE20*100/AE$39 -> 8.3610558 | BJ20: =AF20*100/AF$39 -> 5.4654179 | BK20: =AG20*100/AG$39 -> 5.9248504 | BL20: =AH20*100/AH$39 -> 1.9715418 | BM20: =AI20*100/AI$39 -> 2.4499549 | BN20: =AJ20*100/AJ$39 -> 2.8454967 | BO20: =AK20*100/AK$39 -> 1.2607718 | BP20: =AL20*100/AL$39 -> 1.3131358 | ... CI20: =BE20*100/BE$39 -> 2.4156569
A21: 18:1 | B21: 2287.095 | C21: 2989.9719 | D21: 3119.6499 | E21: 7172.1655 | F21: 8209.4316 | G21: 7676.1016 | H21: 25985.738 | I21: 30956.146 | J21: 29130.135 | K21: 1571.3676 | L21: 2118.8706 | M21: 1955.9019 | N21: 778.7027 | O21: 1337.2318 | P21: 1068.8701 | Q21: 1811.6366 | R21: 3708.8296 | S21: 2879.2048 | T21: 3277.4141 | U21: 5030.2324 | V21: 4088.0967 | W21: 15427.8730 | X21: 17234.9609 | Y21: 16352.7881 | Z21: 15203.6523 | AA21: 19986.8262 | AB21: 18903.3008 | AD21: C18:1, µmol/l | AE21: =((B$21/B$13)*$E$3)/282.4*(1/AE$4*1000)/3 -> 56.187969 | AF21: =((C$21/C$13)*$E$3)/282.4*(1/AF$4*1000)/3 -> 47.311578 | AG21: =((D$21/D$13)*$E$3)/282.4*(1/AG$4*1000)/3 -> 49.679212 | AH21: =((E$21/E$13)*$E$3)/282.4*(1/AH$4*1000)/3 -> 466.84368 | AI21: =((F$21/F$13)*$E$3)/282.4*(1/AI$4*1000)/3 -> 491.65681 | AJ21: =((G$21/G$13)*$E$3)/282.4*(1/AJ$4*1000)/3 -> 466.42334 | AK21: =((H$21/H$13)*$E$3)/282.4*(1/AK$4*1000)/3 -> 1555.4347 | AL21: =((I$21/I$13)*$E$3)/282.4*(1/AL$4*1000)/3 -> 1785.0892 | ... BE21: =((AB$21/AB$13)*$E$3)/282.4*(1/BE$4*1000)/3 -> 2496.3384 | BH21: 0.75069444 | BI21: =AE21*100/AE$39 -> 33.710656 | BJ21: =AF21*100/AF$39 -> 33.031023 | BK21: =AG21*100/AG$39 -> 33.293564 | BL21: =AH21*100/AH$39 -> 59.626137 | BM21: =AI21*100/AI$39 -> 56.660855 | BN21: =AJ21*100/AJ$39 -> 55.366225 | BO21: =AK21*100/AK$39 -> 51.706472 | BP21: =AL21*100/AL$39 -> 51.407967 | ... CI21: =BE21*100/BE$39 -> 58.413163
A22: 18.1v | B22: 680.9717 | C22: 705.2084 | D22: 780.8837 | E22: 0 | F22: 324.8026 | G22: 270.8358 | H22: 0 | I22: 0 | J22: 0 | K22: 432.7260 | L22: 568.4725 | M22: 538.1964 | N22: 0 | O22: 0 | P22: 0 | Q22: 0 | R22: 0 | S22: 0 | T22: 0 | U22: 0 | V22: 0 | W22: 0 | X22: 0 | Y22: 0 | Z22: 0 | AA22: 0 | AB22: 0 | AD22: 18.01v | AE22: =((B$22/B$13)*$E$3)/282.4*(1/AE$4*1000)/3 -> 16.729702 | AF22: =((C$22/C$13)*$E$3)/282.4*(1/AF$4*1000)/3 -> 11.158808 | AG22: =((D$22/D$13)*$E$3)/282.4*(1/AG$4*1000)/3 -> 12.43527 | AH22: =((E$22/E$13)*$E$3)/282.4*(1/AH$4*1000)/3 -> 0 | AI22: =((F$22/F$13)*$E$3)/282.4*(1/AI$4*1000)/3 -> 19.452188 | AJ22: =((G$22/G$13)*$E$3)/282.4*(1/AJ$4*1000)/3 -> 16.456809 | AK22: =((H$22/H$13)*$E$3)/282.4*(1/AK$4*1000)/3 -> 0 | AL22: =((I$22/I$13)*$E$3)/282.4*(1/AL$4*1000)/3 -> 0 | ... BE22: =((AB$22/AB$13)*$E$3)/282.4*(1/BE$4*1000)/3 -> 0 | BH22: 18.01v | BI22: =AE22*100/AE$39 -> 10.037188 | BJ22: =AF22*100/AF$39 -> 7.7906267 | BK22: =AG22*100/AG$39 -> 8.3337561 | BL22: =AH22*100/AH$39 -> 0 | BM22: =AI22*100/AI$39 -> 2.2417621 | BN22: =AJ22*100/AJ$39 -> 1.9534858 | BO22: =AK22*100/AK$39 -> 0 | BP22: =AL22*100/AL$39 -> 0 | ... CI22: =BE22*100/BE$39 -> 0
A23: 18:2 | B23: 280.5177 | C23: 250.4788 | D23: 284.7004 | E23: 1031.3221 | F23: 1282.4253 | G23: 1269.3101 | H23: 5753.5967 | I23: 6965.9585 | J23: 6652.2104 | K23: 0 | L23: 0 | M23: 0 | N23: 0 | O23: 0 | P23: 0 | Q23: 145.9853 | R23: 366.6845 | S23: 273.7926 | T23: 350.4580 | U23: 662.0326 | V23: 585.5858 | W23: 3186.4404 | X23: 3597.1699 | Y23: 3410.7556 | Z23: 3096.7666 | AA23: 4083.2332 | AB23: 3842.9397 | AD23: C18:2, µmol/l | AE23: =((B$23/B$13)*$E$3)/280.4*(1/AE$4*1000)/3 -> 6.9407449 | AF23: =((C$23/C$13)*$E$3)/280.4*(1/AF$4*1000)/3 -> 3.9917008 | AG23: =((D$23/D$13)*$E$3)/280.4*(1/AG$4*1000)/3 -> 4.5660809 | AH23: =((E$23/E$13)*$E$3)/280.4*(1/AH$4*1000)/3 -> 67.608638 | AI23: =((F$23/F$13)*$E$3)/280.4*(1/AI$4*1000)/3 -> 77.35132 | AJ23: =((G$23/G$13)*$E$3)/280.4*(1/AJ$4*1000)/3 -> 77.677275 | AK23: =((H$23/H$13)*$E$3)/280.4*(1/AK$4*1000)/3 -> 346.85091 | AL23: =((I$23/I$13)*$E$3)/280.4*(1/AL$4*1000)/3 -> 404.55782 | ... BE23: =((AB$23/AB$13)*$E$3)/280.4*(1/BE$4*1000)/3 -> 511.11198 | BH23: 0.75138889 | BI23: =AE23*100/AE$39 -> 4.1641844 | BJ23: =AF23*100/AF$39 -> 2.7868434 | BK23: =AG23*100/AG$39 -> 3.0600547 | BL23: =AH23*100/AH$39 -> 8.6351001 | BM23: =AI23*100/AI$39 -> 8.9143317 | BN23: =AJ23*100/AJ$39 -> 9.2205879 | BO23: =AK23*100/AK$39 -> 11.530176 | BP23: =AL23*100/AL$39 -> 11.650675 | ... CI23: =BE23*100/BE$39 -> 11.959784
A24: 18:3g | B24: 0 | C24: 24.0941 | D24: 0 | E24: 0 | F24: 0 | G24: 0 | H24: 742.7986 | I24: 850.4581 | J24: 787.3008 | K24: 0 | L24: 0 | M24: 0 | N24: 0 | O24: 0 | P24: 0 | Q24: 0 | R24: 0 | S24: 0 | T24: 0 | U24: 0 | V24: 0 | W24: 0 | X24: 0 | Y24: 0 | Z24: 0 | AA24: 461.3248 | AB24: 0 | AD24: C18:3, µmol/l | AE24: =((B$24/B$13)*$E$3)/278.4*(1/AE$4*1000)/3 -> 0 | AF24: =((C$24/C$13)*$E$3)/278.4*(1/AF$4*1000)/3 -> 0.38672878 | AG24: =((D$24/D$13)*$E$3)/278.4*(1/AG$4*1000)/3 -> 0 | AH24: =((E$24/E$13)*$E$3)/278.4*(1/AH$4*1000)/3 -> 0 | AI24: =((F$24/F$13)*$E$3)/278.4*(1/AI$4*1000)/3 -> 0 | AJ24: =((G$24/G$13)*$E$3)/278.4*(1/AJ$4*1000)/3 -> 0 | AK24: =((H$24/H$13)*$E$3)/278.4*(1/AK$4*1000)/3 -> 45.100699 | AL24: =((I$24/I$13)*$E$3)/278.4*(1/AL$4*1000)/3 -> 49.746372 | ... BE24: =((AB$24/AB$13)*$E$3)/278.4*(1/BE$4*1000)/3 -> 0 | BH24: 18:3 g | BI24: =AE24*100/AE$39 -> 0 | BJ24: =AF24*100/AF$39 -> 0.26999833 | BK24: =AG24*100/AG$39 -> 0 | BL24: =AH24*100/AH$39 -> 0 | BM24: =AI24*100/AI$39 -> 0 | BN24: =AJ24*100/AJ$39 -> 0 | BO24: =AK24*100/AK$39 -> 1.499258 | BP24: =AL24*100/AL$39 -> 1.432623 | ... CI24: =BE24*100/BE$39 -> 0
A25: 18:3a | B25: 284.6351 | C25: 157.359 | D25: 90.1998 | E25: 0 | F25: 0 | G25: 0 | H25: 0 | I25: 0 | J25: 0 | K25: 542.7094 | L25: 0 | M25: 0 | N25: 0 | O25: 676.7864 | P25: 645.7053 | Q25: 0 | R25: 0 | S25: 0 | T25: 0 | U25: 0 | V25: 0 | W25: 0 | X25: 0 | Y25: 0 | Z25: 0 | AA25: 0 | AB25: 0 | AD25: C18:3, µmol/l | AE25: =((B$25/B$13)*$E$3)/278.4*(1/AE$4*1000)/3 -> 7.0932137 | AF25: =((C$25/C$13)*$E$3)/278.4*(1/AF$4*1000)/3 -> 2.5257326 | AG25: =((D$25/D$13)*$E$3)/278.4*(1/AG$4*1000)/3 -> 1.4570347 | AH25: =((E$25/E$13)*$E$3)/278.4*(1/AH$4*1000)/3 -> 0 | AI25: =((F$25/F$13)*$E$3)/278.4*(1/AI$4*1000)/3 -> 0 | AJ25: =((G$25/G$13)*$E$3)/278.4*(1/AJ$4*1000)/3 -> 0 | AK25: =((H$25/H$13)*$E$3)/278.4*(1/AK$4*1000)/3 -> 0 | AL25: =((I$25/I$13)*$E$3)/278.4*(1/AL$4*1000)/3 -> 0 | ... BE25: =((AB$25/AB$13)*$E$3)/278.4*(1/BE$4*1000)/3 -> 0 | BH25: 18:3 a | BI25: =AE25*100/AE$39 -> 4.25566 | BJ25: =AF25*100/AF$39 -> 1.763364 | BK25: =AG25*100/AG$39 -> 0.97646226 | BL25: =AH25*100/AH$39 -> 0 | BM25: =AI25*100/AI$39 -> 0 | BN25: =AJ25*100/AJ$39 -> 0 | BO25: =AK25*100/AK$39 -> 0 | BP25: =AL25*100/AL$39 -> 0 | ... CI25: =BE25*100/BE$39 -> 0
A26: 20:0 | B26: 0 | C26: 0 | D26: 0 | E26: 0 | F26: 0 | G26: 0 | H26: 0 | I26: 0 | J26: 0 | K26: 0 | L26: 0 | M26: 0 | N26: 0 | O26: 0 | P26: 0 | Q26: 0 | R26: 0 | S26: 0 | T26: 0 | U26: 0 | V26: 0 | W26: 0 | X26: 0 | Y26: 0 | Z26: 0 | AA26: 0 | AB26: 0 | AD26: C20:0, µmol/l | AE26: =((B$26/B$13)*$E$3)/312.5*(1/AE$4*1000)/3 -> 0 | AF26: =((C$26/C$13)*$E$3)/312.5*(1/AF$4*1000)/3 -> 0 | AG26: =((D$26/D$13)*$E$3)/312.5*(1/AG$4*1000)/3 -> 0 | AH26: =((E$26/E$13)*$E$3)/312.5*(1/AH$4*1000)/3 -> 0 | AI26: =((F$26/F$13)*$E$3)/312.5*(1/AI$4*1000)/3 -> 0 | AJ26: =((G$26/G$13)*$E$3)/312.5*(1/AJ$4*1000)/3 -> 0 | AK26: =((H$26/H$13)*$E$3)/312.5*(1/AK$4*1000)/3 -> 0 | AL26: =((I$26/I$13)*$E$3)/312.5*(1/AL$4*1000)/3 -> 0 | ... BE26: =((AB$26/AB$13)*$E$3)/312.5*(1/BE$4*1000)/3 -> 0 | BH26: 0.83333333 | BI26: =AE26*100/AE$39 -> 0 | BJ26: =AF26*100/AF$39 -> 0 | BK26: =AG26*100/AG$39 -> 0 | BL26: =AH26*100/AH$39 -> 0 | BM26: =AI26*100/AI$39 -> 0 | BN26: =AJ26*100/AJ$39 -> 0 | BO26: =AK26*100/AK$39 -> 0 | BP26: =AL26*100/AL$39 -> 0 | ... CI26: =BE26*100/BE$39 -> 0
A27: 20:1 | B27: 0 | C27: 0 | D27: 0 | E27: 0 | F27: 0 | G27: 0 | H27: 0 | I27: 340.8555 | J27: 0 | K27: 0 | L27: 0 | M27: 0 | N27: 0 | O27: 0 | P27: 0 | Q27: 0 | R27: 0 | S27: 0 | T27: 0 | U27: 0 | V27: 0 | W27: 0 | X27: 0 | Y27: 0 | Z27: 0 | AA27: 0 | AB27: 0 | AD27: C20:1, µmol/l | AE27: =((B$27/B$13)*$E$3)/310.5*(1/AE$4*1000)/3 -> 0 | AF27: =((C$27/C$13)*$E$3)/310.5*(1/AF$4*1000)/3 -> 0 | AG27: =((D$27/D$13)*$E$3)/310.5*(1/AG$4*1000)/3 -> 0 | AH27: =((E$27/E$13)*$E$3)/310.5*(1/AH$4*1000)/3 -> 0 | AI27: =((F$27/F$13)*$E$3)/310.5*(1/AI$4*1000)/3 -> 0 | AJ27: =((G$27/G$13)*$E$3)/310.5*(1/AJ$4*1000)/3 -> 0 | AK27: =((H$27/H$13)*$E$3)/310.5*(1/AK$4*1000)/3 -> 0 | AL27: =((I$27/I$13)*$E$3)/310.5*(1/AL$4*1000)/3 -> 17.876662 | ... BE27: =((AB$27/AB$13)*$E$3)/310.5*(1/BE$4*1000)/3 -> 0 | BH27: 0.83402778 | BI27: =AE27*100/AE$39 -> 0 | BJ27: =AF27*100/AF$39 -> 0 | BK27: =AG27*100/AG$39 -> 0 | BL27: =AH27*100/AH$39 -> 0 | BM27: =AI27*100/AI$39 -> 0 | BN27: =AJ27*100/AJ$39 -> 0 | BO27: =AK27*100/AK$39 -> 0 | BP27: =AL27*100/AL$39 -> 0.5148218 | ... CI27: =BE27*100/BE$39 -> 0
A28: 20:2 | B28: 0 | C28: 0 | D28: 0 | E28: 0 | F28: 0 | G28: 0 | H28: 0 | I28: 0 | J28: 0 | K28: 0 | L28: 0 | M28: 0 | N28: 0 | O28: 0 | P28: 0 | Q28: 0 | R28: 0 | S28: 0 | T28: 0 | U28: 0 | V28: 0 | W28: 0 | X28: 0 | Y28: 0 | Z28: 0 | AA28: 0 | AB28: 0 | AD28: C20:2, µmol/l | AE28: =((B$28/B$13)*$E$3)/308.5*(1/AE$4*1000)/3 -> 0 | AF28: =((C$28/C$13)*$E$3)/308.5*(1/AF$4*1000)/3 -> 0 | AG28: =((D$28/D$13)*$E$3)/308.5*(1/AG$4*1000)/3 -> 0 | AH28: =((E$28/E$13)*$E$3)/308.5*(1/AH$4*1000)/3 -> 0 | AI28: =((F$28/F$13)*$E$3)/308.5*(1/AI$4*1000)/3 -> 0 | AJ28: =((G$28/G$13)*$E$3)/308.5*(1/AJ$4*1000)/3 -> 0 | AK28: =((H$28/H$13)*$E$3)/308.5*(1/AK$4*1000)/3 -> 0 | AL28: =((I$28/I$13)*$E$3)/308.5*(1/AL$4*1000)/3 -> 0 | ... BE28: =((AB$28/AB$13)*$E$3)/308.5*(1/BE$4*1000)/3 -> 0 | BH28: 0.83472222 | BI28: =AE28*100/AE$39 -> 0 | BJ28: =AF28*100/AF$39 -> 0 | BK28: =AG28*100/AG$39 -> 0 | BL28: =AH28*100/AH$39 -> 0 | BM28: =AI28*100/AI$39 -> 0 | BN28: =AJ28*100/AJ$39 -> 0 | BO28: =AK28*100/AK$39 -> 0 | BP28: =AL28*100/AL$39 -> 0 | ... CI28: =BE28*100/BE$39 -> 0
A29: 20:3/21:0 | B29: 0 | C29: 0 | D29: 0 | E29: 0 | F29: 0 | G29: 0 | H29: 495.2816 | I29: 617.2098 | J29: 588.5069 | K29: 0 | L29: 0 | M29: 0 | N29: 0 | O29: 0 | P29: 0 | Q29: 0 | R29: 0 | S29: 0 | T29: 0 | U29: 0 | V29: 0 | W29: 0 | X29: 0 | Y29: 0 | Z29: 375.0510 | AA29: 515.3043 | AB29: 486.2425 | AD29: C20:3, µmol/l | AE29: =((B$29/B$13)*$E$3)/306.4*(1/AE$4*1000)/3 -> 0 | AF29: =((C$29/C$13)*$E$3)/306.4*(1/AF$4*1000)/3 -> 0 | AG29: =((D$29/D$13)*$E$3)/306.4*(1/AG$4*1000)/3 -> 0 | AH29: =((E$29/E$13)*$E$3)/306.4*(1/AH$4*1000)/3 -> 0 | AI29: =((F$29/F$13)*$E$3)/306.4*(1/AI$4*1000)/3 -> 0 | AJ29: =((G$29/G$13)*$E$3)/306.4*(1/AJ$4*1000)/3 -> 0 | AK29: =((H$29/H$13)*$E$3)/306.4*(1/AK$4*1000)/3 -> 27.324037 | AL29: =((I$29/I$13)*$E$3)/306.4*(1/AL$4*1000)/3 -> 32.80362 | ... BE29: =((AB$29/AB$13)*$E$3)/306.4*(1/BE$4*1000)/3 -> 59.182684 | BH29: 20:3/21:0 | BI29: =AE29*100/AE$39 -> 0 | BJ29: =AF29*100/AF$39 -> 0 | BK29: =AG29*100/AG$39 -> 0 | BL29: =AH29*100/AH$39 -> 0 | BM29: =AI29*100/AI$39 -> 0 | BN29: =AJ29*100/AJ$39 -> 0 | BO29: =AK29*100/AK$39 -> 0.90831811 | BP29: =AL29*100/AL$39 -> 0.94469644 | ... CI29: =BE29*100/BE$39 -> 1.3848474
A30: 20:3 | B30: 0 | C30: 0 | D30: 0 | E30: 0 | F30: 0 | G30: 0 | H30: 0 | I30: 0 | J30: 0 | K30: 0 | L30: 0 | M30: 0 | N30: 0 | O30: 0 | P30: 0 | Q30: 0 | R30: 0 | S30: 0 | T30: 0 | U30: 0 | V30: 0 | W30: 0 | X30: 0 | Y30: 0 | Z30: 0 | AA30: 0 | AB30: 0 | AD30: C20:3, µmol/l | AE30: =((B$30/B$13)*$E$3)/306.4*(1/AE$4*1000)/3 -> 0 | AF30: =((C$30/C$13)*$E$3)/306.4*(1/AF$4*1000)/3 -> 0 | AG30: =((D$30/D$13)*$E$3)/306.4*(1/AG$4*1000)/3 -> 0 | AH30: =((E$30/E$13)*$E$3)/306.4*(1/AH$4*1000)/3 -> 0 | AI30: =((F$30/F$13)*$E$3)/306.4*(1/AI$4*1000)/3 -> 0 | AJ30: =((G$30/G$13)*$E$3)/306.4*(1/AJ$4*1000)/3 -> 0 | AK30: =((H$30/H$13)*$E$3)/306.4*(1/AK$4*1000)/3 -> 0 | AL30: =((I$30/I$13)*$E$3)/306.4*(1/AL$4*1000)/3 -> 0 | ... BE30: =((AB$30/AB$13)*$E$3)/306.4*(1/BE$4*1000)/3 -> 0 | BH30: 0.83541667 | BI30: =AE30*100/AE$39 -> 0 | BJ30: =AF30*100/AF$39 -> 0 | BK30: =AG30*100/AG$39 -> 0 | BL30: =AH30*100/AH$39 -> 0 | BM30: =AI30*100/AI$39 -> 0 | BN30: =AJ30*100/AJ$39 -> 0 | BO30: =AK30*100/AK$39 -> 0 | BP30: =AL30*100/AL$39 -> 0 | ... CI30: =BE30*100/BE$39 -> 0
A31: 20:4 | B31: 0 | C31: 0 | D31: 0 | E31: 0 | F31: 0 | G31: 0 | H31: 831.8036 | I31: 939.5618 | J31: 839.2937 | K31: 0 | L31: 0 | M31: 0 | N31: 0 | O31: 0 | P31: 0 | Q31: 0 | R31: 0 | S31: 0 | T31: 0 | U31: 0 | V31: 0 | W31: 0 | X31: 0 | Y31: 0 | Z31: 0 | AA31: 0 | AB31: 0 | AD31: C20:4, µmol/l | AE31: =((B$31/B$13)*$E$3)/304.4*(1/AE$4*1000)/3 -> 0 | AF31: =((C$31/C$13)*$E$3)/304.4*(1/AF$4*1000)/3 -> 0 | AG31: =((D$31/D$13)*$E$3)/304.4*(1/AG$4*1000)/3 -> 0 | AH31: =((E$31/E$13)*$E$3)/304.4*(1/AH$4*1000)/3 -> 0 | AI31: =((F$31/F$13)*$E$3)/304.4*(1/AI$4*1000)/3 -> 0 | AJ31: =((G$31/G$13)*$E$3)/304.4*(1/AJ$4*1000)/3 -> 0 | AK31: =((H$31/H$13)*$E$3)/304.4*(1/AK$4*1000)/3 -> 46.191022 | AL31: =((I$31/I$13)*$E$3)/304.4*(1/AL$4*1000)/3 -> 50.26416 | ... BE31: =((AB$31/AB$13)*$E$3)/304.4*(1/BE$4*1000)/3 -> 0 | BH31: 0.83611111 | BI31: =AE31*100/AE$39 -> 0 | BJ31: =AF31*100/AF$39 -> 0 | BK31: =AG31*100/AG$39 -> 0 | BL31: =AH31*100/AH$39 -> 0 | BM31: =AI31*100/AI$39 -> 0 | BN31: =AJ31*100/AJ$39 -> 0 | BO31: =AK31*100/AK$39 -> 1.5355031 | BP31: =AL31*100/AL$39 -> 1.4475345 | ... CI31: =BE31*100/BE$39 -> 0
A32: 20:5 | B32: 0 | C32: 0 | D32: 0 | E32: 0 | F32: 0 | G32: 0 | H32: 0 | I32: 0 | J32: 0 | K32: 0 | L32: 0 | M32: 0 | N32: 0 | O32: 0 | P32: 0 | Q32: 0 | R32: 0 | S32: 0 | T32: 0 | U32: 0 | V32: 0 | W32: 0 | X32: 0 | Y32: 0 | Z32: 0 | AA32: 0 | AB32: 0 | AD32: C20:5, µmol/l | AE32: =((B$32/B$13)*$E$3)/302.5*(1/AE$4*1000)/3 -> 0 | AF32: =((C$32/C$13)*$E$3)/302.5*(1/AF$4*1000)/3 -> 0 | AG32: =((D$32/D$13)*$E$3)/302.5*(1/AG$4*1000)/3 -> 0 | AH32: =((E$32/E$13)*$E$3)/302.5*(1/AH$4*1000)/3 -> 0 | AI32: =((F$32/F$13)*$E$3)/302.5*(1/AI$4*1000)/3 -> 0 | AJ32: =((G$32/G$13)*$E$3)/302.5*(1/AJ$4*1000)/3 -> 0 | AK32: =((H$32/H$13)*$E$3)/302.5*(1/AK$4*1000)/3 -> 0 | AL32: =((I$32/I$13)*$E$3)/302.5*(1/AL$4*1000)/3 -> 0 | ... BE32: =((AB$32/AB$13)*$E$3)/302.5*(1/BE$4*1000)/3 -> 0 | BH32: 0.83680556 | BI32: =AE32*100/AE$39 -> 0 | BJ32: =AF32*100/AF$39 -> 0 | BK32: =AG32*100/AG$39 -> 0 | BL32: =AH32*100/AH$39 -> 0 | BM32: =AI32*100/AI$39 -> 0 | BN32: =AJ32*100/AJ$39 -> 0 | BO32: =AK32*100/AK$39 -> 0 | BP32: =AL32*100/AL$39 -> 0 | ... CI32: =BE32*100/BE$39 -> 0
A33: 22:0 | B33: 0 | C33: 0 | D33: 0 | E33: 0 | F33: 0 | G33: 0 | H33: 0 | I33: 0 | J33: 0 | K33: 0 | L33: 0 | M33: 0 | N33: 0 | O33: 0 | P33: 0 | Q33: 0 | R33: 0 | S33: 0 | T33: 0 | U33: 0 | V33: 0 | W33: 0 | X33: 0 | Y33: 0 | Z33: 0 | AA33: 0 | AB33: 0 | AD33: 0.91666667 | AE33: =((B$33/B$13)*$E$3)/340.5*(1/AE$4*1000)/3 -> 0 | AF33: =((C$33/C$13)*$E$3)/340.5*(1/AF$4*1000)/3 -> 0 | AG33: =((D$33/D$13)*$E$3)/340.5*(1/AG$4*1000)/3 -> 0 | AH33: =((E$33/E$13)*$E$3)/340.5*(1/AH$4*1000)/3 -> 0 | AI33: =((F$33/F$13)*$E$3)/340.5*(1/AI$4*1000)/3 -> 0 | AJ33: =((G$33/G$13)*$E$3)/340.5*(1/AJ$4*1000)/3 -> 0 | AK33: =((H$33/H$13)*$E$3)/340.5*(1/AK$4*1000)/3 -> 0 | AL33: =((I$33/I$13)*$E$3)/340.5*(1/AL$4*1000)/3 -> 0 | ... BE33: =((AB$33/AB$13)*$E$3)/340.5*(1/BE$4*1000)/3 -> 0 | BH33: 0.91666667 | BI33: =AE33*100/AE$39 -> 0 | BJ33: =AF33*100/AF$39 -> 0 | BK33: =AG33*100/AG$39 -> 0 | BL33: =AH33*100/AH$39 -> 0 | BM33: =AI33*100/AI$39 -> 0 | BN33: =AJ33*100/AJ$39 -> 0 | BO33: =AK33*100/AK$39 -> 0 | BP33: =AL33*100/AL$39 -> 0 | ... CI33: =BE33*100/BE$39 -> 0
A34: 22:1 | B34: 0 | C34: 0 | D34: 0 | E34: 0 | F34: 0 | G34: 0 | H34: 0 | I34: 0 | J34: 0 | K34: 0 | L34: 0 | M34: 0 | N34: 0 | O34: 0 | P34: 0 | Q34: 0 | R34: 0 | S34: 0 | T34: 0 | U34: 0 | V34: 0 | W34: 0 | X34: 0 | Y34: 0 | Z34: 0 | AA34: 0 | AB34: 0 | AD34: 0.91736111 | AE34: =((B$34/B$13)*$E$3)/338.5*(1/AE$4*1000)/3 -> 0 | AF34: =((C$34/C$13)*$E$3)/338.5*(1/AF$4*1000)/3 -> 0 | AG34: =((D$34/D$13)*$E$3)/338.5*(1/AG$4*1000)/3 -> 0 | AH34: =((E$34/E$13)*$E$3)/338.5*(1/AH$4*1000)/3 -> 0 | AI34: =((F$34/F$13)*$E$3)/338.5*(1/AI$4*1000)/3 -> 0 | AJ34: =((G$34/G$13)*$E$3)/338.5*(1/AJ$4*1000)/3 -> 0 | AK34: =((H$34/H$13)*$E$3)/338.5*(1/AK$4*1000)/3 -> 0 | AL34: =((I$34/I$13)*$E$3)/338.5*(1/AL$4*1000)/3 -> 0 | ... BE34: =((AB$34/AB$13)*$E$3)/338.5*(1/BE$4*1000)/3 -> 0 | BH34: 0.91736111 | BI34: =AE34*100/AE$39 -> 0 | BJ34: =AF34*100/AF$39 -> 0 | BK34: =AG34*100/AG$39 -> 0 | BL34: =AH34*100/AH$39 -> 0 | BM34: =AI34*100/AI$39 -> 0 | BN34: =AJ34*100/AJ$39 -> 0 | BO34: =AK34*100/AK$39 -> 0 | BP34: =AL34*100/AL$39 -> 0 | ... CI34: =BE34*100/BE$39 -> 0
A35: 22:2 | B35: 0 | C35: 0 | D35: 0 | E35: 0 | F35: 0 | G35: 0 | H35: 0 | I35: 0 | J35: 0 | K35: 0 | L35: 0 | M35: 0 | N35: 0 | O35: 0 | P35: 0 | Q35: 0 | R35: 0 | S35: 0 | T35: 0 | U35: 0 | V35: 0 | W35: 0 | X35: 0 | Y35: 0 | Z35: 0 | AA35: 0 | AB35: 0 | AD35: 0.91805556 | AE35: =((B$35/B$13)*$E$3)/336.5*(1/AE$4*1000)/3 -> 0 | AF35: =((C$35/C$13)*$E$3)/336.5*(1/AF$4*1000)/3 -> 0 | AG35: =((D$35/D$13)*$E$3)/336.5*(1/AG$4*1000)/3 -> 0 | AH35: =((E$35/E$13)*$E$3)/336.5*(1/AH$4*1000)/3 -> 0 | AI35: =((F$35/F$13)*$E$3)/336.5*(1/AI$4*1000)/3 -> 0 | AJ35: =((G$35/G$13)*$E$3)/336.5*(1/AJ$4*1000)/3 -> 0 | AK35: =((H$35/H$13)*$E$3)/336.5*(1/AK$4*1000)/3 -> 0 | AL35: =((I$35/I$13)*$E$3)/336.5*(1/AL$4*1000)/3 -> 0 | ... BE35: =((AB$35/AB$13)*$E$3)/336.5*(1/BE$4*1000)/3 -> 0 | BH35: 0.91805556 | BI35: =AE35*100/AE$39 -> 0 | BJ35: =AF35*100/AF$39 -> 0 | BK35: =AG35*100/AG$39 -> 0 | BL35: =AH35*100/AH$39 -> 0 | BM35: =AI35*100/AI$39 -> 0 | BN35: =AJ35*100/AJ$39 -> 0 | BO35: =AK35*100/AK$39 -> 0 | BP35: =AL35*100/AL$39 -> 0 | ... CI35: =BE35*100/BE$39 -> 0
A36: 23:0 | B36: 0 | C36: 0 | D36: 0 | E36: 0 | F36: 0 | G36: 0 | H36: 0 | I36: 0 | J36: 0 | K36: 21321.3535 | L36: 21707.6094 | M36: 21869.2773 | N36: 22185.0742 | O36: 26228.3418 | P36: 24807.8281 | Q36: 1805.7888 | R36: 2478.4673 | S36: 2304.3887 | T36: 2184.2656 | U36: 2553.6467 | V36: 2572.2612 | W36: 2777.3735 | X36: 2758.1902 | Y36: 2697.4680 | Z36: 2849.5269 | AA36: 2772.8423 | AB36: 2829.7087 | BH36: 0.95833333
A37: 22:5 | B37: 0 | C37: 0 | D37: 0 | E37: 0 | F37: 0 | G37: 0 | H37: 0 | I37: 0 | J37: 0 | K37: 0 | L37: 0 | M37: 0 | N37: 0 | O37: 0 | P37: 0 | Q37: 0 | R37: 0 | S37: 0 | T37: 0 | U37: 0 | V37: 0 | W37: 0 | X37: 0 | Y37: 0 | Z37: 0 | AA37: 0 | AB37: 0 | AD37: C22:5, µmol/l | AE37: =((B$37/B$13)*$E$3)/330.5*(1/AE$4*1000)/3 -> 0 | AF37: =((C$37/C$13)*$E$3)/330.5*(1/AF$4*1000)/3 -> 0 | AG37: =((D$37/D$13)*$E$3)/330.5*(1/AG$4*1000)/3 -> 0 | AH37: =((E$37/E$13)*$E$3)/330.5*(1/AH$4*1000)/3 -> 0 | AI37: =((F$37/F$13)*$E$3)/330.5*(1/AI$4*1000)/3 -> 0 | AJ37: =((G$37/G$13)*$E$3)/330.5*(1/AJ$4*1000)/3 -> 0 | AK37: =((H$37/H$13)*$E$3)/330.5*(1/AK$4*1000)/3 -> 0 | AL37: =((I$37/I$13)*$E$3)/330.5*(1/AL$4*1000)/3 -> 0 | ... BE37: =((AB$37/AB$13)*$E$3)/330.5*(1/BE$4*1000)/3 -> 0 | BH37: 0.92013889 | BI37: =AE37*100/AE$39 -> 0 | BJ37: =AF37*100/AF$39 -> 0 | BK37: =AG37*100/AG$39 -> 0 | BL37: =AH37*100/AH$39 -> 0 | BM37: =AI37*100/AI$39 -> 0 | BN37: =AJ37*100/AJ$39 -> 0 | BO37: =AK37*100/AK$39 -> 0 | BP37: =AL37*100/AL$39 -> 0 | ... CI37: =BE37*100/BE$39 -> 0
A38: 22:6 | B38: 0 | C38: 0 | D38: 0 | E38: 0 | F38: 0 | G38: 0 | H38: 0 | I38: 0 | J38: 0 | K38: 0 | L38: 0 | M38: 0 | N38: 0 | O38: 0 | P38: 0 | Q38: 0 | R38: 0 | S38: 0 | T38: 0 | U38: 0 | V38: 0 | W38: 0 | X38: 0 | Y38: 0 | Z38: 0 | AA38: 0 | AB38: 0 | AD38: C22:6, µmol/l | AE38: =((B$38/B$13)*$E$3)/328.5*(1/AE$4*1000)/3 -> 0 | AF38: =((C$38/C$13)*$E$3)/328.5*(1/AF$4*1000)/3 -> 0 | AG38: =((D$38/D$13)*$E$3)/328.5*(1/AG$4*1000)/3 -> 0 | AH38: =((E$38/E$13)*$E$3)/328.5*(1/AH$4*1000)/3 -> 0 | AI38: =((F$38/F$13)*$E$3)/328.5*(1/AI$4*1000)/3 -> 0 | AJ38: =((G$38/G$13)*$E$3)/328.5*(1/AJ$4*1000)/3 -> 0 | AK38: =((H$38/H$13)*$E$3)/328.5*(1/AK$4*1000)/3 -> 0 | AL38: =((I$38/I$13)*$E$3)/328.5*(1/AL$4*1000)/3 -> 0 | ... BE38: =((AB$38/AB$13)*$E$3)/328.5*(1/BE$4*1000)/3 -> 0 | BH38: 0.92083333 | BI38: =AE38*100/AE$39 -> 0 | BJ38: =AF38*100/AF$39 -> 0 | BK38: =AG38*100/AG$39 -> 0 | BL38: =AH38*100/AH$39 -> 0 | BM38: =AI38*100/AI$39 -> 0 | BN38: =AJ38*100/AJ$39 -> 0 | BO38: =AK38*100/AK$39 -> 0 | BP38: =AL38*100/AL$39 -> 0 | ... CI38: =BE38*100/BE$39 -> 0
AD39: total GC | AE39: =SUM(AE6:AE35,AE37:AE38) -> 166.67717 | AF39: =SUM(AF6:AF35,AF37:AF38) -> 143.23376 | AG39: =SUM(AG6:AG35,AG37:AG38) -> 149.21566 | AH39: =SUM(AH6:AH35,AH37:AH38) -> 782.95141 | AI39: =SUM(AI6:AI35,AI37:AI38) -> 867.71866 | AJ39: =SUM(AJ6:AJ35,AJ37:AJ38) -> 842.43299 | AK39: =SUM(AK6:AK35,AK37:AK38) -> 3008.2013 | AL39: =SUM(AL6:AL35,AL37:AL38) -> 3472.398 | ... BE39: =SUM(BE6:BE35,BE37:BE38) -> 4273.5888
A40: recovery | B40: =((B13/B36)*($E$4/$E$3))*100 -> #DIV/0! | C40: =((C13/C36)*($E$4/$E$3))*100 -> #DIV/0! | D40: =((D13/D36)*($E$4/$E$3))*100 -> #DIV/0! | E40: =((E13/E36)*($E$4/$E$3))*100 -> #DIV/0! | F40: =((F13/F36)*($E$4/$E$3))*100 -> #DIV/0! | G40: =((G13/G36)*($E$4/$E$3))*100 -> #DIV/0! | H40: =((H13/H36)*($E$4/$E$3))*100 -> #DIV/0! | I40: =((I13/I36)*($E$4/$E$3))*100 -> #DIV/0! | ... AB40: =((AB13/AB36)*($E$4/$E$3))*100 -> 51.633994 | BI40: =SUM(BI6:BI38) -> 100 | BJ40: =SUM(BJ6:BJ38) -> 100 | BK40: =SUM(BK6:BK38) -> 100 | BL40: =SUM(BL6:BL38) -> 100 | BM40: =SUM(BM6:BM38) -> 100 | BN40: =SUM(BN6:BN38) -> 100 | BO40: =SUM(BO6:BO38) -> 100 | BP40: =SUM(BP6:BP38) -> 100 | ... CI40: =SUM(CI6:CI38) -> 100
AE41: 166.67717 | AF41: 143.23376 | AG41: 149.21566 | AH41: 782.95141 | AI41: 867.71866 | AJ41: 842.43299 | AK41: 3008.2013 | AL41: 3472.398 | AM41: 3601.7681 | AN41: 70.366206 | AO41: 99.083 | AP41: 110.62982 | AQ41: 24.399747 | AR41: 51.796812 | AS41: 43.845152 | AT41: 627.13862 | AU41: 847.09208 | AV41: 880.23691 | AW41: 954.65717 | AX41: 1041.5577 | AY41: 1089.2281 | AZ41: 3455.2564 | BA41: 3926.3635 | BB41: 4137.0856 | BC41: 3566.4907 | BD41: 4182.1168 | BE41: 4273.5888

Sheet TTRs 
A1: TG | B1: 0.66666667
A2: Sample | B2: Time | C2: 270 | D2: 271 | E2: TTR | F2: TTR - background | H2: %16:0 | J2: TG concentration (umol/l) | L2: 16:0 concentration (umol/l) | N2: U13C-16:0 concentration (umol/l)
B4: Background | E4: =D4/C4 -> #DIV/0! | F4: =E4-$E$4 -> #DIV/0! | H4: ='GC data'!BI15 -> 23.490604 | L4: =(H4/100)*J4 -> 0 | N4: =L4*F4 -> #DIV/0!
B6: 1 | E6: =D6/C6 -> #DIV/0! | F6: =E6-$E$4 -> #DIV/0! | H6: ='GC data'!BJ$15 -> 24.851808 | L6: =(H6/100)*J6 -> 0 | N6: =L6*F6 -> #DIV/0!
B7: 2 | E7: =D7/C7 -> #DIV/0! | F7: =E7-$E$4 -> #DIV/0! | H7: ='GC data'!BK$15 -> 26.001896 | L7: =(H7/100)*J7 -> 0 | N7: =L7*F7 -> #DIV/0!
B8: 3 | E8: =D8/C8 -> #DIV/0! | F8: =E8-$E$4 -> #DIV/0! | H8: ='GC data'!BL$15 -> 20.214556 | L8: =(H8/100)*J8 -> 0 | N8: =L8*F8 -> #DIV/0!
B9: 4 | E9: =D9/C9 -> #DIV/0! | F9: =E9-$E$4 -> #DIV/0! | H9: ='GC data'!BM$15 -> 20.481116 | L9: =(H9/100)*J9 -> 0 | N9: =L9*F9 -> #DIV/0!
B10: 5 | E10: =D10/C10 -> #DIV/0! | F10: =E10-$E$4 -> #DIV/0! | H10: ='GC data'!BN$15 -> 21.287385 | L10: =(H10/100)*J10 -> 0 | N10: =L10*F10 -> #DIV/0!
B11: 6 | E11: =D11/C11 -> #DIV/0! | F11: =E11-$E$4 -> #DIV/0! | H11: ='GC data'!BO$15 -> 26.344857 | L11: =(H11/100)*J11 -> 0 | N11: =L11*F11 -> #DIV/0!
B12: 7 | E12: =D12/C12 -> #DIV/0! | F12: =E12-$E$4 -> #DIV/0! | H12: ='GC data'!BP$15 -> 26.166338
B13: 8 | E13: =D13/C13 -> #DIV/0! | F13: =E13-$E$4 -> #DIV/0! | H13: ='GC data'!BQ$15 -> 26.285097
B14: 9 | E14: =D14/C14 -> #DIV/0! | F14: =E14-$E$4 -> #DIV/0! | H14: ='GC data'!BP$15 -> 26.166338 | L14: =(H14/100)*J14 -> 0 | N14: =L14*F14 -> #DIV/0!
B15: 10 | E15: =D15/C15 -> #DIV/0! | F15: =E15-$E$4 -> #DIV/0! | H15: ='GC data'!BQ$15 -> 26.285097 | L15: =(H15/100)*J15 -> 0 | N15: =L15*F15 -> #DIV/0!
B16: 11 | E16: =D16/C16 -> #DIV/0! | F16: =E16-$E$4 -> #DIV/0! | H16: ='GC data'!BR$15 -> 29.131085 | L16: =(H16/100)*J16 -> 0 | N16: =L16*F16 -> #DIV/0!
B17: 12 | E17: =D17/C17 -> #DIV/0! | F17: =E17-$E$4 -> #DIV/0! | H17: ='GC data'!BS$15 -> 27.425682 | L17: =(H17/100)*J17 -> 0 | N17: =L17*F17 -> #DIV/0!
B18: 13 | E18: =D18/C18 -> #DIV/0! | F18: =E18-$E$4 -> #DIV/0! | H18: ='GC data'!BT$15 -> 25.938355 | L18: =(H18/100)*J18 -> 0 | N18: =L18*F18 -> #DIV/0!
B19: 14 | E19: =D19/C19 -> #DIV/0! | F19: =E19-$E$4 -> #DIV/0! | H19: ='GC data'!BU$15 -> 0 | L19: =(H19/100)*J19 -> 0 | N19: =L19*F19 -> #DIV/0!
B20: 15 | E20: =D20/C20 -> #DIV/0! | F20: =E20-$E$4 -> #DIV/0! | H20: ='GC data'!BV$15 -> 28.09894 | L20: =(H20/100)*J20 -> 0 | N20: =L20*F20 -> #DIV/0!
B21: 16 | E21: =D21/C21 -> #DIV/0! | F21: =E21-$E$4 -> #DIV/0! | H21: ='GC data'!BW$15 -> 28.29337 | L21: =(H21/100)*J21 -> 0 | N21: =L21*F21 -> #DIV/0!
B22: 17 | E22: =D22/C22 -> #DIV/0! | F22: =E22-$E$4 -> #DIV/0! | H22: ='GC data'!BX$15 -> 21.971029 | L22: =(H22/100)*J22 -> 0 | N22: =L22*F22 -> #DIV/0!
B23: 18 | E23: =D23/C23 -> #DIV/0! | F23: =E23-$E$4 -> #DIV/0! | H23: ='GC data'!#REF! -> #REF! | L23: =(H23/100)*J23 -> #REF! | N23: =L23*F23 -> #REF!
A27: 0.66736111
A28: Sample | B28: Time | C28: 268 | D28: 269 | E28: TTR | F28: TTR - background | H28: %16:01 | J28: TG concentration (umol/l) | L28: 16:01 concentration (umol/l) | N28: U13C-16:1 concentration (umol/l)
B30: Background | E30: =((D30/1000)+1)*0.0112372*17/16 -> 0.011939525 | F30: =E30-$E$30 -> 0 | H30: ='GC data'!#REF! -> #REF! | J30: =J4 -> 0 | L30: =(H30/100)*J30 -> #REF! | N30: =L30*F30 -> #REF!
E31: =((D31/1000)+1)*0.0112372*17/16 -> 0.011939525 | F31: =E31-$E$30 -> 0 | H31: ='GC data'!BI$17 -> 13.513359 | J31: =J5 -> 0 | L31: =(H31/100)*J31 -> 0 | N31: =L31*F31 -> 0
B32: 1 | E32: =((D32/1000)+1)*0.0112372*17/16 -> 0.011939525 | F32: =E32-$E$30 -> 0 | H32: ='GC data'!BJ$17 -> 15.52783 | J32: =J6 -> 0 | L32: =(H32/100)*J32 -> 0 | N32: =L32*F32 -> 0
B33: 2 | E33: =((D33/1000)+1)*0.0112372*17/16 -> 0.011939525 | F33: =E33-$E$30 -> 0 | H33: ='GC data'!BK$17 -> 14.894178 | J33: =J7 -> 0 | L33: =(H33/100)*J33 -> 0 | N33: =L33*F33 -> 0
B34: 3 | E34: =((D34/1000)+1)*0.0112372*17/16 -> 0.011939525 | F34: =E34-$E$30 -> 0 | H34: ='GC data'!BL$17 -> 6.5039063 | J34: =J8 -> 0 | L34: =(H34/100)*J34 -> 0 | N34: =L34*F34 -> 0
B35: 4 | E35: =((D35/1000)+1)*0.0112372*17/16 -> 0.011939525 | F35: =E35-$E$30 -> 0 | H35: ='GC data'!BM$17 -> 6.5066511 | J35: =J9 -> 0 | L35: =(H35/100)*J35 -> 0 | N35: =L35*F35 -> 0
B36: 5 | E36: =((D36/1000)+1)*0.0112372*17/16 -> 0.011939525 | F36: =E36-$E$30 -> 0 | H36: ='GC data'!BN$17 -> 6.3232615 | J36: =J10 -> 0 | L36: =(H36/100)*J36 -> 0 | N36: =L36*F36 -> 0
B37: 6 | E37: =((D37/1000)+1)*0.0112372*17/16 -> 0.011939525 | F37: =E37-$E$30 -> 0 | H37: ='GC data'!BO$17 -> 3.8966625 | J37: =J11 -> 0 | L37: =(H37/100)*J37 -> 0 | N37: =L37*F37 -> 0
B38: 7
B39: 8
B40: 9 | E40: =((D40/1000)+1)*0.0112372*17/16 -> 0.011939525 | F40: =E40-$E$40 -> 0 | H40: ='GC data'!BP$17 -> 3.814943 | J40: =J14 -> 0 | L40: =(H40/100)*J40 -> 0 | N40: =L40*F40 -> 0
B41: 10 | E41: =((D41/1000)+1)*0.0112372*17/16 -> 0.011939525 | F41: =E41-$E$40 -> 0 | H41: ='GC data'!BQ$17 -> 3.6311973 | J41: =J15 -> 0 | L41: =(H41/100)*J41 -> 0 | N41: =L41*F41 -> 0
B42: 11 | E42: =((D42/1000)+1)*0.0112372*17/16 -> 0.011939525 | F42: =E42-$E$40 -> 0 | H42: ='GC data'!BR$17 -> 0 | J42: =J16 -> 0 | L42: =(H42/100)*J42 -> 0 | N42: =L42*F42 -> 0
B43: 12 | E43: =((D43/1000)+1)*0.0112372*17/16 -> 0.011939525 | F43: =E43-$E$40 -> 0 | H43: ='GC data'!BS$17 -> 5.6654723 | J43: =J17 -> 0 | L43: =(H43/100)*J43 -> 0 | N43: =L43*F43 -> 0
B44: 13 | E44: =((D44/1000)+1)*0.0112372*17/16 -> 0.011939525 | F44: =E44-$E$40 -> 0 | H44: ='GC data'!BT$17 -> 12.727451 | J44: =J18 -> 0 | L44: =(H44/100)*J44 -> 0 | N44: =L44*F44 -> 0
B45: 14 | E45: =((D45/1000)+1)*0.0112372*17/16 -> 0.011939525 | F45: =E45-$E$40 -> 0 | H45: ='GC data'!BU$17 -> 0 | J45: =J19 -> 0 | L45: =(H45/100)*J45 -> 0 | N45: =L45*F45 -> 0
B46: 15 | E46: =((D46/1000)+1)*0.0112372*17/16 -> 0.011939525 | F46: =E46-$E$40 -> 0 | H46: ='GC data'!BV$17 -> 0 | J46: =J20 -> 0 | L46: =(H46/100)*J46 -> 0 | N46: =L46*F46 -> 0
...
