Workbook

Sheet Exported Results
A1: Block Type | B1: 384-Well Block
A2: Calibration Background is expired | B2: No
A3: Calibration Background performed on | B3: 10-06-2021
A4: Calibration Normalization FAM-ROX is expired | B4: No
A5: Calibration Normalization FAM-ROX performed on | B5: 10-06-2021
A6: Calibration Normalization VIC-ROX is expired | B6: No
A7: Calibration Normalization VIC-ROX performed on | B7: 10-06-2021
A8: Calibration Pure Dye FAM is expired | B8: No
A9: Calibration Pure Dye FAM performed on | B9: 10-06-2021
A10: Calibration Pure Dye NED is expired | B10: No
A11: Calibration Pure Dye NED performed on | B11: 10-06-2021
A12: Calibration Pure Dye ROX is expired | B12: No
... A25: Date Created | B25: 2021-11-04 12:00:27 PM GMT
A26: Experiment Barcode
A27: Experiment Comment
A28: Experiment File Name | B28: D:\Users\Administrator\Desktop\FELIX\Felix HF v LF 3.eds
A29: Experiment Name | B29: Felix HF v LF 3
A30: Experiment Run End Time | B30: 2021-11-04 12:52:13 PM GMT
A31: Experiment Type | B31: Standard Curve
A32: Instrument Name | B32: HotPants
A33: Instrument Serial Number | B33: 278871706
A34: Instrument Type | B34: QuantStudio(TM) 7 Flex System
A35: Passive Reference | B35: ROX
A36: Quantification Cycle Method | B36: Ct
A37: Signal Smoothing On | B37: true
A38: Stage/ Cycle where Analysis is performed | B38: Stage 2, Step 2
A39: User Name
A41: Well Position | B41: Sample Name | C41: Target Name | D41: CT | H41: Sample Name
A42: A1 | B42: Blank 1.a | C42: ATG5 | D42: 34.912167 | H42: Blank 1.a
A43: A2 | B43: Blank 1.b | C43: ATG5 | D43: Undetermined | H43: Blank 1.b
A44: A3 | B44: Blank 1.c | C44: ATG5 | D44: 33.156532 | H44: Blank 1.c
A45: A4 | B45: STD 10a | C45: ATG5 | D45: 25.427053 | H45: STD 10a
A46: A5 | B46: STD 10b | C46: ATG5 | D46: 25.46406 | H46: STD 10b
A47: A6 | B47: STD 10c | C47: ATG5 | D47: 25.217436 | H47: STD 10c
A48: A7 | B48: STD 20a | C48: ATG5 | D48: 25.701344 | H48: STD 20a
A49: A8 | B49: STD 20b | C49: ATG5 | D49: 25.808258 | H49: STD 20b
A50: A9 | B50: STD 20c | C50: ATG5 | D50: 26.212976 | H50: STD 20c
A51: A10 | B51: STD 40a | C51: ATG5 | D51: 27.341259 | H51: STD 40a
A52: A11 | B52: STD 40b | C52: ATG5 | D52: 27.332716 | H52: STD 40b
A53: A12 | B53: STD 40c | C53: ATG5 | D53: 27.17654 | H53: STD 40c
...

Sheet Results Workspace
A2: Well | B2: Ct from reader | C2: Corrected Cts | D2: Sample Name | E2: Average Ct | F2: STDEV
A3: A1 | B3: =VLOOKUP(A3,'Exported Results'!A$42:D$161,4,FALSE) -> 34.912167 | C3: =IF(B3="Undetermined",40.1,B3) -> 34.912167 | D3: =VLOOKUP(A3,'Exported Results'!A$42:D$161,2,FALSE) -> Blank 1.a | E3: =AVERAGE(C3:C5) -> 34.034349 | F3: =_xlfn.STDEV.P(C3:C5) -> 0.87781715
A4: A2 | B4: =VLOOKUP(A4,'Exported Results'!A$42:D$161,4,FALSE) -> Undetermined | D4: =VLOOKUP(A4,'Exported Results'!A$42:D$161,2,FALSE) -> Blank 1.b
A5: A3 | B5: =VLOOKUP(A5,'Exported Results'!A$42:D$161,4,FALSE) -> 33.156532 | C5: =IF(B5="Undetermined",40.1,B5) -> 33.156532 | D5: =VLOOKUP(A5,'Exported Results'!A$42:D$161,2,FALSE) -> Blank 1.c
A6: A4 | B6: =VLOOKUP(A6,'Exported Results'!A$42:D$161,4,FALSE) -> 25.427053 | C6: =IF(B6="Undetermined",40.1,B6) -> 25.427053 | D6: =VLOOKUP(A6,'Exported Results'!A$42:D$161,2,FALSE) -> STD 10a | E6: =AVERAGE(C6:C8) -> 25.369516 | F6: =_xlfn.STDEV.P(C6:C8) -> 0.10859323
A7: A5 | B7: =VLOOKUP(A7,'Exported Results'!A$42:D$161,4,FALSE) -> 25.46406 | C7: =IF(B7="Undetermined",40.1,B7) -> 25.46406 | D7: =VLOOKUP(A7,'Exported Results'!A$42:D$161,2,FALSE) -> STD 10b
A8: A6 | B8: =VLOOKUP(A8,'Exported Results'!A$42:D$161,4,FALSE) -> 25.217436 | C8: =IF(B8="Undetermined",40.1,B8) -> 25.217436 | D8: =VLOOKUP(A8,'Exported Results'!A$42:D$161,2,FALSE) -> STD 10c
A9: A7 | B9: =VLOOKUP(A9,'Exported Results'!A$42:D$161,4,FALSE) -> 25.701344 | C9: =IF(B9="Undetermined",40.1,B9) -> 25.701344 | D9: =VLOOKUP(A9,'Exported Results'!A$42:D$161,2,FALSE) -> STD 20a | E9: =AVERAGE(C9:C11) -> 25.907526 | F9: =_xlfn.STDEV.P(C9:C11) -> 0.22035223
A10: A8 | B10: =VLOOKUP(A10,'Exported Results'!A$42:D$161,4,FALSE) -> 25.808258 | C10: =IF(B10="Undetermined",40.1,B10) -> 25.808258 | D10: =VLOOKUP(A10,'Exported Results'!A$42:D$161,2,FALSE) -> STD 20b
A11: A9 | B11: =VLOOKUP(A11,'Exported Results'!A$42:D$161,4,FALSE) -> 26.212976 | C11: =IF(B11="Undetermined",40.1,B11) -> 26.212976 | D11: =VLOOKUP(A11,'Exported Results'!A$42:D$161,2,FALSE) -> STD 20c
A12: A10 | B12: =VLOOKUP(A12,'Exported Results'!A$42:D$161,4,FALSE) -> 27.341259 | C12: =IF(B12="Undetermined",40.1,B12) -> 27.341259 | D12: =VLOOKUP(A12,'Exported Results'!A$42:D$161,2,FALSE) -> STD 40a | E12: =AVERAGE(C12:C14) -> 27.283505 | F12: =_xlfn.STDEV.P(C12:C14) -> 0.075715866
A13: A11 | B13: =VLOOKUP(A13,'Exported Results'!A$42:D$161,4,FALSE) -> 27.332716 | C13: =IF(B13="Undetermined",40.1,B13) -> 27.332716 | D13: =VLOOKUP(A13,'Exported Results'!A$42:D$161,2,FALSE) -> STD 40b
A14: A12 | B14: =VLOOKUP(A14,'Exported Results'!A$42:D$161,4,FALSE) -> 27.17654 | C14: =IF(B14="Undetermined",40.1,B14) -> 27.17654 | D14: =VLOOKUP(A14,'Exported Results'!A$42:D$161,2,FALSE) -> STD 40c
A15: A13 | B15: =VLOOKUP(A15,'Exported Results'!A$42:D$161,4,FALSE) -> 28.098312 | C15: =IF(B15="Undetermined",40.1,B15) -> 28.098312 | D15: =VLOOKUP(A15,'Exported Results'!A$42:D$161,2,FALSE) -> STD 80a | E15: =AVERAGE(C15:C17) -> 28.17183 | F15: =_xlfn.STDEV.P(C15:C17) -> 0.21826888
A16: A14 | B16: =VLOOKUP(A16,'Exported Results'!A$42:D$161,4,FALSE) -> 27.948957 | C16: =IF(B16="Undetermined",40.1,B16) -> 27.948957 | D16: =VLOOKUP(A16,'Exported Results'!A$42:D$161,2,FALSE) -> STD 80b
A17: A15 | B17: =VLOOKUP(A17,'Exported Results'!A$42:D$161,4,FALSE) -> 28.46822 | C17: =IF(B17="Undetermined",40.1,B17) -> 28.46822 | D17: =VLOOKUP(A17,'Exported Results'!A$42:D$161,2,FALSE) -> STD 80c
A18: A16 | B18: =VLOOKUP(A18,'Exported Results'!A$42:D$161,4,FALSE) -> 29.182129 | C18: =IF(B18="Undetermined",40.1,B18) -> 29.182129 | D18: =VLOOKUP(A18,'Exported Results'!A$42:D$161,2,FALSE) -> STD 160a | E18: =AVERAGE(C18:C20) -> 29.307207 | F18: =_xlfn.STDEV.P(C18:C20) -> 0.10852986
A19: A17 | B19: =VLOOKUP(A19,'Exported Results'!A$42:D$161,4,FALSE) -> 29.446783 | C19: =IF(B19="Undetermined",40.1,B19) -> 29.446783 | D19: =VLOOKUP(A19,'Exported Results'!A$42:D$161,2,FALSE) -> STD 160b
A20: A18 | B20: =VLOOKUP(A20,'Exported Results'!A$42:D$161,4,FALSE) -> 29.292709 | C20: =IF(B20="Undetermined",40.1,B20) -> 29.292709 | D20: =VLOOKUP(A20,'Exported Results'!A$42:D$161,2,FALSE) -> STD 160c
A21: A19 | B21: =VLOOKUP(A21,'Exported Results'!A$42:D$161,4,FALSE) -> 30.392082 | C21: =IF(B21="Undetermined",40.1,B21) -> 30.392082 | D21: =VLOOKUP(A21,'Exported Results'!A$42:D$161,2,FALSE) -> STD 320a | E21: =AVERAGE(C21:C23) -> 30.466387 | F21: =_xlfn.STDEV.P(C21:C23) -> 0.13469041
A22: A20 | B22: =VLOOKUP(A22,'Exported Results'!A$42:D$161,4,FALSE) -> 30.351646 | C22: =IF(B22="Undetermined",40.1,B22) -> 30.351646 | D22: =VLOOKUP(A22,'Exported Results'!A$42:D$161,2,FALSE) -> STD 320b
A23: A21 | B23: =VLOOKUP(A23,'Exported Results'!A$42:D$161,4,FALSE) -> 30.655432 | C23: =IF(B23="Undetermined",40.1,B23) -> 30.655432 | D23: =VLOOKUP(A23,'Exported Results'!A$42:D$161,2,FALSE) -> STD 320c
A24: A22 | B24: =VLOOKUP(A24,'Exported Results'!A$42:D$161,4,FALSE) -> 26.95159 | C24: =IF(B24="Undetermined",40.1,B24) -> 26.95159 | D24: =VLOOKUP(A24,'Exported Results'!A$42:D$161,2,FALSE) -> 0.1.a | E24: =AVERAGE(C24:C26) -> 26.984384 | F24: =_xlfn.STDEV.P(C24:C26) -> 0.10113031
A25: A23 | B25: =VLOOKUP(A25,'Exported Results'!A$42:D$161,4,FALSE) -> 26.880222 | C25: =IF(B25="Undetermined",40.1,B25) -> 26.880222 | D25: =VLOOKUP(A25,'Exported Results'!A$42:D$161,2,FALSE) -> 0.1.b
A26: A24 | B26: =VLOOKUP(A26,'Exported Results'!A$42:D$161,4,FALSE) -> 27.12134 | C26: =IF(B26="Undetermined",40.1,B26) -> 27.12134 | D26: =VLOOKUP(A26,'Exported Results'!A$42:D$161,2,FALSE) -> 0.1.c
A27: B1 | B27: =VLOOKUP(A27,'Exported Results'!A$42:D$161,4,FALSE) -> 27.065632 | C27: =IF(B27="Undetermined",40.1,B27) -> 27.065632 | D27: =VLOOKUP(A27,'Exported Results'!A$42:D$161,2,FALSE) -> 0.2.a | E27: =AVERAGE(C27:C29) -> 27.163047 | F27: =_xlfn.STDEV.P(C27:C29) -> 0.076943245
A28: B2 | B28: =VLOOKUP(A28,'Exported Results'!A$42:D$161,4,FALSE) -> 27.253744 | C28: =IF(B28="Undetermined",40.1,B28) -> 27.253744 | D28: =VLOOKUP(A28,'Exported Results'!A$42:D$161,2,FALSE) -> 0.2.b
A29: B3 | B29: =VLOOKUP(A29,'Exported Results'!A$42:D$161,4,FALSE) -> 27.169764 | C29: =IF(B29="Undetermined",40.1,B29) -> 27.169764 | D29: =VLOOKUP(A29,'Exported Results'!A$42:D$161,2,FALSE) -> 0.2.c
A30: B4 | B30: =VLOOKUP(A30,'Exported Results'!A$42:D$161,4,FALSE) -> 27.006998 | C30: =IF(B30="Undetermined",40.1,B30) -> 27.006998 | D30: =VLOOKUP(A30,'Exported Results'!A$42:D$161,2,FALSE) -> 0.3.a | E30: =AVERAGE(C30:C32) -> 27.093292 | F30: =_xlfn.STDEV.P(C30:C32) -> 0.078945143
A31: B5 | B31: =VLOOKUP(A31,'Exported Results'!A$42:D$161,4,FALSE) -> 27.197786 | C31: =IF(B31="Undetermined",40.1,B31) -> 27.197786 | D31: =VLOOKUP(A31,'Exported Results'!A$42:D$161,2,FALSE) -> 0.3.b
A32: B6 | B32: =VLOOKUP(A32,'Exported Results'!A$42:D$161,4,FALSE) -> 27.07509 | C32: =IF(B32="Undetermined",40.1,B32) -> 27.07509 | D32: =VLOOKUP(A32,'Exported Results'!A$42:D$161,2,FALSE) -> 0.3.c
A33: B7 | B33: =VLOOKUP(A33,'Exported Results'!A$42:D$161,4,FALSE) -> 26.861311 | C33: =IF(B33="Undetermined",40.1,B33) -> 26.861311 | D33: =VLOOKUP(A33,'Exported Results'!A$42:D$161,2,FALSE) -> 2.1.a | E33: =AVERAGE(C33:C35) -> 26.918574 | F33: =_xlfn.STDEV.P(C33:C35) -> 0.040919359
A34: B8 | B34: =VLOOKUP(A34,'Exported Results'!A$42:D$161,4,FALSE) -> 26.939974 | C34: =IF(B34="Undetermined",40.1,B34) -> 26.939974 | D34: =VLOOKUP(A34,'Exported Results'!A$42:D$161,2,FALSE) -> 2.1.b
A35: B9 | B35: =VLOOKUP(A35,'Exported Results'!A$42:D$161,4,FALSE) -> 26.954437 | C35: =IF(B35="Undetermined",40.1,B35) -> 26.954437 | D35: =VLOOKUP(A35,'Exported Results'!A$42:D$161,2,FALSE) -> 2.1.c
A36: B10 | B36: =VLOOKUP(A36,'Exported Results'!A$42:D$161,4,FALSE) -> 27.833195 | C36: =IF(B36="Undetermined",40.1,B36) -> 27.833195 | D36: =VLOOKUP(A36,'Exported Results'!A$42:D$161,2,FALSE) -> 2.2.a | E36: =AVERAGE(C36:C38) -> 27.575932 | F36: =_xlfn.STDEV.P(C36:C38) -> 0.18415553
A37: B11 | B37: =VLOOKUP(A37,'Exported Results'!A$42:D$161,4,FALSE) -> 27.482399 | C37: =IF(B37="Undetermined",40.1,B37) -> 27.482399 | D37: =VLOOKUP(A37,'Exported Results'!A$42:D$161,2,FALSE) -> 2.2.b
A38: B12 | B38: =VLOOKUP(A38,'Exported Results'!A$42:D$161,4,FALSE) -> 27.412203 | C38: =IF(B38="Undetermined",40.1,B38) -> 27.412203 | D38: =VLOOKUP(A38,'Exported Results'!A$42:D$161,2,FALSE) -> 2.2.c
A39: B13 | B39: =VLOOKUP(A39,'Exported Results'!A$42:D$161,4,FALSE) -> 27.052355 | C39: =IF(B39="Undetermined",40.1,B39) -> 27.052355 | D39: =VLOOKUP(A39,'Exported Results'!A$42:D$161,2,FALSE) -> 2.3.a | E39: =AVERAGE(C39:C41) -> 26.997463 | F39: =_xlfn.STDEV.P(C39:C41) -> 0.25393282
A40: B14 | B40: =VLOOKUP(A40,'Exported Results'!A$42:D$161,4,FALSE) -> 26.662668 | C40: =IF(B40="Undetermined",40.1,B40) -> 26.662668 | D40: =VLOOKUP(A40,'Exported Results'!A$42:D$161,2,FALSE) -> 2.3.b
A41: B15 | B41: =VLOOKUP(A41,'Exported Results'!A$42:D$161,4,FALSE) -> 27.277365 | C41: =IF(B41="Undetermined",40.1,B41) -> 27.277365 | D41: =VLOOKUP(A41,'Exported Results'!A$42:D$161,2,FALSE) -> 2.3.c
...

Sheet ATG5
A1: Standard dilution | B1: Av CT | C1: SD CT | D1: CV CT | E1: Dilution | F1: log dilution
A2: =B33 -> STD 10a | B2: =C33 -> 25.369516 | C2: =D33 -> 0.10859323 | D2: =C2/B2 -> 0.0042804613 | E2: 0.1 | F2: =LOG(E2,10) -> -1
A3: =B34 -> STD 20a | B3: =C34 -> 25.907526 | C3: =D34 -> 0.22035223 | D3: =C3/B3 -> 0.0085053366 | E3: 0.05 | F3: =LOG(E3,10) -> -1.30103
A4: =B35 -> STD 40a | B4: =C35 -> 27.283505 | C4: =D35 -> 0.075715866 | D4: =C4/B4 -> 0.0027751517 | E4: 0.025 | F4: =LOG(E4,10) -> -1.60206
A5: =B36 -> STD 80a | B5: =C36 -> 28.17183 | C5: =D36 -> 0.21826888 | D5: =C5/B5 -> 0.0077477706 | E5: 0.0125 | F5: =LOG(E5,10) -> -1.90309
A6: =B37 -> STD 160a | B6: =C37 -> 29.307207 | C6: =D37 -> 0.10852986 | D6: =C6/B6 -> 0.0037031798 | E6: 0.00625 | F6: =LOG(E6,10) -> -2.20412
A7: =B38 -> STD 320a | B7: =C38 -> 30.466387 | C7: =D38 -> 0.13469041 | D7: =C7/B7 -> 0.0044209511 | E7: 0.003125 | F7: =LOG(E7,10) -> -2.50515
B28: Slope | C28: =SLOPE(B2:B7,F2:F7) -> -3.4711036
B29: Efficiency | C29: =10^(-1/C28) -> 1.9413007
B31: Sample | C31: Av Ct | D31: SD Ct | E31: CV Ct | F31: delta Ct (to STD 20) | G31: deltadelta Ct
B32: ='Results Workspace'!D3 -> Blank 1.a | C32: ='Results Workspace'!E3 -> 34.034349 | D32: ='Results Workspace'!F3 -> 0.87781715 | E32: =D32/C32 -> 0.025792094 | F32: =$C$29^($B$3-C32) -> 0.0045574357
B33: ='Results Workspace'!D6 -> STD 10a | C33: ='Results Workspace'!E6 -> 25.369516 | D33: ='Results Workspace'!F6 -> 0.10859323 | E33: =D33/C33 -> 0.0042804613 | F33: =$C$29^($B$3-C33) -> 1.4288831
B34: ='Results Workspace'!D9 -> STD 20a | C34: ='Results Workspace'!E9 -> 25.907526 | D34: ='Results Workspace'!F9 -> 0.22035223 | E34: =D34/C34 -> 0.0085053366 | F34: =$C$29^($B$3-C34) -> 1
B35: ='Results Workspace'!D12 -> STD 40a | C35: ='Results Workspace'!E12 -> 27.283505 | D35: ='Results Workspace'!F12 -> 0.075715866 | E35: =D35/C35 -> 0.0027751517 | F35: =$C$29^($B$3-C35) -> 0.40141196
B36: ='Results Workspace'!D15 -> STD 80a | C36: ='Results Workspace'!E15 -> 28.17183 | D36: ='Results Workspace'!F15 -> 0.21826888 | E36: =D36/C36 -> 0.0077477706 | F36: =$C$29^($B$3-C36) -> 0.22267442
B37: ='Results Workspace'!D18 -> STD 160a | C37: ='Results Workspace'!E18 -> 29.307207 | D37: ='Results Workspace'!F18 -> 0.10852986 | E37: =D37/C37 -> 0.0037031798 | F37: =$C$29^($B$3-C37) -> 0.1048519
B38: ='Results Workspace'!D21 -> STD 320a | C38: ='Results Workspace'!E21 -> 30.466387 | D38: ='Results Workspace'!F21 -> 0.13469041 | E38: =D38/C38 -> 0.0044209511 | F38: =$C$29^($B$3-C38) -> 0.048598734
B39: ='Results Workspace'!D24 -> 0.1.a | C39: ='Results Workspace'!E24 -> 26.984384 | D39: ='Results Workspace'!F24 -> 0.10113031 | E39: =D39/C39 -> 0.0037477347 | F39: =$C$29^($B$3-C39) -> 0.48951384 | G39: =F39/'Housekeeper summary'!$E$4 -> 0.92361103
B40: ='Results Workspace'!D27 -> 0.2.a | C40: ='Results Workspace'!E27 -> 27.163047 | D40: ='Results Workspace'!F27 -> 0.076943245 | E40: =D40/C40 -> 0.0028326442 | F40: =$C$29^($B$3-C40) -> 0.43480403 | G40: =F40/'Housekeeper summary'!$E$4 -> 0.82038497
B41: ='Results Workspace'!D30 -> 0.3.a | C41: ='Results Workspace'!E30 -> 27.093292 | D41: ='Results Workspace'!F30 -> 0.078945143 | E41: =D41/C41 -> 0.0029138262 | F41: =$C$29^($B$3-C41) -> 0.45539625 | G41: =F41/'Housekeeper summary'!$E$4 -> 0.85923821
B42: ='Results Workspace'!D33 -> 2.1.a | C42: ='Results Workspace'!E33 -> 26.918574 | D42: ='Results Workspace'!F33 -> 0.040919359 | E42: =D42/C42 -> 0.0015201161 | F42: =$C$29^($B$3-C42) -> 0.51135715 | G42: =F42/'Housekeeper summary'!$E$4 -> 0.96482482
B43: ='Results Workspace'!D36 -> 2.2.a | C43: ='Results Workspace'!E36 -> 27.575932 | D43: ='Results Workspace'!F36 -> 0.18415553 | E43: =D43/C43 -> 0.0066781253 | F43: =$C$29^($B$3-C43) -> 0.33063145 | G43: =F43/'Housekeeper summary'!$E$4 -> 0.62383293
B44: ='Results Workspace'!D39 -> 2.3.a | C44: ='Results Workspace'!E39 -> 26.997463 | D44: ='Results Workspace'!F39 -> 0.25393282 | E44: =D44/C44 -> 0.0094058032 | F44: =$C$29^($B$3-C44) -> 0.48528526 | G44: =F44/'Housekeeper summary'!$E$4 -> 0.91563257
B45: ='Results Workspace'!D42 -> 8.1.a | C45: ='Results Workspace'!E42 -> 27.445764 | D45: ='Results Workspace'!F42 -> 0.050216522 | E45: =D45/C45 -> 0.0018296638 | F45: =$C$29^($B$3-C45) -> 0.36044974 | G45: =F45/'Housekeeper summary'!$E$4 -> 0.68009385
B46: ='Results Workspace'!D45 -> 8.2.a | C46: ='Results Workspace'!E45 -> 27.542994 | D46: ='Results Workspace'!F45 -> 0.035537233 | E46: =D46/C46 -> 0.0012902459 | F46: =$C$29^($B$3-C46) -> 0.3379353 | G46: =F46/'Housekeeper summary'!$E$4 -> 0.63761376
B47: ='Results Workspace'!D48 -> 8.3.a | C47: ='Results Workspace'!E48 -> 26.837469 | D47: ='Results Workspace'!F48 -> 0.042916192 | E47: =D47/C47 -> 0.0015991147 | F47: =$C$29^($B$3-C47) -> 0.53962253 | G47: =F47/'Housekeeper summary'!$E$4 -> 1.0181557
B48: ='Results Workspace'!D51 -> 0.4.a | C48: ='Results Workspace'!E51 -> 26.977293 | D48: ='Results Workspace'!F51 -> 0.044723677 | E48: =D48/C48 -> 0.0016578267 | F48: =$C$29^($B$3-C48) -> 0.49182184 | G48: =F48/'Housekeeper summary'!$E$4 -> 0.92796574
B49: ='Results Workspace'!D54 -> 0.5.a | C49: ='Results Workspace'!E54 -> 27.387163 | D49: ='Results Workspace'!F54 -> 0.12271914 | E49: =D49/C49 -> 0.0044809001 | F49: =$C$29^($B$3-C49) -> 0.37473767 | G49: =F49/'Housekeeper summary'!$E$4 -> 0.70705221
B50: ='Results Workspace'!D57 -> 0.6.a | C50: ='Results Workspace'!E57 -> 27.726927 | D50: ='Results Workspace'!F57 -> 0.25018981 | E50: =D50/C50 -> 0.0090233516 | F50: =$C$29^($B$3-C50) -> 0.29911867 | G50: =F50/'Housekeeper summary'!$E$4 -> 0.56437485
B51: ='Results Workspace'!D60 -> 0.7.a | C51: ='Results Workspace'!E60 -> 29.197978 | D51: ='Results Workspace'!F60 -> 0.10150906 | E51: =D51/C51 -> 0.0034765785 | F51: =$C$29^($B$3-C51) -> 0.11273125 | G51: =F51/'Housekeeper summary'!$E$4 -> 0.21270047
B52: ='Results Workspace'!D63 -> 0.8.a | C52: ='Results Workspace'!E63 -> 27.094268 | D52: ='Results Workspace'!F63 -> 0.24513517 | E52: =D52/C52 -> 0.0090474917 | F52: =$C$29^($B$3-C52) -> 0.45510134 | G52: =F52/'Housekeeper summary'!$E$4 -> 0.85868177
B53: ='Results Workspace'!D66 -> 0.9.a | C53: ='Results Workspace'!E66 -> 26.658962 | D53: ='Results Workspace'!F66 -> 0.21475511 | E53: =D53/C53 -> 0.0080556443 | F53: =$C$29^($B$3-C53) -> 0.60745876 | G53: =F53/'Housekeeper summary'!$E$4 -> 1.1461486
B54: ='Results Workspace'!D69 -> 2.4.a | C54: ='Results Workspace'!E69 -> 27.69861 | D54: ='Results Workspace'!F69 -> 0.17998242 | E54: =D54/C54 -> 0.0064978863 | F54: =$C$29^($B$3-C54) -> 0.30479054 | G54: =F54/'Housekeeper summary'!$E$4 -> 0.57507649
B55: ='Results Workspace'!D72 -> 2.5.a | C55: ='Results Workspace'!E72 -> 28.36083 | D55: ='Results Workspace'!F72 -> 0.13774068 | E55: =D55/C55 -> 0.0048567223 | F55: =$C$29^($B$3-C55) -> 0.19643581 | G55: =F55/'Housekeeper summary'!$E$4 -> 0.3706336
B56: ='Results Workspace'!D75 -> 2.6.a | C56: ='Results Workspace'!E75 -> 27.652743 | D56: ='Results Workspace'!F75 -> 0.10750597 | E56: =D56/C56 -> 0.0038877144 | F56: =$C$29^($B$3-C56) -> 0.31420676 | G56: =F56/'Housekeeper summary'!$E$4 -> 0.59284293
B57: ='Results Workspace'!D78 -> 2.7.a | C57: ='Results Workspace'!E78 -> 26.46083 | D57: ='Results Workspace'!F78 -> 0.11986233 | E57: =D57/C57 -> 0.0045298022 | F57: =$C$29^($B$3-C57) -> 0.69278278 | G57: =F57/'Housekeeper summary'!$E$4 -> 1.3071373
B58: ='Results Workspace'!D81 -> 2.8.a | C58: ='Results Workspace'!E81 -> #DIV/0! | D58: ='Results Workspace'!F81 -> #DIV/0! | E58: =D58/C58 -> #DIV/0! | F58: =$C$29^($B$3-C58) -> #DIV/0! | G58: =F58/'Housekeeper summary'!$E$4 -> #DIV/0!
B59: ='Results Workspace'!D84 -> 2.9.a | C59: ='Results Workspace'!E84 -> 27.380887 | D59: ='Results Workspace'!F84 -> 0.18439177 | E59: =D59/C59 -> 0.0067343242 | F59: =$C$29^($B$3-C59) -> 0.37630084 | G59: =F59/'Housekeeper summary'!$E$4 -> 0.71000158
B60: ='Results Workspace'!D87 -> 8.4.a | C60: ='Results Workspace'!E87 -> #DIV/0! | D60: ='Results Workspace'!F87 -> #DIV/0! | E60: =D60/C60 -> #DIV/0! | F60: =$C$29^($B$3-C60) -> #DIV/0! | G60: =F60/'Housekeeper summary'!$E$4 -> #DIV/0!
B61: ='Results Workspace'!D90 -> 8.5.a | C61: ='Results Workspace'!E90 -> 27.215469 | D61: ='Results Workspace'!F90 -> 0.15057581 | E61: =D61/C61 -> 0.0055327288 | F61: =$C$29^($B$3-C61) -> 0.41994373 | G61: =F61/'Housekeeper summary'!$E$4 -> 0.79234666
...

Sheet ATG7
A1: Standard dilution | B1: Av CT | C1: SD CT | D1: CV CT | E1: Dilution | F1: log dilution
A2: =B33 -> STD 10a | B2: =C33 -> 26.394094 | C2: =D33 -> 0.036956665 | D2: =C2/B2 -> 0.0014001869 | E2: 0.1 | F2: =LOG(E2,10) -> -1
A3: =B34 -> STD 20a | B3: =C34 -> 27.180834 | C3: =D34 -> 0.072766424 | D3: =C3/B3 -> 0.0026771225 | E3: 0.05 | F3: =LOG(E3,10) -> -1.30103
A4: =B35 -> STD 40a | B4: =C35 -> 28.207694 | C4: =D35 -> 0.12669 | D4: =C4/B4 -> 0.0044913276 | E4: 0.025 | F4: =LOG(E4,10) -> -1.60206
A5: =B36 -> STD 80a | B5: =C36 -> 29.255451 | C5: =D36 -> 0.082444979 | D5: =C5/B5 -> 0.0028181066 | E5: 0.0125 | F5: =LOG(E5,10) -> -1.90309
A6: =B37 -> STD 160a | B6: =C37 -> 30.3968 | C6: =D37 -> 0.09793067 | D6: =C6/B6 -> 0.0032217428 | E6: 0.00625 | F6: =LOG(E6,10) -> -2.20412
A7: =B38 -> STD 320a | B7: =C38 -> 31.583166 | C7: =D38 -> 0.13457537 | D7: =C7/B7 -> 0.0042609842 | E7: 0.003125 | F7: =LOG(E7,10) -> -2.50515
B28: Slope | C28: =SLOPE(B2:B7,F2:F7) -> -3.4776804
B29: Efficiency | C29: =10^(-1/C28) -> 1.9388669
B31: Sample | C31: Av Ct | D31: SD Ct | E31: CV Ct | F31: delta Ct (to STD 20) | G31: deltadelta Ct
B32: ='Results Workspace'!D123 -> Blank 1.a | C32: ='Results Workspace'!E123 -> 40.1 | D32: ='Results Workspace'!F123 -> 0 | E32: =D32/C32 -> 0 | F32: =$C$29^($B$3-C32) -> 0.00019280574
B33: ='Results Workspace'!D126 -> STD 10a | C33: ='Results Workspace'!E126 -> 26.394094 | D33: ='Results Workspace'!F126 -> 0.036956665 | E33: =D33/C33 -> 0.0014001869 | F33: =$C$29^($B$3-C33) -> 1.6835487
B34: ='Results Workspace'!D129 -> STD 20a | C34: ='Results Workspace'!E129 -> 27.180834 | D34: ='Results Workspace'!F129 -> 0.072766424 | E34: =D34/C34 -> 0.0026771225 | F34: =$C$29^($B$3-C34) -> 1
B35: ='Results Workspace'!D132 -> STD 40a | C35: ='Results Workspace'!E132 -> 28.207694 | D35: ='Results Workspace'!F132 -> 0.12669 | E35: =D35/C35 -> 0.0044913276 | F35: =$C$29^($B$3-C35) -> 0.50667386
B36: ='Results Workspace'!D135 -> STD 80a | C36: ='Results Workspace'!E135 -> 29.255451 | D36: ='Results Workspace'!F135 -> 0.082444979 | E36: =D36/C36 -> 0.0028181066 | F36: =$C$29^($B$3-C36) -> 0.25319092
B37: ='Results Workspace'!D138 -> STD 160a | C37: ='Results Workspace'!E138 -> 30.3968 | D37: ='Results Workspace'!F138 -> 0.09793067 | E37: =D37/C37 -> 0.0032217428 | F37: =$C$29^($B$3-C37) -> 0.11892021
B38: ='Results Workspace'!D141 -> STD 320a | C38: ='Results Workspace'!E141 -> 31.583166 | D38: ='Results Workspace'!F141 -> 0.13457537 | E38: =D38/C38 -> 0.0042609842 | F38: =$C$29^($B$3-C38) -> 0.054214866
B39: ='Results Workspace'!D144 -> 0.1.a | C39: ='Results Workspace'!E144 -> 28.052827 | D39: ='Results Workspace'!F144 -> 0.1284474 | E39: =D39/C39 -> 0.0045787685 | F39: =$C$29^($B$3-C39) -> 0.56138427 | G39: =F39/'Housekeeper summary'!$E$4 -> 1.0592156
B40: ='Results Workspace'!D147 -> 0.2.a | C40: ='Results Workspace'!E147 -> 28.274887 | D40: ='Results Workspace'!F147 -> 0.093967908 | E40: =D40/C40 -> 0.0033233699 | F40: =$C$29^($B$3-C40) -> 0.48462673 | G40: =F40/'Housekeeper summary'!$E$4 -> 0.91439006
B41: ='Results Workspace'!D150 -> 0.3.a | C41: ='Results Workspace'!E150 -> 28.305675 | D41: ='Results Workspace'!F150 -> 0.025372008 | E41: =D41/C41 -> 0.00089635765 | F41: =$C$29^($B$3-C41) -> 0.47484777 | G41: =F41/'Housekeeper summary'!$E$4 -> 0.89593919
B42: ='Results Workspace'!D153 -> 2.1.a | C42: ='Results Workspace'!E153 -> 28.260672 | D42: ='Results Workspace'!F153 -> 0.04365465 | E42: =D42/C42 -> 0.0015447138 | F42: =$C$29^($B$3-C42) -> 0.48920963 | G42: =F42/'Housekeeper summary'!$E$4 -> 0.92303704
B43: ='Results Workspace'!D156 -> 2.2.a | C43: ='Results Workspace'!E156 -> 28.289199 | D43: ='Results Workspace'!F156 -> 0.12373898 | E43: =D43/C43 -> 0.0043740715 | F43: =$C$29^($B$3-C43) -> 0.48005605 | G43: =F43/'Housekeeper summary'!$E$4 -> 0.90576614
B44: ='Results Workspace'!D159 -> 2.3.a | C44: ='Results Workspace'!E159 -> 28.075367 | D44: ='Results Workspace'!F159 -> 0.099146578 | E44: =D44/C44 -> 0.0035314437 | F44: =$C$29^($B$3-C44) -> 0.55306856 | G44: =F44/'Housekeeper summary'!$E$4 -> 1.0435256
B45: ='Results Workspace'!D162 -> 8.1.a | C45: ='Results Workspace'!E162 -> 28.259968 | D45: ='Results Workspace'!F162 -> 0.0059513891 | E45: =D45/C45 -> 0.00021059433 | F45: =$C$29^($B$3-C45) -> 0.48943745 | G45: =F45/'Housekeeper summary'!$E$4 -> 0.92346688
B46: ='Results Workspace'!D165 -> 8.2.a | C46: ='Results Workspace'!E165 -> 28.362015 | D46: ='Results Workspace'!F165 -> 0.085022395 | E46: =D46/C46 -> 0.0029977558 | F46: =$C$29^($B$3-C46) -> 0.4574609 | G46: =F46/'Housekeeper summary'!$E$4 -> 0.86313377
B47: ='Results Workspace'!D168 -> 8.3.a | C47: ='Results Workspace'!E168 -> 28.074987 | D47: ='Results Workspace'!F168 -> 0.038342662 | E47: =D47/C47 -> 0.0013657233 | F47: =$C$29^($B$3-C47) -> 0.55320781 | G47: =F47/'Housekeeper summary'!$E$4 -> 1.0437883
B48: ='Results Workspace'!D171 -> 0.4.a | C48: ='Results Workspace'!E171 -> 27.852994 | D48: ='Results Workspace'!F171 -> 0.1785645 | E48: =D48/C48 -> 0.0064109626 | F48: =$C$29^($B$3-C48) -> 0.64079895 | G48: =F48/'Housekeeper summary'!$E$4 -> 1.2090546
B49: ='Results Workspace'!D174 -> 0.5.a | C49: ='Results Workspace'!E174 -> 28.186542 | D49: ='Results Workspace'!F174 -> 0.11928482 | E49: =D49/C49 -> 0.0042319777 | F49: =$C$29^($B$3-C49) -> 0.51381982 | G49: =F49/'Housekeeper summary'!$E$4 -> 0.96947136
B50: ='Results Workspace'!D177 -> 0.6.a | C50: ='Results Workspace'!E177 -> 28.728039 | D50: ='Results Workspace'!F177 -> 0.13139386 | E50: =D50/C50 -> 0.0045737149 | F50: =$C$29^($B$3-C50) -> 0.35900816 | G50: =F50/'Housekeeper summary'!$E$4 -> 0.67737389
B51: ='Results Workspace'!D180 -> 0.7.a | C51: ='Results Workspace'!E180 -> 30.690798 | D51: ='Results Workspace'!F180 -> 0.18302337 | E51: =D51/C51 -> 0.0059634608 | F51: =$C$29^($B$3-C51) -> 0.097885175 | G51: =F51/'Housekeeper summary'!$E$4 -> 0.18468901
B52: ='Results Workspace'!D183 -> 0.8.a | C52: ='Results Workspace'!E183 -> 27.64066 | D52: ='Results Workspace'!F183 -> 0.028723717 | E52: =D52/C52 -> 0.0010391835 | F52: =$C$29^($B$3-C52) -> 0.73752714 | G52: =F52/'Housekeeper summary'!$E$4 -> 1.3915606
B53: ='Results Workspace'!D186 -> 0.9.a | C53: ='Results Workspace'!E186 -> 27.692382 | D53: ='Results Workspace'!F186 -> 0.19973845 | E53: =D53/C53 -> 0.0072127581 | F53: =$C$29^($B$3-C53) -> 0.7126982 | G53: =F53/'Housekeeper summary'!$E$4 -> 1.3447136
B54: ='Results Workspace'!D189 -> 2.4.a | C54: ='Results Workspace'!E189 -> 28.468693 | D54: ='Results Workspace'!F189 -> 0.074674401 | E54: =D54/C54 -> 0.0026230358 | F54: =$C$29^($B$3-C54) -> 0.42626427 | G54: =F54/'Housekeeper summary'!$E$4 -> 0.80427221
B55: ='Results Workspace'!D192 -> 2.5.a | C55: ='Results Workspace'!E192 -> 29.539459 | D55: ='Results Workspace'!F192 -> 0.16979986 | E55: =D55/C55 -> 0.0057482387 | F55: =$C$29^($B$3-C55) -> 0.20978875 | G55: =F55/'Housekeeper summary'!$E$4 -> 0.39582783
B56: ='Results Workspace'!D195 -> 2.6.a | C56: ='Results Workspace'!E195 -> 28.296377 | D56: ='Results Workspace'!F195 -> 0.07064209 | E56: =D56/C56 -> 0.0024965065 | F56: =$C$29^($B$3-C56) -> 0.47777996 | G56: =F56/'Housekeeper summary'!$E$4 -> 0.90147163
B57: ='Results Workspace'!D198 -> 2.7.a | C57: ='Results Workspace'!E198 -> 27.344095 | D57: ='Results Workspace'!F198 -> 0.082032943 | E57: =D57/C57 -> 0.0030000241 | F57: =$C$29^($B$3-C57) -> 0.8975422 | G57: =F57/'Housekeeper summary'!$E$4 -> 1.6934758
B58: ='Results Workspace'!D201 -> 2.8.a | C58: ='Results Workspace'!E201 -> #DIV/0! | D58: ='Results Workspace'!F201 -> #DIV/0! | E58: =D58/C58 -> #DIV/0! | F58: =$C$29^($B$3-C58) -> #DIV/0! | G58: =F58/'Housekeeper summary'!$E$4 -> #DIV/0!
B59: ='Results Workspace'!D204 -> 2.9.a | C59: ='Results Workspace'!E204 -> 28.124681 | D59: ='Results Workspace'!F204 -> 0.090979567 | E59: =D59/C59 -> 0.0032348658 | F59: =$C$29^($B$3-C59) -> 0.53530201 | G59: =F59/'Housekeeper summary'!$E$4 -> 1.0100038
B60: ='Results Workspace'!D207 -> 8.4.a | C60: ='Results Workspace'!E207 -> #DIV/0! | D60: ='Results Workspace'!F207 -> #DIV/0! | E60: =D60/C60 -> #DIV/0! | F60: =$C$29^($B$3-C60) -> #DIV/0! | G60: =F60/'Housekeeper summary'!$E$4 -> #DIV/0!
B61: ='Results Workspace'!D210 -> 8.5.a | C61: ='Results Workspace'!E210 -> 28.102909 | D61: ='Results Workspace'!F210 -> 0.01952019 | E61: =D61/C61 -> 0.00069459678 | F61: =$C$29^($B$3-C61) -> 0.54307435 | G61: =F61/'Housekeeper summary'!$E$4 -> 1.0246686
...

Sheet ATG10
A1: Standard dilution | B1: Av CT | C1: SD CT | D1: CV CT | E1: Dilution | F1: log dilution
A2: =B33 -> STD 10a | B2: =C33 -> 26.867812 | C2: =D33 -> 0.037377324 | D2: =C2/B2 -> 0.0013911562 | E2: 0.1 | F2: =LOG(E2,10) -> -1
A3: =B34 -> STD 20a | B3: =C34 -> 27.944016 | C3: =D34 -> 0.0056324005 | D3: =C3/B3 -> 0.00020156017 | E3: 0.05 | F3: =LOG(E3,10) -> -1.30103
A4: =B35 -> STD 40a | B4: =C35 -> 28.78227 | C4: =D35 -> 0.024351901 | D4: =C4/B4 -> 0.00084607297 | E4: 0.025 | F4: =LOG(E4,10) -> -1.60206
A5: =B36 -> STD 80a | B5: =C36 -> 29.613501 | C5: =D36 -> 0.25298851 | D5: =C5/B5 -> 0.0085430125 | E5: 0.0125 | F5: =LOG(E5,10) -> -1.90309
A6: =B37 -> STD 160a | B6: =C37 -> 30.941669 | C6: =D37 -> 0.015639136 | D6: =C6/B6 -> 0.00050543933 | E6: 0.00625 | F6: =LOG(E6,10) -> -2.20412
A7: =B38 -> STD 320a | B7: =C38 -> 32.113107 | C7: =D38 -> 0.12372584 | D7: =C7/B7 -> 0.0038528143 | E7: 0.003125 | F7: =LOG(E7,10) -> -2.50515
B28: Slope | C28: =SLOPE(B2:B7,F2:F7) -> -3.4216489
B29: Efficiency | C29: =10^(-1/C28) -> 1.9600031
B31: Sample | C31: Av Ct | D31: SD Ct | E31: CV Ct | F31: delta Ct (to STD 20) | G31: deltadelta Ct
B32: ='Results Workspace'!D243 -> Blank 1.a | C32: ='Results Workspace'!E243 -> 40.1 | D32: ='Results Workspace'!F243 -> 0 | E32: =D32/C32 -> 0 | F32: =$C$29^($B$3-C32) -> 0.00028011179
B33: ='Results Workspace'!D246 -> STD 10a | C33: ='Results Workspace'!E246 -> 26.867812 | D33: ='Results Workspace'!F246 -> 0.037377324 | E33: =D33/C33 -> 0.0013911562 | F33: =$C$29^($B$3-C33) -> 2.0631348
B34: ='Results Workspace'!D249 -> STD 20a | C34: ='Results Workspace'!E249 -> 27.944016 | D34: ='Results Workspace'!F249 -> 0.0056324005 | E34: =D34/C34 -> 0.00020156017 | F34: =$C$29^($B$3-C34) -> 1
B35: ='Results Workspace'!D252 -> STD 40a | C35: ='Results Workspace'!E252 -> 28.78227 | D35: ='Results Workspace'!F252 -> 0.024351901 | E35: =D35/C35 -> 0.00084607297 | F35: =$C$29^($B$3-C35) -> 0.56887171
B36: ='Results Workspace'!D255 -> STD 80a | C36: ='Results Workspace'!E255 -> 29.613501 | D36: ='Results Workspace'!F255 -> 0.25298851 | E36: =D36/C36 -> 0.0085430125 | F36: =$C$29^($B$3-C36) -> 0.32514846
B37: ='Results Workspace'!D258 -> STD 160a | C37: ='Results Workspace'!E258 -> 30.941669 | D37: ='Results Workspace'!F258 -> 0.015639136 | E37: =D37/C37 -> 0.00050543933 | F37: =$C$29^($B$3-C37) -> 0.13301958
B38: ='Results Workspace'!D261 -> STD 320a | C38: ='Results Workspace'!E261 -> 32.113107 | D38: ='Results Workspace'!F261 -> 0.12372584 | E38: =D38/C38 -> 0.0038528143 | F38: =$C$29^($B$3-C38) -> 0.060472069
B39: ='Results Workspace'!D264 -> 0.1.a | C39: ='Results Workspace'!E264 -> 28.747938 | D39: ='Results Workspace'!F264 -> 0.077257463 | E39: =D39/C39 -> 0.0026874088 | F39: =$C$29^($B$3-C39) -> 0.58216779 | G39: =F39/'Housekeeper summary'!$E$4 -> 1.0984298
B40: ='Results Workspace'!D267 -> 0.2.a | C40: ='Results Workspace'!E267 -> 28.987052 | D40: ='Results Workspace'!F267 -> 0.081268037 | E40: =D40/C40 -> 0.0028035978 | F40: =$C$29^($B$3-C40) -> 0.49563898 | G40: =F40/'Housekeeper summary'!$E$4 -> 0.93516789
B41: ='Results Workspace'!D270 -> 0.3.a | C41: ='Results Workspace'!E270 -> 28.660826 | D41: ='Results Workspace'!F270 -> 0.049178378 | E41: =D41/C41 -> 0.0017158744 | F41: =$C$29^($B$3-C41) -> 0.6173155 | G41: =F41/'Housekeeper summary'!$E$4 -> 1.1647462
B42: ='Results Workspace'!D273 -> 2.1.a | C42: ='Results Workspace'!E273 -> 28.797217 | D42: ='Results Workspace'!F273 -> 0.078046513 | E42: =D42/C42 -> 0.0027102103 | F42: =$C$29^($B$3-C42) -> 0.56317852 | G42: =F42/'Housekeeper summary'!$E$4 -> 1.062601
B43: ='Results Workspace'!D276 -> 2.2.a | C43: ='Results Workspace'!E276 -> 28.909216 | D43: ='Results Workspace'!F276 -> 0.16970373 | E43: =D43/C43 -> 0.0058702293 | F43: =$C$29^($B$3-C43) -> 0.52229234 | G43: =F43/'Housekeeper summary'!$E$4 -> 0.98545724
B44: ='Results Workspace'!D279 -> 2.3.a | C44: ='Results Workspace'!E279 -> 28.749145 | D44: ='Results Workspace'!F279 -> 0.17878892 | E44: =D44/C44 -> 0.00621893 | F44: =$C$29^($B$3-C44) -> 0.58169523 | G44: =F44/'Housekeeper summary'!$E$4 -> 1.0975382
B45: ='Results Workspace'!D282 -> 8.1.a | C45: ='Results Workspace'!E282 -> 28.836127 | D45: ='Results Workspace'!F282 -> 0.12922873 | E45: =D45/C45 -> 0.004481487 | F45: =$C$29^($B$3-C45) -> 0.54862349 | G45: =F45/'Housekeeper summary'!$E$4 -> 1.0351387
B46: ='Results Workspace'!D285 -> 8.2.a | C46: ='Results Workspace'!E285 -> 28.930133 | D46: ='Results Workspace'!F285 -> 0.032573912 | E46: =D46/C46 -> 0.001125951 | F46: =$C$29^($B$3-C46) -> 0.51499218 | G46: =F46/'Housekeeper summary'!$E$4 -> 0.97168335
B47: ='Results Workspace'!D288 -> 8.3.a | C47: ='Results Workspace'!E288 -> 28.725109 | D47: ='Results Workspace'!F288 -> 0.1160601 | E47: =D47/C47 -> 0.0040403709 | F47: =$C$29^($B$3-C47) -> 0.59118052 | G47: =F47/'Housekeeper summary'!$E$4 -> 1.115435
B48: ='Results Workspace'!D291 -> 0.4.a | C48: ='Results Workspace'!E291 -> 28.430091 | D48: ='Results Workspace'!F291 -> 0.08066411 | E48: =D48/C48 -> 0.0028372793 | F48: =$C$29^($B$3-C48) -> 0.72100967 | G48: =F48/'Housekeeper summary'!$E$4 -> 1.3603956
B49: ='Results Workspace'!D294 -> 0.5.a | C49: ='Results Workspace'!E294 -> 28.642039 | D49: ='Results Workspace'!F294 -> 0.12689036 | E49: =D49/C49 -> 0.0044302139 | F49: =$C$29^($B$3-C49) -> 0.6251697 | G49: =F49/'Housekeeper summary'!$E$4 -> 1.1795655
B50: ='Results Workspace'!D297 -> 0.6.a | C50: ='Results Workspace'!E297 -> 28.839453 | D50: ='Results Workspace'!F297 -> 0.042471485 | E50: =D50/C50 -> 0.0014726869 | F50: =$C$29^($B$3-C50) -> 0.54739677 | G50: =F50/'Housekeeper summary'!$E$4 -> 1.0328241
B51: ='Results Workspace'!D300 -> 0.7.a | C51: ='Results Workspace'!E300 -> 30.775831 | D51: ='Results Workspace'!F300 -> 0.22096822 | E51: =D51/C51 -> 0.0071799272 | F51: =$C$29^($B$3-C51) -> 0.14872463 | G51: =F51/'Housekeeper summary'!$E$4 -> 0.28061252
B52: ='Results Workspace'!D303 -> 0.8.a | C52: ='Results Workspace'!E303 -> 28.341237 | D52: ='Results Workspace'!F303 -> 0.27961079 | E52: =D52/C52 -> 0.0098658639 | F52: =$C$29^($B$3-C52) -> 0.76543659 | G52: =F52/'Housekeeper summary'!$E$4 -> 1.44422
B53: ='Results Workspace'!D306 -> 0.9.a | C53: ='Results Workspace'!E306 -> 28.26667 | D53: ='Results Workspace'!F306 -> 0.063616323 | E53: =D53/C53 -> 0.0022505772 | F53: =$C$29^($B$3-C53) -> 0.80482596 | G53: =F53/'Housekeeper summary'!$E$4 -> 1.5185395
B54: ='Results Workspace'!D309 -> 2.4.a | C54: ='Results Workspace'!E309 -> 28.854655 | D54: ='Results Workspace'!F309 -> 0.10778307 | E54: =D54/C54 -> 0.0037353789 | F54: =$C$29^($B$3-C54) -> 0.54182554 | G54: =F54/'Housekeeper summary'!$E$4 -> 1.0223123
B55: ='Results Workspace'!D312 -> 2.5.a | C55: ='Results Workspace'!E312 -> 29.766582 | D55: ='Results Workspace'!F312 -> 0.16236822 | E55: =D55/C55 -> 0.0054547151 | F55: =$C$29^($B$3-C55) -> 0.29332067 | G55: =F55/'Housekeeper summary'!$E$4 -> 0.55343523
B56: ='Results Workspace'!D315 -> 2.6.a | C56: ='Results Workspace'!E315 -> 28.801395 | D56: ='Results Workspace'!F315 -> 0.051162543 | E56: =D56/C56 -> 0.0017763912 | F56: =$C$29^($B$3-C56) -> 0.56159743 | G56: =F56/'Housekeeper summary'!$E$4 -> 1.0596178
B57: ='Results Workspace'!D318 -> 2.7.a | C57: ='Results Workspace'!E318 -> 27.724384 | D57: ='Results Workspace'!F318 -> 0.094791878 | E57: =D57/C57 -> 0.0034190796 | F57: =$C$29^($B$3-C57) -> 1.159281 | G57: =F57/'Housekeeper summary'!$E$4 -> 2.1873226
B58: ='Results Workspace'!D321 -> 2.8.a | C58: ='Results Workspace'!E321 -> #DIV/0! | D58: ='Results Workspace'!F321 -> #DIV/0! | E58: =D58/C58 -> #DIV/0! | F58: =$C$29^($B$3-C58) -> #DIV/0! | G58: =F58/'Housekeeper summary'!$E$4 -> #DIV/0!
B59: ='Results Workspace'!D324 -> 2.9.a | C59: ='Results Workspace'!E324 -> 28.723314 | D59: ='Results Workspace'!F324 -> 0.086422885 | E59: =D59/C59 -> 0.0030088062 | F59: =$C$29^($B$3-C59) -> 0.59189525 | G59: =F59/'Housekeeper summary'!$E$4 -> 1.1167835
B60: ='Results Workspace'!D327 -> 8.4.a | C60: ='Results Workspace'!E327 -> #DIV/0! | D60: ='Results Workspace'!F327 -> #DIV/0! | E60: =D60/C60 -> #DIV/0! | F60: =$C$29^($B$3-C60) -> #DIV/0! | G60: =F60/'Housekeeper summary'!$E$4 -> #DIV/0!
B61: ='Results Workspace'!D330 -> 8.5.a | C61: ='Results Workspace'!E330 -> 28.451129 | D61: ='Results Workspace'!F330 -> 0.044608719 | E61: =D61/C61 -> 0.0015679068 | F61: =$C$29^($B$3-C61) -> 0.71087421 | G61: =F61/'Housekeeper summary'!$E$4 -> 1.3412721
...

Sheet Housekeeper summary
B3: B2M | C3: HMBS | D3: YWHA2 | E3: geometric mean
A4: 0.1.a | B4: 0.51 | C4: 0.56 | D4: 0.52 | E4: 0.53
A5: 0.2.a | B5: 0.46 | C5: 0.53 | D5: 0.42 | E5: 0.47
A6: 0.3.a | B6: 0.49 | C6: 0.59 | D6: 0.5 | E6: 0.52
A7: 2.1.a | B7: 0.52 | C7: 0.51 | D7: 0.5 | E7: 0.51
A8: 2.2.a | B8: 0.43 | C8: 0.62 | D8: 0.41 | E8: 0.48
A9: 2.3.a | B9: 0.5 | C9: 1.02 | D9: 0.58 | E9: 0.67
A10: 8.1.a | B10: 0.44 | C10: 0.59 | D10: 0.4 | E10: 0.47
A11: 8.2.a | B11: 0.41 | C11: 0.47 | D11: 0.41 | E11: 0.43
A12: 8.3.a | B12: 0.55 | C12: 0.73 | D12: 0.52 | E12: 0.6
A13: 0.4.a | B13: 0.63 | C13: 0.54 | D13: 0.55 | E13: 0.57
A14: 0.5.a | B14: 0.48 | C14: 0.45 | D14: 0.47 | E14: 0.46
A15: 0.6.a | B15: 0.45 | C15: 0.49 | D15: 0.42 | E15: 0.45
A16: 0.7.a
A17: 0.8.a | B17: 0.44 | C17: 0.79 | D17: 0.64 | E17: 0.6
A18: 0.9.a | B18: 0.57 | C18: 0.58 | D18: 0.65 | E18: 0.6
A19: 2.4.a | B19: 0.4 | C19: 0.44 | D19: 0.39 | E19: 0.41
A20: 2.5.a
A21: 2.6.a | B21: 0.44 | C21: 0.42 | D21: 0.38 | E21: 0.41
A22: 2.7.a | B22: 0.73 | C22: 0.55 | D22: 0.76 | E22: 0.67
A23: 2.8.a
A24: 2.9.a | B24: 0.55 | C24: 0.5 | D24: 0.44 | E24: 0.49
A25: 8.4.a
A26: 8.5.a | B26: 0.56 | C26: 0.49 | D26: 0.56 | E26: 0.54
A27: 8.6.a | B27: 0.6 | C27: 0.6 | D27: 0.62 | E27: 0.6
A28: 8.7.a | B28: 0.51 | C28: 0.72 | D28: 0.5 | E28: 0.56
A29: 8.8.a | B29: 0.51 | C29: 0.86 | D29: 0.57 | E29: 0.63
A30: 8.9.a | B30: 0.38 | C30: 0.49 | D30: 0.42 | E30: 0.43
