Workbook

Sheet Exported Results
A1: Block Type | B1: 384-Well Block
A2: Calibration Background is expired | B2: No
A3: Calibration Background performed on | B3: 10-06-2021
A4: Calibration Normalization FAM-ROX is expired | B4: No
A5: Calibration Normalization FAM-ROX performed on | B5: 10-06-2021
A6: Calibration Normalization VIC-ROX is expired | B6: No
A7: Calibration Normalization VIC-ROX performed on | B7: 10-06-2021
A8: Calibration Pure Dye FAM is expired | B8: No
A9: Calibration Pure Dye FAM performed on | B9: 10-06-2021
A10: Calibration Pure Dye NED is expired | B10: No
A11: Calibration Pure Dye NED performed on | B11: 10-06-2021
A12: Calibration Pure Dye ROX is expired | B12: No
... A25: Date Created | B25: 2021-11-05 13:21:38 PM GMT
A26: Experiment Barcode
A27: Experiment Comment
A28: Experiment File Name | B28: D:\Users\Administrator\Desktop\FELIX\Felix HF v LF 5.eds
A29: Experiment Name | B29: Felix HF v LF 5
A30: Experiment Run End Time | B30: 2021-11-05 14:12:10 PM GMT
A31: Experiment Type | B31: Standard Curve
A32: Instrument Name | B32: HotPants
A33: Instrument Serial Number | B33: 278871706
A34: Instrument Type | B34: QuantStudio(TM) 7 Flex System
A35: Passive Reference | B35: ROX
A36: Quantification Cycle Method | B36: Ct
A37: Signal Smoothing On | B37: true
A38: Stage/ Cycle where Analysis is performed | B38: Stage 2, Step 2
A39: User Name
A41: Well Position | B41: Sample Name | C41: Target Name | D41: CT | H41: Sample Name
A42: A1 | B42: Blank 1.a | C42: NLRP3 | D42: Undetermined | H42: Blank 1.a
A43: A2 | B43: Blank 1.b | C43: NLRP3 | D43: Undetermined | H43: Blank 1.b
A44: A3 | B44: Blank 1.c | C44: NLRP3 | D44: Undetermined | H44: Blank 1.c
A45: A4 | B45: STD 10a | C45: NLRP3 | D45: 36.972271 | H45: STD 10a
A46: A5 | B46: STD 10b | C46: NLRP3 | D46: 38.422947 | H46: STD 10b
A47: A6 | B47: STD 10c | C47: NLRP3 | D47: 39.003254 | H47: STD 10c
A48: A7 | B48: STD 20a | C48: NLRP3 | D48: 38.318333 | H48: STD 20a
A49: A8 | B49: STD 20b | C49: NLRP3 | D49: Undetermined | H49: STD 20b
A50: A9 | B50: STD 20c | C50: NLRP3 | D50: Undetermined | H50: STD 20c
A51: A10 | B51: STD 40a | C51: NLRP3 | D51: Undetermined | H51: STD 40a
A52: A11 | B52: STD 40b | C52: NLRP3 | D52: Undetermined | H52: STD 40b
A53: A12 | B53: STD 40c | C53: NLRP3 | D53: Undetermined | H53: STD 40c
...

Sheet Results Workspace
A2: Well | B2: Ct from reader | C2: Corrected Cts | D2: Sample Name | E2: Average Ct | F2: STDEV
A3: A1 | B3: =VLOOKUP(A3,'Exported Results'!A$42:D$161,4,FALSE) -> Undetermined | C3: =IF(B3="Undetermined",40.1,B3) -> 40.1 | D3: =VLOOKUP(A3,'Exported Results'!A$42:D$161,2,FALSE) -> Blank 1.a | E3: =AVERAGE(C3:C5) -> 40.1 | F3: =_xlfn.STDEV.P(C3:C5) -> 0
A4: A2 | B4: =VLOOKUP(A4,'Exported Results'!A$42:D$161,4,FALSE) -> Undetermined | D4: =VLOOKUP(A4,'Exported Results'!A$42:D$161,2,FALSE) -> Blank 1.b
A5: A3 | B5: =VLOOKUP(A5,'Exported Results'!A$42:D$161,4,FALSE) -> Undetermined | C5: =IF(B5="Undetermined",40.1,B5) -> 40.1 | D5: =VLOOKUP(A5,'Exported Results'!A$42:D$161,2,FALSE) -> Blank 1.c
A6: A4 | B6: =VLOOKUP(A6,'Exported Results'!A$42:D$161,4,FALSE) -> 36.972271 | C6: =IF(B6="Undetermined",40.1,B6) -> 36.972271 | D6: =VLOOKUP(A6,'Exported Results'!A$42:D$161,2,FALSE) -> STD 10a | E6: =AVERAGE(C6:C8) -> 38.132824 | F6: =_xlfn.STDEV.P(C6:C8) -> 0.85414732
A7: A5 | B7: =VLOOKUP(A7,'Exported Results'!A$42:D$161,4,FALSE) -> 38.422947 | C7: =IF(B7="Undetermined",40.1,B7) -> 38.422947 | D7: =VLOOKUP(A7,'Exported Results'!A$42:D$161,2,FALSE) -> STD 10b
A8: A6 | B8: =VLOOKUP(A8,'Exported Results'!A$42:D$161,4,FALSE) -> 39.003254 | C8: =IF(B8="Undetermined",40.1,B8) -> 39.003254 | D8: =VLOOKUP(A8,'Exported Results'!A$42:D$161,2,FALSE) -> STD 10c
A9: A7 | B9: =VLOOKUP(A9,'Exported Results'!A$42:D$161,4,FALSE) -> 38.318333 | C9: =IF(B9="Undetermined",40.1,B9) -> 38.318333 | D9: =VLOOKUP(A9,'Exported Results'!A$42:D$161,2,FALSE) -> STD 20a | E9: =AVERAGE(C9:C11) -> 39.506111 | F9: =_xlfn.STDEV.P(C9:C11) -> 0.83988603
A10: A8 | B10: =VLOOKUP(A10,'Exported Results'!A$42:D$161,4,FALSE) -> Undetermined | C10: =IF(B10="Undetermined",40.1,B10) -> 40.1 | D10: =VLOOKUP(A10,'Exported Results'!A$42:D$161,2,FALSE) -> STD 20b
A11: A9 | B11: =VLOOKUP(A11,'Exported Results'!A$42:D$161,4,FALSE) -> Undetermined | C11: =IF(B11="Undetermined",40.1,B11) -> 40.1 | D11: =VLOOKUP(A11,'Exported Results'!A$42:D$161,2,FALSE) -> STD 20c
A12: A10 | B12: =VLOOKUP(A12,'Exported Results'!A$42:D$161,4,FALSE) -> Undetermined | C12: =IF(B12="Undetermined",40.1,B12) -> 40.1 | D12: =VLOOKUP(A12,'Exported Results'!A$42:D$161,2,FALSE) -> STD 40a | E12: =AVERAGE(C12:C14) -> 40.1 | F12: =_xlfn.STDEV.P(C12:C14) -> 0
A13: A11 | B13: =VLOOKUP(A13,'Exported Results'!A$42:D$161,4,FALSE) -> Undetermined | C13: =IF(B13="Undetermined",40.1,B13) -> 40.1 | D13: =VLOOKUP(A13,'Exported Results'!A$42:D$161,2,FALSE) -> STD 40b
A14: A12 | B14: =VLOOKUP(A14,'Exported Results'!A$42:D$161,4,FALSE) -> Undetermined | C14: =IF(B14="Undetermined",40.1,B14) -> 40.1 | D14: =VLOOKUP(A14,'Exported Results'!A$42:D$161,2,FALSE) -> STD 40c
A15: A13 | B15: =VLOOKUP(A15,'Exported Results'!A$42:D$161,4,FALSE) -> Undetermined | C15: =IF(B15="Undetermined",40.1,B15) -> 40.1 | D15: =VLOOKUP(A15,'Exported Results'!A$42:D$161,2,FALSE) -> STD 80a | E15: =AVERAGE(C15:C17) -> 39.359822 | F15: =_xlfn.STDEV.P(C15:C17) -> 1.0467693
A16: A14 | B16: =VLOOKUP(A16,'Exported Results'!A$42:D$161,4,FALSE) -> Undetermined | C16: =IF(B16="Undetermined",40.1,B16) -> 40.1 | D16: =VLOOKUP(A16,'Exported Results'!A$42:D$161,2,FALSE) -> STD 80b
A17: A15 | B17: =VLOOKUP(A17,'Exported Results'!A$42:D$161,4,FALSE) -> 37.879467 | C17: =IF(B17="Undetermined",40.1,B17) -> 37.879467 | D17: =VLOOKUP(A17,'Exported Results'!A$42:D$161,2,FALSE) -> STD 80c
A18: A16 | B18: =VLOOKUP(A18,'Exported Results'!A$42:D$161,4,FALSE) -> Undetermined | C18: =IF(B18="Undetermined",40.1,B18) -> 40.1 | D18: =VLOOKUP(A18,'Exported Results'!A$42:D$161,2,FALSE) -> STD 160a | E18: =AVERAGE(C18:C20) -> 40.1 | F18: =_xlfn.STDEV.P(C18:C20) -> 0
A19: A17 | B19: =VLOOKUP(A19,'Exported Results'!A$42:D$161,4,FALSE) -> Undetermined | C19: =IF(B19="Undetermined",40.1,B19) -> 40.1 | D19: =VLOOKUP(A19,'Exported Results'!A$42:D$161,2,FALSE) -> STD 160b
A20: A18 | B20: =VLOOKUP(A20,'Exported Results'!A$42:D$161,4,FALSE) -> Undetermined | C20: =IF(B20="Undetermined",40.1,B20) -> 40.1 | D20: =VLOOKUP(A20,'Exported Results'!A$42:D$161,2,FALSE) -> STD 160c
A21: A19 | B21: =VLOOKUP(A21,'Exported Results'!A$42:D$161,4,FALSE) -> Undetermined | C21: =IF(B21="Undetermined",40.1,B21) -> 40.1 | D21: =VLOOKUP(A21,'Exported Results'!A$42:D$161,2,FALSE) -> STD 320a | E21: =AVERAGE(C21:C23) -> 40.1 | F21: =_xlfn.STDEV.P(C21:C23) -> 0
A22: A20 | B22: =VLOOKUP(A22,'Exported Results'!A$42:D$161,4,FALSE) -> Undetermined | C22: =IF(B22="Undetermined",40.1,B22) -> 40.1 | D22: =VLOOKUP(A22,'Exported Results'!A$42:D$161,2,FALSE) -> STD 320b
A23: A21 | B23: =VLOOKUP(A23,'Exported Results'!A$42:D$161,4,FALSE) -> Undetermined | C23: =IF(B23="Undetermined",40.1,B23) -> 40.1 | D23: =VLOOKUP(A23,'Exported Results'!A$42:D$161,2,FALSE) -> STD 320c
A24: A22 | B24: =VLOOKUP(A24,'Exported Results'!A$42:D$161,4,FALSE) -> Undetermined | C24: =IF(B24="Undetermined",40.1,B24) -> 40.1 | D24: =VLOOKUP(A24,'Exported Results'!A$42:D$161,2,FALSE) -> 0.1.a | E24: =AVERAGE(C24:C26) -> 39.546048 | F24: =_xlfn.STDEV.P(C24:C26) -> 0.78340611
A25: A23 | B25: =VLOOKUP(A25,'Exported Results'!A$42:D$161,4,FALSE) -> 38.438145 | C25: =IF(B25="Undetermined",40.1,B25) -> 38.438145 | D25: =VLOOKUP(A25,'Exported Results'!A$42:D$161,2,FALSE) -> 0.1.b
A26: A24 | B26: =VLOOKUP(A26,'Exported Results'!A$42:D$161,4,FALSE) -> Undetermined | C26: =IF(B26="Undetermined",40.1,B26) -> 40.1 | D26: =VLOOKUP(A26,'Exported Results'!A$42:D$161,2,FALSE) -> 0.1.c
A27: B1 | B27: =VLOOKUP(A27,'Exported Results'!A$42:D$161,4,FALSE) -> 38.4613 | C27: =IF(B27="Undetermined",40.1,B27) -> 38.4613 | D27: =VLOOKUP(A27,'Exported Results'!A$42:D$161,2,FALSE) -> 0.2.a | E27: =AVERAGE(C27:C29) -> 39.553767 | F27: =_xlfn.STDEV.P(C27:C29) -> 0.77249064
A28: B2 | B28: =VLOOKUP(A28,'Exported Results'!A$42:D$161,4,FALSE) -> Undetermined | C28: =IF(B28="Undetermined",40.1,B28) -> 40.1 | D28: =VLOOKUP(A28,'Exported Results'!A$42:D$161,2,FALSE) -> 0.2.b
A29: B3 | B29: =VLOOKUP(A29,'Exported Results'!A$42:D$161,4,FALSE) -> Undetermined | C29: =IF(B29="Undetermined",40.1,B29) -> 40.1 | D29: =VLOOKUP(A29,'Exported Results'!A$42:D$161,2,FALSE) -> 0.2.c
A30: B4 | B30: =VLOOKUP(A30,'Exported Results'!A$42:D$161,4,FALSE) -> Undetermined | C30: =IF(B30="Undetermined",40.1,B30) -> 40.1 | D30: =VLOOKUP(A30,'Exported Results'!A$42:D$161,2,FALSE) -> 0.3.a | E30: =AVERAGE(C30:C32) -> 40.1 | F30: =_xlfn.STDEV.P(C30:C32) -> 0
A31: B5 | B31: =VLOOKUP(A31,'Exported Results'!A$42:D$161,4,FALSE) -> Undetermined | C31: =IF(B31="Undetermined",40.1,B31) -> 40.1 | D31: =VLOOKUP(A31,'Exported Results'!A$42:D$161,2,FALSE) -> 0.3.b
A32: B6 | B32: =VLOOKUP(A32,'Exported Results'!A$42:D$161,4,FALSE) -> Undetermined | C32: =IF(B32="Undetermined",40.1,B32) -> 40.1 | D32: =VLOOKUP(A32,'Exported Results'!A$42:D$161,2,FALSE) -> 0.3.c
A33: B7 | B33: =VLOOKUP(A33,'Exported Results'!A$42:D$161,4,FALSE) -> Undetermined | C33: =IF(B33="Undetermined",40.1,B33) -> 40.1 | D33: =VLOOKUP(A33,'Exported Results'!A$42:D$161,2,FALSE) -> 2.1.a | E33: =AVERAGE(C33:C35) -> 39.544691 | F33: =_xlfn.STDEV.P(C33:C35) -> 0.78532486
A34: B8 | B34: =VLOOKUP(A34,'Exported Results'!A$42:D$161,4,FALSE) -> 38.434074 | C34: =IF(B34="Undetermined",40.1,B34) -> 38.434074 | D34: =VLOOKUP(A34,'Exported Results'!A$42:D$161,2,FALSE) -> 2.1.b
A35: B9 | B35: =VLOOKUP(A35,'Exported Results'!A$42:D$161,4,FALSE) -> Undetermined | C35: =IF(B35="Undetermined",40.1,B35) -> 40.1 | D35: =VLOOKUP(A35,'Exported Results'!A$42:D$161,2,FALSE) -> 2.1.c
A36: B10 | B36: =VLOOKUP(A36,'Exported Results'!A$42:D$161,4,FALSE) -> 38.205517 | C36: =IF(B36="Undetermined",40.1,B36) -> 38.205517 | D36: =VLOOKUP(A36,'Exported Results'!A$42:D$161,2,FALSE) -> 2.2.a | E36: =AVERAGE(C36:C38) -> 39.017572 | F36: =_xlfn.STDEV.P(C36:C38) -> 0.7966984
A37: B11 | B37: =VLOOKUP(A37,'Exported Results'!A$42:D$161,4,FALSE) -> Undetermined | C37: =IF(B37="Undetermined",40.1,B37) -> 40.1 | D37: =VLOOKUP(A37,'Exported Results'!A$42:D$161,2,FALSE) -> 2.2.b
A38: B12 | B38: =VLOOKUP(A38,'Exported Results'!A$42:D$161,4,FALSE) -> 38.7472 | C38: =IF(B38="Undetermined",40.1,B38) -> 38.7472 | D38: =VLOOKUP(A38,'Exported Results'!A$42:D$161,2,FALSE) -> 2.2.c
A39: B13 | B39: =VLOOKUP(A39,'Exported Results'!A$42:D$161,4,FALSE) -> Undetermined | C39: =IF(B39="Undetermined",40.1,B39) -> 40.1 | D39: =VLOOKUP(A39,'Exported Results'!A$42:D$161,2,FALSE) -> 2.3.a | E39: =AVERAGE(C39:C41) -> 40.1 | F39: =_xlfn.STDEV.P(C39:C41) -> 0
A40: B14 | B40: =VLOOKUP(A40,'Exported Results'!A$42:D$161,4,FALSE) -> Undetermined | C40: =IF(B40="Undetermined",40.1,B40) -> 40.1 | D40: =VLOOKUP(A40,'Exported Results'!A$42:D$161,2,FALSE) -> 2.3.b
A41: B15 | B41: =VLOOKUP(A41,'Exported Results'!A$42:D$161,4,FALSE) -> Undetermined | C41: =IF(B41="Undetermined",40.1,B41) -> 40.1 | D41: =VLOOKUP(A41,'Exported Results'!A$42:D$161,2,FALSE) -> 2.3.c
...

Sheet NLRP3
A1: Standard dilution | B1: Av CT | C1: SD CT | D1: CV CT | E1: Dilution | F1: log dilution
A2: =B33 -> STD 10a | B2: =C33 -> 38.132824 | C2: =D33 -> 0.85414732 | D2: =C2/B2 -> 0.022399267 | E2: 0.1 | F2: =LOG(E2,10) -> -1
A3: =B34 -> STD 20a | B3: =C34 -> 39.506111 | C3: =D34 -> 0.83988603 | D3: =C3/B3 -> 0.021259649 | E3: 0.05 | F3: =LOG(E3,10) -> -1.30103
A4: =B35 -> STD 40a | B4: =C35 -> 40.1 | C4: =D35 -> 0 | D4: =C4/B4 -> 0 | E4: 0.025 | F4: =LOG(E4,10) -> -1.60206
A5: =B36 -> STD 80a | B5: =C36 -> 39.359822 | C5: =D36 -> 1.0467693 | D5: =C5/B5 -> 0.026594868 | E5: 0.0125 | F5: =LOG(E5,10) -> -1.90309
A6: =B37 -> STD 160a | B6: =C37 -> 40.1 | C6: =D37 -> 0 | D6: =C6/B6 -> 0 | E6: 0.00625 | F6: =LOG(E6,10) -> -2.20412
A7: =B38 -> STD 320a | B7: =C38 -> 40.1 | C7: =D38 -> 0 | D7: =C7/B7 -> 0 | E7: 0.003125 | F7: =LOG(E7,10) -> -2.50515
B28: Slope | C28: =SLOPE(B2:B7,F2:F7) -> -1.0323955
B29: Efficiency | C29: =10^(-1/C28) -> 9.3029585
B31: Sample | C31: Av Ct | D31: SD Ct | E31: CV Ct | F31: delta Ct (to STD 20) | G31: deltadelta Ct
B32: ='Results Workspace'!D3 -> Blank 1.a | C32: ='Results Workspace'!E3 -> 40.1 | D32: ='Results Workspace'!F3 -> 0 | E32: =D32/C32 -> 0 | F32: =$C$29^($B$3-C32) -> 0.26591724
B33: ='Results Workspace'!D6 -> STD 10a | C33: ='Results Workspace'!E6 -> 38.132824 | D33: ='Results Workspace'!F6 -> 0.85414732 | E33: =D33/C33 -> 0.022399267 | F33: =$C$29^($B$3-C33) -> 21.389207
B34: ='Results Workspace'!D9 -> STD 20a | C34: ='Results Workspace'!E9 -> 39.506111 | D34: ='Results Workspace'!F9 -> 0.83988603 | E34: =D34/C34 -> 0.021259649 | F34: =$C$29^($B$3-C34) -> 1
B35: ='Results Workspace'!D12 -> STD 40a | C35: ='Results Workspace'!E12 -> 40.1 | D35: ='Results Workspace'!F12 -> 0 | E35: =D35/C35 -> 0 | F35: =$C$29^($B$3-C35) -> 0.26591724
B36: ='Results Workspace'!D15 -> STD 80a | C36: ='Results Workspace'!E15 -> 39.359822 | D36: ='Results Workspace'!F15 -> 1.0467693 | E36: =D36/C36 -> 0.026594868 | F36: =$C$29^($B$3-C36) -> 1.3857924
B37: ='Results Workspace'!D18 -> STD 160a | C37: ='Results Workspace'!E18 -> 40.1 | D37: ='Results Workspace'!F18 -> 0 | E37: =D37/C37 -> 0 | F37: =$C$29^($B$3-C37) -> 0.26591724
B38: ='Results Workspace'!D21 -> STD 320a | C38: ='Results Workspace'!E21 -> 40.1 | D38: ='Results Workspace'!F21 -> 0 | E38: =D38/C38 -> 0 | F38: =$C$29^($B$3-C38) -> 0.26591724
B39: ='Results Workspace'!D24 -> 0.1.a | C39: ='Results Workspace'!E24 -> 39.546048 | D39: ='Results Workspace'!F24 -> 0.78340611 | E39: =D39/C39 -> 0.019809972 | F39: =$C$29^($B$3-C39) -> 0.9147783 | G39: =F39/'Housekeeper summary'!$E$4 -> 1.7259968
B40: ='Results Workspace'!D27 -> 0.2.a | C40: ='Results Workspace'!E27 -> 39.553767 | D40: ='Results Workspace'!F27 -> 0.77249064 | E40: =D40/C40 -> 0.019530141 | F40: =$C$29^($B$3-C40) -> 0.89916552 | G40: =F40/'Housekeeper summary'!$E$4 -> 1.6965387
B41: ='Results Workspace'!D30 -> 0.3.a | C41: ='Results Workspace'!E30 -> 40.1 | D41: ='Results Workspace'!F30 -> 0 | E41: =D41/C41 -> 0 | F41: =$C$29^($B$3-C41) -> 0.26591724 | G41: =F41/'Housekeeper summary'!$E$4 -> 0.50173063
B42: ='Results Workspace'!D33 -> 2.1.a | C42: ='Results Workspace'!E33 -> 39.544691 | D42: ='Results Workspace'!F33 -> 0.78532486 | E42: =D42/C42 -> 0.019859173 | F42: =$C$29^($B$3-C42) -> 0.91755064 | G42: =F42/'Housekeeper summary'!$E$4 -> 1.7312276
B43: ='Results Workspace'!D36 -> 2.2.a | C43: ='Results Workspace'!E36 -> 39.017572 | D43: ='Results Workspace'!F36 -> 0.7966984 | E43: =D43/C43 -> 0.020418964 | F43: =$C$29^($B$3-C43) -> 2.9730951 | G43: =F43/'Housekeeper summary'!$E$4 -> 5.6096134
B44: ='Results Workspace'!D39 -> 2.3.a | C44: ='Results Workspace'!E39 -> 40.1 | D44: ='Results Workspace'!F39 -> 0 | E44: =D44/C44 -> 0 | F44: =$C$29^($B$3-C44) -> 0.26591724 | G44: =F44/'Housekeeper summary'!$E$4 -> 0.50173063
B45: ='Results Workspace'!D42 -> 8.1.a | C45: ='Results Workspace'!E42 -> 38.832723 | D45: ='Results Workspace'!F42 -> 0.89702035 | E45: =D45/C45 -> 0.023099599 | F45: =$C$29^($B$3-C45) -> 4.4901126 | G45: =F45/'Housekeeper summary'!$E$4 -> 8.4719106
B46: ='Results Workspace'!D45 -> 8.2.a | C46: ='Results Workspace'!E45 -> 38.916371 | D46: ='Results Workspace'!F45 -> 0.83766793 | E46: =D46/C46 -> 0.021524821 | F46: =$C$29^($B$3-C46) -> 3.7259291 | G46: =F46/'Housekeeper summary'!$E$4 -> 7.0300549
B47: ='Results Workspace'!D48 -> 8.3.a | C47: ='Results Workspace'!E48 -> 38.910723 | D47: ='Results Workspace'!F48 -> 0.84125694 | E47: =D47/C47 -> 0.021620183 | F47: =$C$29^($B$3-C47) -> 3.7731637 | G47: =F47/'Housekeeper summary'!$E$4 -> 7.1191768
B48: ='Results Workspace'!D51 -> 0.4.a | C48: ='Results Workspace'!E51 -> 38.93518 | D48: ='Results Workspace'!F51 -> 0.82634417 | E48: =D48/C48 -> 0.021223587 | F48: =$C$29^($B$3-C48) -> 3.5728583 | G48: =F48/'Housekeeper summary'!$E$4 -> 6.7412421
B49: ='Results Workspace'!D54 -> 0.5.a | C49: ='Results Workspace'!E54 -> 39.517893 | D49: ='Results Workspace'!F54 -> 0.8232233 | E49: =D49/C49 -> 0.02083166 | F49: =$C$29^($B$3-C49) -> 0.97406377 | G49: =F49/'Housekeeper summary'!$E$4 -> 1.8378562
B50: ='Results Workspace'!D57 -> 0.6.a | C50: ='Results Workspace'!E57 -> 40.1 | D50: ='Results Workspace'!F57 -> 0 | E50: =D50/C50 -> 0 | F50: =$C$29^($B$3-C50) -> 0.26591724 | G50: =F50/'Housekeeper summary'!$E$4 -> 0.50173063
B51: ='Results Workspace'!D60 -> 0.7.a | C51: ='Results Workspace'!E60 -> 40.1 | D51: ='Results Workspace'!F60 -> 0 | E51: =D51/C51 -> 0 | F51: =$C$29^($B$3-C51) -> 0.26591724 | G51: =F51/'Housekeeper summary'!$E$4 -> 0.50173063
B52: ='Results Workspace'!D63 -> 0.8.a | C52: ='Results Workspace'!E63 -> 39.534786 | D52: ='Results Workspace'!F63 -> 0.79933335 | E52: =D52/C52 -> 0.020218482 | F52: =$C$29^($B$3-C52) -> 0.93804725 | G52: =F52/'Housekeeper summary'!$E$4 -> 1.7699005
B53: ='Results Workspace'!D66 -> 0.9.a | C53: ='Results Workspace'!E66 -> 40.1 | D53: ='Results Workspace'!F66 -> 0 | E53: =D53/C53 -> 0 | F53: =$C$29^($B$3-C53) -> 0.26591724 | G53: =F53/'Housekeeper summary'!$E$4 -> 0.50173063
B54: ='Results Workspace'!D69 -> 2.4.a | C54: ='Results Workspace'!E69 -> 39.155872 | D54: ='Results Workspace'!F69 -> 1.3351985 | E54: =D54/C54 -> 0.034099572 | F54: =$C$29^($B$3-C54) -> 2.1839801 | G54: =F54/'Housekeeper summary'!$E$4 -> 4.1207173
B55: ='Results Workspace'!D72 -> 2.5.a | C55: ='Results Workspace'!E72 -> 40.1 | D55: ='Results Workspace'!F72 -> 0 | E55: =D55/C55 -> 0 | F55: =$C$29^($B$3-C55) -> 0.26591724 | G55: =F55/'Housekeeper summary'!$E$4 -> 0.50173063
B56: ='Results Workspace'!D75 -> 2.6.a | C56: ='Results Workspace'!E75 -> 40.1 | D56: ='Results Workspace'!F75 -> 0 | E56: =D56/C56 -> 0 | F56: =$C$29^($B$3-C56) -> 0.26591724 | G56: =F56/'Housekeeper summary'!$E$4 -> 0.50173063
B57: ='Results Workspace'!D78 -> 2.7.a | C57: ='Results Workspace'!E78 -> 38.474319 | D57: ='Results Workspace'!F78 -> 1.2320414 | E57: =D57/C57 -> 0.032022435 | F57: =$C$29^($B$3-C57) -> 9.9865544 | G57: =F57/'Housekeeper summary'!$E$4 -> 18.842556
B58: ='Results Workspace'!D81 -> 2.8.a | C58: ='Results Workspace'!E81 -> #DIV/0! | D58: ='Results Workspace'!F81 -> #DIV/0! | E58: =D58/C58 -> #DIV/0! | F58: =$C$29^($B$3-C58) -> #DIV/0! | G58: =F58/'Housekeeper summary'!$E$4 -> #DIV/0!
B59: ='Results Workspace'!D84 -> 2.9.a | C59: ='Results Workspace'!E84 -> 39.160395 | D59: ='Results Workspace'!F84 -> 1.3288021 | E59: =D59/C59 -> 0.033932295 | F59: =$C$29^($B$3-C59) -> 2.1620596 | G59: =F59/'Housekeeper summary'!$E$4 -> 4.0793576
B60: ='Results Workspace'!D87 -> 8.4.a | C60: ='Results Workspace'!E87 -> #DIV/0! | D60: ='Results Workspace'!F87 -> #DIV/0! | E60: =D60/C60 -> #DIV/0! | F60: =$C$29^($B$3-C60) -> #DIV/0! | G60: =F60/'Housekeeper summary'!$E$4 -> #DIV/0!
B61: ='Results Workspace'!D90 -> 8.5.a | C61: ='Results Workspace'!E90 -> 39.504266 | D61: ='Results Workspace'!F90 -> 0.84249532 | E61: =D61/C61 -> 0.021326692 | F61: =$C$29^($B$3-C61) -> 1.0041235 | G61: =F61/'Housekeeper summary'!$E$4 -> 1.8945727
...

Sheet NFKB1
A1: Standard dilution | B1: Av CT | C1: SD CT | D1: CV CT | E1: Dilution | F1: log dilution
A2: =B33 -> STD 10a | B2: =C33 -> 26.317688 | C2: =D33 -> 0.023153305 | D2: =C2/B2 -> 0.00087976212 | E2: 0.1 | F2: =LOG(E2,10) -> -1
A3: =B34 -> STD 20a | B3: =C34 -> 26.988927 | C3: =D34 -> 0.2364861 | D3: =C3/B3 -> 0.008762338 | E3: 0.05 | F3: =LOG(E3,10) -> -1.30103
A4: =B35 -> STD 40a | B4: =C35 -> 28.210165 | C4: =D35 -> 0.051523199 | D4: =C4/B4 -> 0.0018264055 | E4: 0.025 | F4: =LOG(E4,10) -> -1.60206
A5: =B36 -> STD 80a | B5: =C36 -> 29.209851 | C5: =D36 -> 0.14845088 | D5: =C5/B5 -> 0.0050822197 | E5: 0.0125 | F5: =LOG(E5,10) -> -1.90309
A6: =B37 -> STD 160a | B6: =C37 -> 30.489621 | C6: =D37 -> 0.068141268 | D6: =C6/B6 -> 0.0022349004 | E6: 0.00625 | F6: =LOG(E6,10) -> -2.20412
A7: =B38 -> STD 320a | B7: =C38 -> 31.748273 | C7: =D38 -> 0.13298788 | D7: =C7/B7 -> 0.0041888226 | E7: 0.003125 | F7: =LOG(E7,10) -> -2.50515
B28: Slope | C28: =SLOPE(B2:B7,F2:F7) -> -3.6688033
B29: Efficiency | C29: =10^(-1/C28) -> 1.8731322
B31: Sample | C31: Av Ct | D31: SD Ct | E31: CV Ct | F31: delta Ct (to STD 20) | G31: deltadelta Ct
B32: ='Results Workspace'!D123 -> Blank 1.a | C32: ='Results Workspace'!E123 -> 40.1 | D32: ='Results Workspace'!F123 -> 0 | E32: =D32/C32 -> 0 | F32: =$C$29^($B$3-C32) -> 0.00026689187
B33: ='Results Workspace'!D126 -> STD 10a | C33: ='Results Workspace'!E126 -> 26.317688 | D33: ='Results Workspace'!F126 -> 0.023153305 | E33: =D33/C33 -> 0.00087976212 | F33: =$C$29^($B$3-C33) -> 1.5239076
B34: ='Results Workspace'!D129 -> STD 20a | C34: ='Results Workspace'!E129 -> 26.988927 | D34: ='Results Workspace'!F129 -> 0.2364861 | E34: =D34/C34 -> 0.008762338 | F34: =$C$29^($B$3-C34) -> 1
B35: ='Results Workspace'!D132 -> STD 40a | C35: ='Results Workspace'!E132 -> 28.210165 | D35: ='Results Workspace'!F132 -> 0.051523199 | E35: =D35/C35 -> 0.0018264055 | F35: =$C$29^($B$3-C35) -> 0.46465339
B36: ='Results Workspace'!D135 -> STD 80a | C36: ='Results Workspace'!E135 -> 29.209851 | D36: ='Results Workspace'!F135 -> 0.14845088 | E36: =D36/C36 -> 0.0050822197 | F36: =$C$29^($B$3-C36) -> 0.24811115
B37: ='Results Workspace'!D138 -> STD 160a | C37: ='Results Workspace'!E138 -> 30.489621 | D37: ='Results Workspace'!F138 -> 0.068141268 | E37: =D37/C37 -> 0.0022349004 | F37: =$C$29^($B$3-C37) -> 0.11112742
B38: ='Results Workspace'!D141 -> STD 320a | C38: ='Results Workspace'!E141 -> 31.748273 | D38: ='Results Workspace'!F141 -> 0.13298788 | E38: =D38/C38 -> 0.0041888226 | F38: =$C$29^($B$3-C38) -> 0.050437376
B39: ='Results Workspace'!D144 -> 0.1.a | C39: ='Results Workspace'!E144 -> 28.053437 | D39: ='Results Workspace'!F144 -> 0.049050163 | E39: =D39/C39 -> 0.0017484547 | F39: =$C$29^($B$3-C39) -> 0.51268221 | G39: =F39/'Housekeeper summary'!$E$4 -> 0.96732493
B40: ='Results Workspace'!D147 -> 0.2.a | C40: ='Results Workspace'!E147 -> 28.280895 | D40: ='Results Workspace'!F147 -> 0.081555029 | E40: =D40/C40 -> 0.0028837499 | F40: =$C$29^($B$3-C40) -> 0.44447802 | G40: =F40/'Housekeeper summary'!$E$4 -> 0.83863778
B41: ='Results Workspace'!D150 -> 0.3.a | C41: ='Results Workspace'!E150 -> 28.262847 | D41: ='Results Workspace'!F150 -> 0.069934634 | E41: =D41/C41 -> 0.002474437 | F41: =$C$29^($B$3-C41) -> 0.44954148 | G41: =F41/'Housekeeper summary'!$E$4 -> 0.84819147
B42: ='Results Workspace'!D153 -> 2.1.a | C42: ='Results Workspace'!E153 -> 28.16004 | D42: ='Results Workspace'!F153 -> 0.13827218 | E42: =D42/C42 -> 0.0049102266 | F42: =$C$29^($B$3-C42) -> 0.47950334 | G42: =F42/'Housekeeper summary'!$E$4 -> 0.90472329
B43: ='Results Workspace'!D156 -> 2.2.a | C43: ='Results Workspace'!E156 -> 28.672782 | D43: ='Results Workspace'!F156 -> 0.13793183 | E43: =D43/C43 -> 0.0048105494 | F43: =$C$29^($B$3-C43) -> 0.34756371 | G43: =F43/'Housekeeper summary'!$E$4 -> 0.65578059
B44: ='Results Workspace'!D159 -> 2.3.a | C44: ='Results Workspace'!E159 -> 28.18965 | D44: ='Results Workspace'!F159 -> 0.1473084 | E44: =D44/C44 -> 0.00522562 | F44: =$C$29^($B$3-C44) -> 0.47067464 | G44: =F44/'Housekeeper summary'!$E$4 -> 0.88806537
B45: ='Results Workspace'!D162 -> 8.1.a | C45: ='Results Workspace'!E162 -> 28.302849 | D45: ='Results Workspace'!F162 -> 0.10131066 | E45: =D45/C45 -> 0.0035795215 | F45: =$C$29^($B$3-C45) -> 0.43839568 | G45: =F45/'Housekeeper summary'!$E$4 -> 0.82716166
B46: ='Results Workspace'!D165 -> 8.2.a | C46: ='Results Workspace'!E165 -> 28.474786 | D46: ='Results Workspace'!F165 -> 0.10530054 | E46: =D46/C46 -> 0.0036980275 | F46: =$C$29^($B$3-C46) -> 0.39355167 | G46: =F46/'Housekeeper summary'!$E$4 -> 0.74255031
B47: ='Results Workspace'!D168 -> 8.3.a | C47: ='Results Workspace'!E168 -> 28.183967 | D47: ='Results Workspace'!F168 -> 0.041416954 | E47: =D47/C47 -> 0.0014695218 | F47: =$C$29^($B$3-C47) -> 0.47235648 | G47: =F47/'Housekeeper summary'!$E$4 -> 0.89123865
B48: ='Results Workspace'!D171 -> 0.4.a | C48: ='Results Workspace'!E171 -> 27.705382 | D48: ='Results Workspace'!F171 -> 0.098174939 | E48: =D48/C48 -> 0.0035435331 | F48: =$C$29^($B$3-C48) -> 0.63784775 | G48: =F48/'Housekeeper summary'!$E$4 -> 1.2034863
B49: ='Results Workspace'!D174 -> 0.5.a | C49: ='Results Workspace'!E174 -> 28.043025 | D49: ='Results Workspace'!F174 -> 0.12303792 | E49: =D49/C49 -> 0.0043874697 | F49: =$C$29^($B$3-C49) -> 0.51604348 | G49: =F49/'Housekeeper summary'!$E$4 -> 0.97366693
B50: ='Results Workspace'!D177 -> 0.6.a | C50: ='Results Workspace'!E177 -> 28.537216 | D50: ='Results Workspace'!F177 -> 0.16775519 | E50: =D50/C50 -> 0.0058784708 | F50: =$C$29^($B$3-C50) -> 0.37842992 | G50: =F50/'Housekeeper summary'!$E$4 -> 0.71401871
B51: ='Results Workspace'!D180 -> 0.7.a | C51: ='Results Workspace'!E180 -> #DIV/0! | D51: ='Results Workspace'!F180 -> #DIV/0! | E51: =D51/C51 -> #DIV/0! | F51: =$C$29^($B$3-C51) -> #DIV/0! | G51: =F51/'Housekeeper summary'!$E$4 -> #DIV/0!
B52: ='Results Workspace'!D183 -> 0.8.a | C52: ='Results Workspace'!E183 -> 27.370659 | D52: ='Results Workspace'!F183 -> 0.02936554 | E52: =D52/C52 -> 0.0010728839 | F52: =$C$29^($B$3-C52) -> 0.7869588 | G52: =F52/'Housekeeper summary'!$E$4 -> 1.4848279
B53: ='Results Workspace'!D186 -> 0.9.a | C53: ='Results Workspace'!E186 -> 27.444311 | D53: ='Results Workspace'!F186 -> 0.075687408 | E53: =D53/C53 -> 0.0027578542 | F53: =$C$29^($B$3-C53) -> 0.75140955 | G53: =F53/'Housekeeper summary'!$E$4 -> 1.4177539
B54: ='Results Workspace'!D189 -> 2.4.a | C54: ='Results Workspace'!E189 -> 28.733622 | D54: ='Results Workspace'!F189 -> 0.087619518 | E54: =D54/C54 -> 0.0030493725 | F54: =$C$29^($B$3-C54) -> 0.33454242 | G54: =F54/'Housekeeper summary'!$E$4 -> 0.63121212
B55: ='Results Workspace'!D192 -> 2.5.a | C55: ='Results Workspace'!E192 -> 29.189847 | D55: ='Results Workspace'!F192 -> 0.20542503 | E55: =D55/C55 -> 0.0070375507 | F55: =$C$29^($B$3-C55) -> 0.2512457 | G55: =F55/'Housekeeper summary'!$E$4 -> 0.4740485
B56: ='Results Workspace'!D195 -> 2.6.a | C56: ='Results Workspace'!E195 -> 28.220193 | D56: ='Results Workspace'!F195 -> 0.12214797 | E56: =D56/C56 -> 0.0043283889 | F56: =$C$29^($B$3-C56) -> 0.46173813 | G56: =F56/'Housekeeper summary'!$E$4 -> 0.87120402
B57: ='Results Workspace'!D198 -> 2.7.a | C57: ='Results Workspace'!E198 -> 27.153296 | D57: ='Results Workspace'!F198 -> 0.02292483 | E57: =D57/C57 -> 0.00084427429 | F57: =$C$29^($B$3-C57) -> 0.90198271 | G57: =F57/'Housekeeper summary'!$E$4 -> 1.7018542
B58: ='Results Workspace'!D201 -> 2.8.a | C58: ='Results Workspace'!E201 -> #DIV/0! | D58: ='Results Workspace'!F201 -> #DIV/0! | E58: =D58/C58 -> #DIV/0! | F58: =$C$29^($B$3-C58) -> #DIV/0! | G58: =F58/'Housekeeper summary'!$E$4 -> #DIV/0!
B59: ='Results Workspace'!D204 -> 2.9.a | C59: ='Results Workspace'!E204 -> 28.163593 | D59: ='Results Workspace'!F204 -> 0.15801926 | E59: =D59/C59 -> 0.0056107634 | F59: =$C$29^($B$3-C59) -> 0.47843517 | G59: =F59/'Housekeeper summary'!$E$4 -> 0.90270787
B60: ='Results Workspace'!D207 -> 8.4.a | C60: ='Results Workspace'!E207 -> #DIV/0! | D60: ='Results Workspace'!F207 -> #DIV/0! | E60: =D60/C60 -> #DIV/0! | F60: =$C$29^($B$3-C60) -> #DIV/0! | G60: =F60/'Housekeeper summary'!$E$4 -> #DIV/0!
B61: ='Results Workspace'!D210 -> 8.5.a | C61: ='Results Workspace'!E210 -> 28.0746 | D61: ='Results Workspace'!F210 -> 0.070387797 | E61: =D61/C61 -> 0.0025071701 | F61: =$C$29^($B$3-C61) -> 0.50591762 | G61: =F61/'Housekeeper summary'!$E$4 -> 0.95456154
...

Sheet FOXO1
A1: Standard dilution | B1: Av CT | C1: SD CT | D1: CV CT | E1: Dilution | F1: log dilution
A2: =B33 -> STD 10a | B2: =C33 -> 28.361588 | C2: =D33 -> 0.077795228 | D2: =C2/B2 -> 0.0027429785 | E2: 0.1 | F2: =LOG(E2,10) -> -1
A3: =B34 -> STD 20a | B3: =C34 -> 29.062718 | C3: =D34 -> 0.12143575 | D3: =C3/B3 -> 0.0041784031 | E3: 0.05 | F3: =LOG(E3,10) -> -1.30103
A4: =B35 -> STD 40a | B4: =C35 -> 30.123767 | C4: =D35 -> 0.11821576 | D4: =C4/B4 -> 0.0039243353 | E4: 0.025 | F4: =LOG(E4,10) -> -1.60206
A5: =B36 -> STD 80a | B5: =C36 -> 31.634493 | C5: =D36 -> 0.097381592 | D5: =C5/B5 -> 0.0030783358 | E5: 0.0125 | F5: =LOG(E5,10) -> -1.90309
A6: =B37 -> STD 160a | B6: =C37 -> 32.566486 | C6: =D37 -> 0.040200759 | D6: =C6/B6 -> 0.0012344211 | E6: 0.00625 | F6: =LOG(E6,10) -> -2.20412
A7: =B38 -> STD 320a | B7: =C38 -> 33.611463 | C7: =D38 -> 0.13156686 | D7: =C7/B7 -> 0.0039143449 | E7: 0.003125 | F7: =LOG(E7,10) -> -2.50515
B28: Slope | C28: =SLOPE(B2:B7,F2:F7) -> -3.6324244
B29: Efficiency | C29: =10^(-1/C28) -> 1.884943
B31: Sample | C31: Av Ct | D31: SD Ct | E31: CV Ct | F31: delta Ct (to STD 20) | G31: deltadelta Ct
B32: ='Results Workspace'!D243 -> Blank 1.a | C32: ='Results Workspace'!E243 -> 40.1 | D32: ='Results Workspace'!F243 -> 0 | E32: =D32/C32 -> 0 | F32: =$C$29^($B$3-C32) -> 0.00091507317
B33: ='Results Workspace'!D246 -> STD 10a | C33: ='Results Workspace'!E246 -> 28.361588 | D33: ='Results Workspace'!F246 -> 0.077795228 | E33: =D33/C33 -> 0.0027429785 | F33: =$C$29^($B$3-C33) -> 1.5596237
B34: ='Results Workspace'!D249 -> STD 20a | C34: ='Results Workspace'!E249 -> 29.062718 | D34: ='Results Workspace'!F249 -> 0.12143575 | E34: =D34/C34 -> 0.0041784031 | F34: =$C$29^($B$3-C34) -> 1
B35: ='Results Workspace'!D252 -> STD 40a | C35: ='Results Workspace'!E252 -> 30.123767 | D35: ='Results Workspace'!F252 -> 0.11821576 | E35: =D35/C35 -> 0.0039243353 | F35: =$C$29^($B$3-C35) -> 0.51038165
B36: ='Results Workspace'!D255 -> STD 80a | C36: ='Results Workspace'!E255 -> 31.634493 | D36: ='Results Workspace'!F255 -> 0.097381592 | E36: =D36/C36 -> 0.0030783358 | F36: =$C$29^($B$3-C36) -> 0.19588219
B37: ='Results Workspace'!D258 -> STD 160a | C37: ='Results Workspace'!E258 -> 32.566486 | D37: ='Results Workspace'!F258 -> 0.040200759 | E37: =D37/C37 -> 0.0012344211 | F37: =$C$29^($B$3-C37) -> 0.10849727
B38: ='Results Workspace'!D261 -> STD 320a | C38: ='Results Workspace'!E261 -> 33.611463 | D38: ='Results Workspace'!F261 -> 0.13156686 | E38: =D38/C38 -> 0.0039143449 | F38: =$C$29^($B$3-C38) -> 0.055942078
B39: ='Results Workspace'!D264 -> 0.1.a | C39: ='Results Workspace'!E264 -> 30.189128 | D39: ='Results Workspace'!F264 -> 0.029176291 | E39: =D39/C39 -> 0.0009664503 | F39: =$C$29^($B$3-C39) -> 0.48966769 | G39: =F39/'Housekeeper summary'!$E$4 -> 0.9239013
B40: ='Results Workspace'!D267 -> 0.2.a | C40: ='Results Workspace'!E267 -> 30.717288 | D40: ='Results Workspace'!F267 -> 0.10726461 | E40: =D40/C40 -> 0.0034919947 | F40: =$C$29^($B$3-C40) -> 0.35034808 | G40: =F40/'Housekeeper summary'!$E$4 -> 0.6610341
B41: ='Results Workspace'!D270 -> 0.3.a | C41: ='Results Workspace'!E270 -> 30.4491 | D41: ='Results Workspace'!F270 -> 0.15330654 | E41: =D41/C41 -> 0.0050348465 | F41: =$C$29^($B$3-C41) -> 0.41527095 | G41: =F41/'Housekeeper summary'!$E$4 -> 0.78353009
B42: ='Results Workspace'!D273 -> 2.1.a | C42: ='Results Workspace'!E273 -> 30.522472 | D42: ='Results Workspace'!F273 -> 0.18523758 | E42: =D42/C42 -> 0.0060688916 | F42: =$C$29^($B$3-C42) -> 0.3963987 | G42: =F42/'Housekeeper summary'!$E$4 -> 0.74792208
B43: ='Results Workspace'!D276 -> 2.2.a | C43: ='Results Workspace'!E276 -> 30.335466 | D43: ='Results Workspace'!F276 -> 0.16570461 | E43: =D43/C43 -> 0.0054624053 | F43: =$C$29^($B$3-C43) -> 0.4462876 | G43: =F43/'Housekeeper summary'!$E$4 -> 0.84205207
B44: ='Results Workspace'!D279 -> 2.3.a | C44: ='Results Workspace'!E279 -> 30.085995 | D44: ='Results Workspace'!F279 -> 0.094778667 | E44: =D44/C44 -> 0.0031502586 | F44: =$C$29^($B$3-C44) -> 0.52274944 | G44: =F44/'Housekeeper summary'!$E$4 -> 0.9863197
B45: ='Results Workspace'!D282 -> 8.1.a | C45: ='Results Workspace'!E282 -> 30.510065 | D45: ='Results Workspace'!F282 -> 0.18862849 | E45: =D45/C45 -> 0.0061825003 | F45: =$C$29^($B$3-C45) -> 0.39952865 | G45: =F45/'Housekeeper summary'!$E$4 -> 0.75382765
B46: ='Results Workspace'!D285 -> 8.2.a | C46: ='Results Workspace'!E285 -> 30.717518 | D46: ='Results Workspace'!F285 -> 0.13027659 | E46: =D46/C46 -> 0.0042411172 | F46: =$C$29^($B$3-C46) -> 0.35029711 | G46: =F46/'Housekeeper summary'!$E$4 -> 0.66093794
B47: ='Results Workspace'!D288 -> 8.3.a | C47: ='Results Workspace'!E288 -> 30.601849 | D47: ='Results Workspace'!F288 -> 0.049075743 | E47: =D47/C47 -> 0.0016036856 | F47: =$C$29^($B$3-C47) -> 0.37694667 | G47: =F47/'Housekeeper summary'!$E$4 -> 0.71122014
B48: ='Results Workspace'!D291 -> 0.4.a | C48: ='Results Workspace'!E291 -> 29.439936 | D48: ='Results Workspace'!F291 -> 0.10459895 | E48: =D48/C48 -> 0.0035529612 | F48: =$C$29^($B$3-C48) -> 0.78732249 | G48: =F48/'Housekeeper summary'!$E$4 -> 1.4855141
B49: ='Results Workspace'!D294 -> 0.5.a | C49: ='Results Workspace'!E294 -> 29.838798 | D49: ='Results Workspace'!F294 -> 0.12456417 | E49: =D49/C49 -> 0.0041745707 | F49: =$C$29^($B$3-C49) -> 0.61142992 | G49: =F49/'Housekeeper summary'!$E$4 -> 1.1536414
B50: ='Results Workspace'!D297 -> 0.6.a | C50: ='Results Workspace'!E297 -> 29.796198 | D50: ='Results Workspace'!F297 -> 0.11348743 | E50: =D50/C50 -> 0.0038087891 | F50: =$C$29^($B$3-C50) -> 0.62816582 | G50: =F50/'Housekeeper summary'!$E$4 -> 1.1852185
B51: ='Results Workspace'!D300 -> 0.7.a | C51: ='Results Workspace'!E300 -> #DIV/0! | D51: ='Results Workspace'!F300 -> #DIV/0! | E51: =D51/C51 -> #DIV/0! | F51: =$C$29^($B$3-C51) -> #DIV/0! | G51: =F51/'Housekeeper summary'!$E$4 -> #DIV/0!
B52: ='Results Workspace'!D303 -> 0.8.a | C52: ='Results Workspace'!E303 -> 29.447967 | D52: ='Results Workspace'!F303 -> 0.163505 | E52: =D52/C52 -> 0.0055523358 | F52: =$C$29^($B$3-C52) -> 0.78332445 | G52: =F52/'Housekeeper summary'!$E$4 -> 1.4779707
B53: ='Results Workspace'!D306 -> 0.9.a | C53: ='Results Workspace'!E306 -> 29.523329 | D53: ='Results Workspace'!F306 -> 0.17824482 | E53: =D53/C53 -> 0.0060374227 | F53: =$C$29^($B$3-C53) -> 0.74678315 | G53: =F53/'Housekeeper summary'!$E$4 -> 1.4090248
B54: ='Results Workspace'!D309 -> 2.4.a | C54: ='Results Workspace'!E309 -> 30.085556 | D54: ='Results Workspace'!F309 -> 0.048312912 | E54: =D54/C54 -> 0.0016058507 | F54: =$C$29^($B$3-C54) -> 0.52289504 | G54: =F54/'Housekeeper summary'!$E$4 -> 0.98659441
B55: ='Results Workspace'!D312 -> 2.5.a | C55: ='Results Workspace'!E312 -> 30.756222 | D55: ='Results Workspace'!F312 -> 0.27130964 | E55: =D55/C55 -> 0.0088212928 | F55: =$C$29^($B$3-C55) -> 0.34180738 | G55: =F55/'Housekeeper summary'!$E$4 -> 0.64491958
B56: ='Results Workspace'!D315 -> 2.6.a | C56: ='Results Workspace'!E315 -> 29.818853 | D56: ='Results Workspace'!F315 -> 0.11652101 | E56: =D56/C56 -> 0.0039076288 | F56: =$C$29^($B$3-C56) -> 0.61920904 | G56: =F56/'Housekeeper summary'!$E$4 -> 1.1683189
B57: ='Results Workspace'!D318 -> 2.7.a | C57: ='Results Workspace'!E318 -> 29.398215 | D57: ='Results Workspace'!F318 -> 0.18828513 | E57: =D57/C57 -> 0.0064046449 | F57: =$C$29^($B$3-C57) -> 0.80842232 | G57: =F57/'Housekeeper summary'!$E$4 -> 1.5253251
B58: ='Results Workspace'!D321 -> 2.8.a | C58: ='Results Workspace'!E321 -> #DIV/0! | D58: ='Results Workspace'!F321 -> #DIV/0! | E58: =D58/C58 -> #DIV/0! | F58: =$C$29^($B$3-C58) -> #DIV/0! | G58: =F58/'Housekeeper summary'!$E$4 -> #DIV/0!
B59: ='Results Workspace'!D324 -> 2.9.a | C59: ='Results Workspace'!E324 -> 30.434568 | D59: ='Results Workspace'!F324 -> 0.047119984 | E59: =D59/C59 -> 0.0015482389 | F59: =$C$29^($B$3-C59) -> 0.41911387 | G59: =F59/'Housekeeper summary'!$E$4 -> 0.79078088
B60: ='Results Workspace'!D327 -> 8.4.a | C60: ='Results Workspace'!E327 -> #DIV/0! | D60: ='Results Workspace'!F327 -> #DIV/0! | E60: =D60/C60 -> #DIV/0! | F60: =$C$29^($B$3-C60) -> #DIV/0! | G60: =F60/'Housekeeper summary'!$E$4 -> #DIV/0!
B61: ='Results Workspace'!D330 -> 8.5.a | C61: ='Results Workspace'!E330 -> 29.784992 | D61: ='Results Workspace'!F330 -> 0.073821396 | E61: =D61/C61 -> 0.0024784763 | F61: =$C$29^($B$3-C61) -> 0.63264398 | G61: =F61/'Housekeeper summary'!$E$4 -> 1.1936679
...

Sheet Housekeeper summary
B3: B2M | C3: HMBS | D3: YWHA2 | E3: geometric mean
A4: 0.1.a | B4: 0.51 | C4: 0.56 | D4: 0.52 | E4: 0.53
A5: 0.2.a | B5: 0.46 | C5: 0.53 | D5: 0.42 | E5: 0.47
A6: 0.3.a | B6: 0.49 | C6: 0.59 | D6: 0.5 | E6: 0.52
A7: 2.1.a | B7: 0.52 | C7: 0.51 | D7: 0.5 | E7: 0.51
A8: 2.2.a | B8: 0.43 | C8: 0.62 | D8: 0.41 | E8: 0.48
A9: 2.3.a | B9: 0.5 | C9: 1.02 | D9: 0.58 | E9: 0.67
A10: 8.1.a | B10: 0.44 | C10: 0.59 | D10: 0.4 | E10: 0.47
A11: 8.2.a | B11: 0.41 | C11: 0.47 | D11: 0.41 | E11: 0.43
A12: 8.3.a | B12: 0.55 | C12: 0.73 | D12: 0.52 | E12: 0.6
A13: 0.4.a | B13: 0.63 | C13: 0.54 | D13: 0.55 | E13: 0.57
A14: 0.5.a | B14: 0.48 | C14: 0.45 | D14: 0.47 | E14: 0.46
A15: 0.6.a | B15: 0.45 | C15: 0.49 | D15: 0.42 | E15: 0.45
A16: 0.7.a
A17: 0.8.a | B17: 0.44 | C17: 0.79 | D17: 0.64 | E17: 0.6
A18: 0.9.a | B18: 0.57 | C18: 0.58 | D18: 0.65 | E18: 0.6
A19: 2.4.a | B19: 0.4 | C19: 0.44 | D19: 0.39 | E19: 0.41
A20: 2.5.a
A21: 2.6.a | B21: 0.44 | C21: 0.42 | D21: 0.38 | E21: 0.41
A22: 2.7.a | B22: 0.73 | C22: 0.55 | D22: 0.76 | E22: 0.67
A23: 2.8.a
A24: 2.9.a | B24: 0.55 | C24: 0.5 | D24: 0.44 | E24: 0.49
A25: 8.4.a
A26: 8.5.a | B26: 0.56 | C26: 0.49 | D26: 0.56 | E26: 0.54
A27: 8.6.a | B27: 0.6 | C27: 0.6 | D27: 0.62 | E27: 0.6
A28: 8.7.a | B28: 0.51 | C28: 0.72 | D28: 0.5 | E28: 0.56
A29: 8.8.a | B29: 0.51 | C29: 0.86 | D29: 0.57 | E29: 0.63
A30: 8.9.a | B30: 0.38 | C30: 0.49 | D30: 0.42 | E30: 0.43
